{
  "xsize": 16,
  "zsize": 16,
  "slices": [
    [
      "#$$#        #$$#",
      "$##############$",
      "$###1##########$",
      "################",
      "$#####1########$",
      "$##############$",
      "################",
      "$##########  ##$",
      "$##########  ##$",
      "###########  ###",
      "$##########cc##$",
      "$##############$",
      "################",
      "$##############$",
      "$##############$",
      "#$$#        #$$#"
    ],
    [
      "μμββ        ββμμ",
      "μ⑮⑫⑮βμββββμβ ⓐⓛμ",
      "β        #     β",
      "β              β",
      "β        #     β",
      "μ    ⓘFFⓘ# cc  μ",
      "β# #######:dd: β",
      "β   ④⑱⑤   :  : β",
      "β         :  : β",
      "β         :  : β",
      "μ     ### :  : μ",
      "β              β",
      "β              β",
      "β              β",
      "μFF βμββββμβ   μ",
      "μμββ        ββμμ"
    ],
    [
      "μμθθ        θθμμ",
      "μ   θμθθθθμθ   μ",
      "θ        :     θ",
      "θ              θ",
      "θ        :     θ",
      "μ        :     μ",
      "θ: ::::::# cc  θ",
      "θ          dd  θ",
      "θ              θ",
      "θ              θ",
      "μ     ###      μ",
      "θ              θ",
      "θ              θ",
      "θ              θ",
      "μ   θμθθθθμθ   μ",
      "μμθθ        θθμμ"
    ],
    [
      "μμθθ        θθμμ",
      "μ   θμθθθθμθ   μ",
      "θ        :     θ",
      "θ        :     θ",
      "θ        :     θ",
      "μ        :     μ",
      "θ::::::::#     θ",
      "θ          cc  θ",
      "θ          dd  θ",
      "θ              θ",
      "μ     ###      μ",
      "θ      E       θ",
      "θ              θ",
      "θ              θ",
      "μ   θμθθθθμθ   μ",
      "μμθθ        θθμμ"
    ],
    [
      "μμθθ        θθμμ",
      "μ###θμθθθθμθ###μ",
      "θ##############θ",
      "θ##############θ",
      "θ##############θ",
      "μ##########  ##μ",
      "θ##########  ##θ",
      "θ##########  ##θ",
      "θ##########cc##θ",
      "θ###### ###dd##θ",
      "μ##########  ##μ",
      "θ##############θ",
      "θ##############θ",
      "θ##############θ",
      "μ###θμθθθθμθ###μ",
      "μμθθ        θθμμ"
    ],
    [
      "μμββ        ββμμ",
      "μ###βμββββμβ###μ",
      "β##############β",
      "β##############β",
      "β##############β",
      "μ##########  ##μ",
      "β##########  ##β",
      "β##########  ##β",
      "β##########  ##β",
      "β###### ###cc##β",
      "μ##########dd##μ",
      "β##############β",
      "β##############β",
      "β##############β",
      "μ###βμββββμβ###μ",
      "μμββ        ββμμ"
    ]
  ],
  "refpalette": "rotwire:furnished_facades"
}
