{
  "xsize": 16,
  "zsize": 16,
  "slices": [
    [
      "WWWWWWWFFWWWWWWW",
      "WFFFFFFFFFFFFFFW",
      "WFFFFFFFFFFFFFFW",
      "WFFFFFFFFFFFFFFW",
      "WFFFFFFFFFFFFFFW",
      "WFFFFFFFFFFFFFFW",
      "WFFFFFFFFFFFFFFW",
      "WFFFFFFFFFFFFFFW",
      "WFFFFFFFFFFFFFFW",
      "WFFFFFFFFFFFFFFW",
      "WFFFFFFFFFFFFFFW",
      "WFFFFFFFFFFFFFFW",
      "WFFFFFFFFFFFFFFW",
      "WFFFFFFFFFFFFFFW",
      "WFFFFFFFFFFFFFFW",
      "WWWWWWWWWWWWWWWW"
    ],
    [
      "WWWWAWA  AWAWW  ",
      "              W ",
      "          W    W",
      "          W    W",
      "   TTTTT  W  u A",
      "          W    W",
      "          W    W",
      "               W",
      "               W",
      "          W    W",
      "          W    W",
      "        AAAAAi A",
      "          W    W",
      "          W    W",
      "               W",
      "               W"
    ],
    [
      "AWGGAAA  AAAGG  ",
      "              G ",
      "          W    G",
      "          W    G",
      "          W    A",
      "          W    A",
      "          W    G",
      "               G",
      "               G",
      "          W    G",
      "          W    A",
      "          W    A",
      "          W    G",
      "          W    G",
      "               W",
      "               A"
    ],
    [
      "AWGGAAA  AAAGG  ",
      "              G ",
      "          W    G",
      "          W    G",
      "          W    A",
      "          W    A",
      "          W    G",
      "               G",
      "               G",
      "          W    G",
      "          W    A",
      "          W    A",
      "          W    G",
      "          W    G",
      "               W",
      "               A"
    ],
    [
      "WWGGAWAAAAWAGG  ",
      "              G ",
      "               G",
      "               G",
      "               A",
      "               W",
      "               G",
      "               G",
      "               G",
      "               G",
      "               W",
      "               A",
      "               G",
      "               G",
      "               W",
      "               W"
    ],
    [
      "WWWWAWWWWWWAWW  ",
      "              W ",
      "               W",
      "               W",
      "               A",
      "   L    L      W",
      "               W",
      "               W",
      "               W",
      "               W",
      "               W",
      "               A",
      "   L    L      W",
      "               W",
      "               W",
      "               W"
    ]
  ],
  "refpalette": "rotwire:custom_buildings"
}
