{
  "xsize": 16,
  "zsize": 16,
  "slices": [
    [
      "WWWWWWWFFWWWWWWW",
      "WFFFFFFFFFFFFFFW",
      "WFFFFFFFFFFFFFFW",
      "WFFFFFFFFFFFFFFW",
      "WFFFFFFFFFFFFFFW",
      "WFFFFFFFFFFFFFFW",
      "WFFFFFFFFFFFFFFW",
      "WFFFFFFFFFFFFFFW",
      "WFFFFFFFFFFFFFFW",
      "WFFFFFFFFFFFFFFW",
      "WFFFFFFFFFFFFFFW",
      "WFFFFFFFFFFFFFFW",
      "WFFFFFFFFFFFFFFW",
      "WFFFFFFFFFFFFFFW",
      "WFFFFFFFFFFFFFFW",
      "WWWWWWWWWWWWWWWW"
    ],
    [
      "  WWAWA  AWAWWWW",
      " W              ",
      "W    W          ",
      "W    W          ",
      "A  TTTTT     u  ",
      "W    W          ",
      "W    W          ",
      "W               ",
      "W         cc    ",
      "W    W   :dd:   ",
      "W    W   :  :   ",
      "A    W  A:AA:i  ",
      "W    W   :  :   ",
      "W    W   :  :   ",
      "W               ",
      "W               "
    ],
    [
      "  GGAAA  AAAGGWA",
      " G              ",
      "G    W          ",
      "G    W          ",
      "A    W          ",
      "A    W          ",
      "G    W          ",
      "G               ",
      "G               ",
      "G    W    cc    ",
      "A    W    dd    ",
      "A    W          ",
      "G    W          ",
      "G    W          ",
      "W               ",
      "A               "
    ],
    [
      "  GGAAA  AAAGGWA",
      " G              ",
      "G    W          ",
      "G    W          ",
      "A    W          ",
      "A    W          ",
      "G    W          ",
      "G               ",
      "G               ",
      "G    W          ",
      "A    W    cc    ",
      "A    W    dd    ",
      "G    W          ",
      "G    W          ",
      "W               ",
      "A               "
    ],
    [
      "  GGAWAAAAWAGGWW",
      " G              ",
      "G               ",
      "G               ",
      "A               ",
      "W               ",
      "G               ",
      "G               ",
      "G               ",
      "G               ",
      "W               ",
      "A         cc    ",
      "G         dd    ",
      "G               ",
      "W               ",
      "W               "
    ],
    [
      "  WWAWWWWWWAWWWW",
      " W              ",
      "W               ",
      "W               ",
      "A               ",
      "W  L    L       ",
      "W               ",
      "W               ",
      "W               ",
      "W               ",
      "W               ",
      "A               ",
      "W  L    L cc    ",
      "W         dd    ",
      "W               ",
      "W               "
    ]
  ],
  "refpalette": "rotwire:custom_buildings"
}
