{
  "xsize": 16,
  "zsize": 16,
  "slices": [
    [
      "WWWWWWWWWWWWWWWW",
      "WFFFFFFFFFFFFFFW",
      "WFFFFFFFFFFFFFFW",
      "WFFFFFFFFFFFFFFW",
      "WFFFFFFFFFFFFFFW",
      "WFFFFFFFFFFFFFFW",
      "WFFFFFFFFFFFFFFW",
      "WFFFFFFFFFFFFFFW",
      "WFFFFFFFFFFFFFFW",
      "WFFFFFFFFFFFFFFW",
      "WFFFFFFFFFFFFFFW",
      "WFFFFFFFFFFFFFFW",
      "WFFFFFFFFFFFFFFW",
      "WFFFFFFFFFFFFFFW",
      " FFFFFFFFFFFFFFW",
      "  WWWWWWWWWWWWWW"
    ],
    [
      "W               ",
      "W               ",
      "W    W          ",
      "W q  W q        ",
      "A Q  W Q     u  ",
      "W    W          ",
      "W    W          ",
      "W               ",
      "W               ",
      "W    W          ",
      "W q  W q        ",
      "A Q  W Q     i  ",
      "W    W          ",
      "W    W          ",
      " W              ",
      "  WWAWWWWWWAWWWW"
    ],
    [
      "A               ",
      "W               ",
      "G    W          ",
      "G    W          ",
      "A    W          ",
      "A    W          ",
      "G    W          ",
      "G               ",
      "G               ",
      "G    W          ",
      "A    W          ",
      "A    W          ",
      "G    W          ",
      "G    W          ",
      " G              ",
      "  GGAAGGGGAAGGWA"
    ],
    [
      "A               ",
      "W               ",
      "G    W          ",
      "G    W          ",
      "A    W          ",
      "A    W          ",
      "G    W          ",
      "G               ",
      "G               ",
      "G    W          ",
      "A    W          ",
      "A    W          ",
      "G    W          ",
      "G    W          ",
      " G              ",
      "  GGAAGGGGAAGGWA"
    ],
    [
      "W               ",
      "W               ",
      "G               ",
      "G               ",
      "A               ",
      "W               ",
      "G               ",
      "G               ",
      "G               ",
      "G               ",
      "W               ",
      "A               ",
      "G               ",
      "G               ",
      " G              ",
      "  GGAWGGGGWAGGWW"
    ],
    [
      "W               ",
      "W               ",
      "W               ",
      "W               ",
      "A               ",
      "W  L    L       ",
      "W               ",
      "W               ",
      "W               ",
      "W               ",
      "W               ",
      "A               ",
      "W  L    L       ",
      "W               ",
      " W              ",
      "  WWAWWWWWWAWWWW"
    ]
  ],
  "refpalette": "rotwire:custom_buildings"
}
