{
  "xsize": 16,
  "zsize": 16,
  "slices": [
    [
      "WWWWWWWWWWWWWWWW",
      "WFFFFFFFFFFFFFFW",
      "WFFFFFFFFFFFFFFW",
      "WFFFFFFFFFFFFFFW",
      "WFFFFFFFFFFFFFFW",
      "WFFFFFFFFFFFFFFW",
      "WFFFFFFFFFFFFFFW",
      "WFFFFFFFFFFFFFFW",
      "WFFFFFFFFFFFFFFW",
      "WFFFFFFFFFFFFFFW",
      "WFFFFFFFFF  FFFW",
      "WFFFFFFFFF  FFFW",
      "WFFFFFFFFF  FFFW",
      "WFFFFFFFFFccFFFW",
      "WFFFFFFFFFFFFFF ",
      "WWWWWWWWWWWWWW  "
    ],
    [
      "               W",
      "               W",
      "          W    W",
      "  q    q  W    W",
      "  Q    Q  W  u A",
      "          W    W",
      "               W",
      "               W",
      "          cc   W",
      "         :dd:  W",
      "  q    q :W :  W",
      "  Q    Q :W :i A",
      "         :W :  W",
      "         :W :  W",
      "              W ",
      "WWWWAWWWWWWAWW  "
    ],
    [
      "               A",
      "               W",
      "          W    G",
      "          W    G",
      "          W    A",
      "          W    A",
      "               G",
      "               G",
      "               G",
      "          cc   G",
      "          dd   A",
      "          W    A",
      "          W    G",
      "          W    G",
      "              G ",
      "AWGGAAGGGGAAGG  "
    ],
    [
      "               A",
      "               W",
      "          W    G",
      "          W    G",
      "          W    A",
      "          W    A",
      "               G",
      "               G",
      "               G",
      "          W    G",
      "          cc   A",
      "          dd   A",
      "          W    G",
      "          W    G",
      "              G ",
      "AWGGAAGGGGAAGG  "
    ],
    [
      "               W",
      "               W",
      "               G",
      "               G",
      "               A",
      "               W",
      "               G",
      "               G",
      "               G",
      "               G",
      "               W",
      "          cc   A",
      "          dd   G",
      "               G",
      "              G ",
      "WWGGAWGGGGWAGG  "
    ],
    [
      "               W",
      "               W",
      "               W",
      "               W",
      "               A",
      "   L    L      W",
      "               W",
      "               W",
      "               W",
      "               W",
      "               W",
      "               A",
      "   L    L cc   W",
      "          dd   W",
      "              W ",
      "WWWWAWWWWWWAWW  "
    ]
  ],
  "refpalette": "rotwire:custom_buildings"
}
