{
  "xsize": 16,
  "zsize": 16,
  "slices": [
    [
      " NN          NN ",
      "NFFFFFFFFFFFFFFN",
      "NFFFFFFFFFFFFFFN",
      "NFFFFFFFFFFFFFFN",
      "NFFFFFFFFFFFFFFN",
      "NFFFFFFFFFFFFFFN",
      "NFFFFFFFFFFFFFFN",
      "NFFFFFFFFFFFFFFN",
      "NFFFFFFFFFFFFFFN",
      "NFFFFFFFFFFFFFFN",
      "NFFFFFFFFF  FFFN",
      "NFFFFFFFFF  FFFN",
      "NFFFFFFFFF  FFFN",
      "NFFFFFFFFFccFFFN",
      "NFFFFFFFFFFFFFFN",
      " NNNNNNNNNNNNNN "
    ],
    [
      " NN          NN ",
      "N  RNNNNNNNNR  N",
      "N              N",
      "N  TT  TT    e N",
      "N            O N",
      "N            O N",
      "NNNN  NNN    f N",
      "N              N",
      "N         cc   N",
      "N        :dd:  N",
      "N  TT  TT:  :  N",
      "N        :  :  N",
      "N        :  :  N",
      "N  e   f :  :  N",
      "N              N",
      " NRNNNRNNNRNNRN "
    ],
    [
      " NV          VN ",
      "N  RVVVVVVVVR  N",
      "V              V",
      "V  K   K       V",
      "V              V",
      "R              R",
      "VNNN  NNN      V",
      "V              V",
      "V              V",
      "V         cc   V",
      "R  K   K  dd   R",
      "V              V",
      "V              V",
      "V              V",
      "N              N",
      " NRVVRRVVVRVVRN "
    ],
    [
      " NV          VN ",
      "N  RVVVVVVVVR  N",
      "V              V",
      "V              V",
      "V              V",
      "R              R",
      "VNNN  NNN      V",
      "V              V",
      "V              V",
      "V              V",
      "R         cc   R",
      "V         dd   V",
      "V              V",
      "V              V",
      "N              N",
      " NRVVRRVVVRVVRN "
    ],
    [
      " NV          VN ",
      "N  RVVVVVVVVR  N",
      "V              V",
      "V              V",
      "V              V",
      "N              N",
      "V              V",
      "V              V",
      "V              V",
      "V              V",
      "N              N",
      "V         cc   V",
      "V         dd   V",
      "V              V",
      "N              N",
      " NRVVNRVVVRVVRN "
    ],
    [
      " NN          NN ",
      "N  RNNNNNNNNR  N",
      "N              N",
      "N              N",
      "N   L   L      N",
      "N              N",
      "N              N",
      "N              N",
      "N              N",
      "N              N",
      "N              N",
      "N   L   L      N",
      "N         cc   N",
      "N         dd   N",
      "N              N",
      " NRNNNRNNNRNNRN "
    ]
  ],
  "refpalette": "rotwire:custom_buildings"
}
