{
  "xsize": 16,
  "zsize": 16,
  "slices": [
    [
      " FFFFFFFFFFFFFF ",
      "FFFFFFFFFFFFFFFF",
      "FFFFFFFFFFFFFFFF",
      "FFFFFFFFFFFFFFFF",
      "FFFFFFFFFFFFFFFF",
      "FFFFFFFFFFFFFFFF",
      "FFFFFFFFFFFFFFFF",
      "FFFFFFFFFFFFFFFF",
      "FFFFFFFFFFFFFFFF",
      "FFFFFFFFFFFFFFFF",
      "FFFFFFFFFF  FFFF",
      "FFFFFFFFFF  FFFF",
      "FFFFFFFFFF  FFFF",
      "FFFFFFFFFFccFFFF",
      "FFFFFFFFFFFFFFFF",
      " FFFFFFFFFFFFFF "
    ],
    [
      " NNNNNNNNNNNNNN ",
      "N              N",
      "N              N",
      "N  XX XX       N",
      "N  XX          N",
      "N              N",
      "N              N",
      "N  RRRRR       N",
      "N              N",
      "N        NNNN  N",
      "N        N  N  N",
      "N        N  N  N",
      "N        N  N  N",
      "N           N  N",
      "N        NNNN  N",
      " NNNNNNNNNNNNNN "
    ],
    [
      "                ",
      "                ",
      "                ",
      "                ",
      "                ",
      "                ",
      "                ",
      "                ",
      "                ",
      "         NNNN   ",
      "         N  N   ",
      "         N  G   ",
      "         N  N   ",
      "            N   ",
      "         NNNN   ",
      "                "
    ],
    [
      "                ",
      "                ",
      "                ",
      "                ",
      "                ",
      "                ",
      "                ",
      "                ",
      "                ",
      "         NNNN   ",
      "         N  N   ",
      "         N  G   ",
      "         N  N   ",
      "            N   ",
      "         NNNN   ",
      "                "
    ],
    [
      "                ",
      "                ",
      "                ",
      "                ",
      "                ",
      "                ",
      "                ",
      "                ",
      "                ",
      "         FFFF   ",
      "         FFFF   ",
      "         FFFF   ",
      "         FFFF   ",
      "         FFFF   ",
      "         FFFF   ",
      "                "
    ],
    [
      "                ",
      "                ",
      "                ",
      "                ",
      "                ",
      "                ",
      "                ",
      "                ",
      "                ",
      "                ",
      "                ",
      "                ",
      "                ",
      "                ",
      "                ",
      "                "
    ]
  ],
  "refpalette": "rotwire:custom_buildings"
}
