{
  "xsize": 16,
  "zsize": 16,
  "slices": [
    [
      "PPPPPPPFFPPPPPPP",
      "PFFFFFFFFFFFFFFP",
      "PFFFFFFFFFFFFFFP",
      "PFFFFFFFFFFFFFFP",
      "PFFFFFFFFFFFFFFP",
      "PFFFFFFFFFFFFFFP",
      "PFFFFFFFFFFFFFFP",
      "PFFFFFFFFFFFFFFP",
      "PFFFFFFFFFFFFFFP",
      "PFFFFFFFFFFFFFFP",
      "PFFFFFFFFFFFFFFP",
      "PFFFFFFFFFFFFFFP",
      "PFFFFFFFFFFFFFFP",
      "PFFFFFFFFFFFFFFP",
      "PFFFFFFFFFFFFFFP",
      "PPPPPPPPPPPPPPPP"
    ],
    [
      " P    H  HPPPPP ",
      "P HPPH         P",
      "P q  u P  q  i P",
      "P Q    P  Q    P",
      "P              P",
      "P      P       P",
      "P      P       P",
      "PPP  PPPP    PPP",
      "P      P  cc   P",
      "P      P :dd:  P",
      "P q    Pq:  :  P",
      "P Q     Q:  :  P",
      "P    j P :  :m P",
      "P      P :  :  P",
      "P HPPH P       P",
      " P    PPPPPPPPP "
    ],
    [
      " P    H  HHGGGP ",
      "P HGGH         P",
      "G      P       G",
      "G      P       G",
      "G              G",
      "H      P       H",
      "G      P       G",
      "GPP  PPPP    PPG",
      "G      P       G",
      "G      P  cc   G",
      "H      P  dd   H",
      "G              G",
      "G      P       G",
      "G      P       G",
      "P HGGH P       P",
      " P    GGGGHGGGP "
    ],
    [
      " P    H  HHGGGP ",
      "P HGGH         P",
      "G      P       G",
      "G      P       G",
      "G              G",
      "H      P       H",
      "G      P       G",
      "GPP  PPPP    PPG",
      "G      P       G",
      "G      P       G",
      "H      P  cc   H",
      "G         dd   G",
      "G      P       G",
      "G      P       G",
      "P HGGH P       P",
      " P    GGGGHGGGP "
    ],
    [
      " P    HHHHPGGGP ",
      "P HGGH P       P",
      "G      P       G",
      "G      P       G",
      "G              G",
      "P      P       P",
      "G      P       G",
      "GPP  PPPPPPPPPPG",
      "G      P       G",
      "G      P       G",
      "P      P       P",
      "G         cc   G",
      "G      P  dd   G",
      "G      P       G",
      "P HGGH P       P",
      " P    GGGGPGGGP "
    ],
    [
      " P    PPPPPPPPP ",
      "P HPPH         P",
      "P              P",
      "P              P",
      "P   L      L   P",
      "P              P",
      "P              P",
      "P              P",
      "P              P",
      "P              P",
      "P              P",
      "P   L      L   P",
      "P         cc   P",
      "P         dd   P",
      "P HPPH         P",
      " P    PPPPPPPPP "
    ]
  ],
  "refpalette": "rotwire:custom_buildings"
}
