{
  "xsize": 16,
  "zsize": 16,
  "slices": [
    [
      " ############## ",
      "################",
      "################",
      "################",
      "################",
      "################",
      "################",
      "################",
      "################",
      "##########  ####",
      "##########  ####",
      "##########  ####",
      "##########cc####",
      "################",
      "################",
      " ############## "
    ],
    [
      " ιδδδιδδδδιδδδι ",
      "ι⑮ⓐⓛⓒⓑ # ⑫⑫ LLLι",
      "δ   ①  #      Lδ",
      "δ             ⑬δ",
      "δ      #      Lδ",
      "ι      #      Lι",
      "δ    ####      δ",
      "δ    #F⑫F#cc   δ",
      "δ    #   :dd:  δ",
      "δ        :  :  δ",
      "ι# ######:  :  ι",
      "δ    F   :  :  δ",
      "δ        :  :  δ",
      "δ              δ",
      "ιⓖⓗδδ  δ       ι",
      " ιδρρρρρδδιδδδι "
    ],
    [
      " ιηηηιηηηηιηηηι ",
      "ι      #      Lι",
      "η      #      eη",
      "η              η",
      "η      #       η",
      "ι      #      Lι",
      "η    ####      η",
      "η    #   #     η",
      "η    #   #cc   η",
      "η        #dd   η",
      "ι# #######     ι",
      "η              η",
      "η              η",
      "η              η",
      "ι  ηη  η       ι",
      " ιη     ηηιηηηι "
    ],
    [
      " ιηηηιηηηηιηηηι ",
      "ι      #      Lι",
      "η      #       η",
      "η      #       η",
      "η      #       η",
      "ι      #      Lι",
      "η    ####      η",
      "η    # E #     η",
      "η    #   #     η",
      "η    #   #cc   η",
      "ι#########dd   ι",
      "η              η",
      "η              η",
      "η              η",
      "ι  ηηιηη       ι",
      " ιη     ηηιηηηι "
    ],
    [
      " ιηηηιηηηηιηηηι ",
      "ι##############ι",
      "η##############η",
      "η##############η",
      "η##############η",
      "ι##############ι",
      "η##############η",
      "η#########  ###η",
      "η#########  ###η",
      "η###### ##  ###η",
      "ι#########cc###ι",
      "η#########dd###η",
      "η#########  ###η",
      "η##############η",
      "ι##ηηιηη#######ι",
      " ιη     ηηιηηηι "
    ],
    [
      " ιδδδιδδδδιδδδι ",
      "ι##############ι",
      "δ##############δ",
      "δ##############δ",
      "δ##############δ",
      "ι##############ι",
      "δ##############δ",
      "δ#########  ###δ",
      "δ#########  ###δ",
      "δ###### ##  ###δ",
      "ι#########  ###ι",
      "δ#########cc###δ",
      "δ#########dd###δ",
      "δ##############δ",
      "ι##δδιδδ#######ι",
      " ιδ     δδιδδδι "
    ]
  ],
  "refpalette": "rotwire:furnished_facades"
}
