{
  "xsize": 16,
  "zsize": 16,
  "slices": [
    [
      " ############## ",
      "################",
      "################",
      "################",
      "################",
      "################",
      "################",
      "################",
      "################",
      "##########  ####",
      "##########  ####",
      "##########  ####",
      "##########cc####",
      "################",
      "################",
      " ############## "
    ],
    [
      " ιδδδιδδδδιδδδι ",
      "ι≈WWWW≈W≈WWW≈WWι",
      "δW≈W≈WW≈WWW≈W≈Wδ",
      "δWW≈W≈WW≈W≈W≈WWδ",
      "δW≈W≈W≈WW≈WWW≈Wδ",
      "ιaaaaaaaa    aaι",
      "δ ⓛ            δ",
      "δ         cc   δ",
      "δL        dd:  δ",
      "δF       L  :  δ",
      "ιF    ####  : :ι",
      "δ ④⑱⑤  : :  :  δ",
      "δ        :  :  δ",
      "δ      :       δ",
      "ι  δδ  δⓜ      ι",
      " ιδρρρρρδδιδδδι "
    ],
    [
      " ιηηηιηηηηιηηηι ",
      "ιWWWWWWWWWWWWWWι",
      "ηWWWWWWWWWWWWWWη",
      "ηWWWWWWWWWWWWWWη",
      "ηWWWWWWWWWWWWWWη",
      "ιaaaaaaaa    aaι",
      "η              η",
      "η              η",
      "ηL        cc   η",
      "η       ⓑⓑdd   η",
      "ι     ###:  : :ι",
      "η      :       η",
      "η              η",
      "η      :       η",
      "ι  ηη  η       ι",
      " ιη     ηηιηηηι "
    ],
    [
      " ιηηηιηηηηιηηηι ",
      "ιWWWWWWWWWWWWWWι",
      "ηWWWWWWWWWWWWWWη",
      "ηWWWWWWWWWWWWWWη",
      "ηWWWWWWWWWWWWWWη",
      "ιaaaaaaaa    aaι",
      "η              η",
      "η              η",
      "ηL             η",
      "η       ⓑⓑcc   η",
      "ι     ###:dd:::ι",
      "η      :       η",
      "η      :       η",
      "η      :       η",
      "ι  ηηιηη       ι",
      " ιη     ηηιηηηι "
    ],
    [
      " ιηηηιηηηηιηηηι ",
      "ι##############ι",
      "η##############η",
      "η##############η",
      "η##############η",
      "ι##############ι",
      "η##############η",
      "η#########  ###η",
      "η#########  ###η",
      "η###### ##  ###η",
      "ι#########cc###ι",
      "η#########dd###η",
      "η#1#1#####  ###η",
      "η##############η",
      "ι##ηηιηη#######ι",
      " ιη     ηηιηηηι "
    ],
    [
      " ιδδδιδδδδιδδδι ",
      "ι##############ι",
      "δ##############δ",
      "δ##############δ",
      "δ##############δ",
      "ι##############ι",
      "δ##############δ",
      "δ#########  ###δ",
      "δ#########  ###δ",
      "δ###### ##  ###δ",
      "ι#########  ###ι",
      "δ#########cc###δ",
      "δ#########dd###δ",
      "δ##############δ",
      "ι##δδιδδ#######ι",
      " ιδ     δδιδδδι "
    ]
  ],
  "refpalette": "rotwire:furnished_facades"
}
