{
  "xsize": 16,
  "zsize": 16,
  "slices": [
    [
      " ############## ",
      "################",
      "################",
      "################",
      "################",
      "################",
      "################",
      "################",
      "################",
      "##########  ####",
      "####1#####  ####",
      "##########  ####",
      "##########cc####",
      "################",
      "################",
      " ############## "
    ],
    [
      " ιδδδιδδδδιδδδι ",
      "ιⓓ⑨F      L⑮Lⓑⓒι",
      "δ ⑧          ① δ",
      "δ              δ",
      "δ              δ",
      "ι             Fι",
      "δ④ⓘ⑤           δ",
      "δ④ⓘ⑤      cc   δ",
      "δ④ⓘ⑤     :dd:  δ",
      "δ     LLL:  :  δ",
      "ι#### ###:  : #ι",
      "δ        :  :  δ",
      "δ        :  :  δ",
      "δ              δ",
      "ι  δδ  δ       ι",
      " ιδρρρρρδδιδδδι "
    ],
    [
      " ιηηηιηηηηιηηηι ",
      "ι         **   ι",
      "η              η",
      "η              η",
      "η              η",
      "ι              ι",
      "η              η",
      "η              η",
      "η         cc   η",
      "η     ⓑ ⓑ dd   η",
      "ι#::# ####    #ι",
      "η              η",
      "η              η",
      "η              η",
      "ι  ηη  η       ι",
      " ιη     ηηιηηηι "
    ],
    [
      " ιηηηιηηηηιηηηι ",
      "ι              ι",
      "η              η",
      "η              η",
      "η              η",
      "ι              ι",
      "η              η",
      "η              η",
      "η              η",
      "η    E  ⓑ cc   η",
      "ι#########dd###ι",
      "η    E         η",
      "η              η",
      "η              η",
      "ι  ηηιηη       ι",
      " ιη     ηηιηηηι "
    ],
    [
      " ιηηηιηηηηιηηηι ",
      "ι##############ι",
      "η##############η",
      "η##############η",
      "η##############η",
      "ι##############ι",
      "η##############η",
      "η#########  ###η",
      "η#########  ###η",
      "η###### ##  ###η",
      "ι#########cc###ι",
      "η#########dd###η",
      "η#########  ###η",
      "η##############η",
      "ι##ηηιηη#######ι",
      " ιη     ηηιηηηι "
    ],
    [
      " ιδδδιδδδδιδδδι ",
      "ι##############ι",
      "δ##############δ",
      "δ##############δ",
      "δ##############δ",
      "ι##############ι",
      "δ##############δ",
      "δ#########  ###δ",
      "δ#########  ###δ",
      "δ###### ##  ###δ",
      "ι#########  ###ι",
      "δ#########cc###δ",
      "δ#########dd###δ",
      "δ##############δ",
      "ι##δδιδδ#######ι",
      " ιδ     δδιδδδι "
    ]
  ],
  "refpalette": "rotwire:furnished_facades"
}
