{
  "xsize": 16,
  "zsize": 16,
  "slices": [
    [
      "###    ##    ###",
      "################",
      "################",
      "################",
      "################",
      "####  ##########",
      "####  ##########",
      "####  ##########",
      "####cc##########",
      "################",
      "################",
      "################",
      "################",
      "################",
      "################",
      "################"
    ],
    [
      "ααδδδδδδδ    δαα",
      "α##    ⓛ δαδδ##α",
      "δ#      ⓐⓐ     δ",
      "δ#  cc         δ",
      "δ#  dd:        δ",
      "α#    :        α",
      "δ     :      ⓓⓕδ",
      "δ     :       ⓔδ",
      "δ     :        δ",
      "δ             ⓑδ",
      "α#     ##      α",
      "δ#    FF       δ",
      "δ#             δ",
      "δ#             δ",
      "α#####  ⓗⓖ#####α",
      "ααδαδαδαδδααδδαα"
    ],
    [
      "ααη    δδ    δαα",
      "α#a      ηαηηa#α",
      "ηa            aη",
      "δa            aδ",
      "δa  cc        aδ",
      "α#  dd        #α",
      "η              η",
      "δ              δ",
      "δ              δ",
      "δ              δ",
      "α#     ##     #α",
      "δa            aδ",
      "δa            aδ",
      "δa            aδ",
      "α#aaa#    #aaa#α",
      "ααηαδαηαδδααδδαα"
    ],
    [
      "ααη    δδ    δαα",
      "α#a      ηαηηa#α",
      "ηa            aη",
      "δa            aδ",
      "δa            aδ",
      "α#  cc        #α",
      "η   dd         η",
      "δ              δ",
      "δ              δ",
      "δ              δ",
      "α#     ##     #α",
      "δa            aδ",
      "δa            aδ",
      "δa            aδ",
      "α#aaa#    #aaa#α",
      "ααηαδαηαδδααδδαα"
    ],
    [
      "ααη    δδ    δαα",
      "α#aηηαηLLηαηηa#α",
      "ηa            aη",
      "δa            aδ",
      "δa            aδ",
      "α#E          E#α",
      "η   cc         η",
      "δ   dd         δ",
      "δ              δ",
      "δ             Lδ",
      "α#E   ###    E#α",
      "δa            aδ",
      "δa            aδ",
      "δa            aδ",
      "α#aaa#    #aaa#α",
      "ααηαδαηαδδααδδαα"
    ],
    [
      "ααδ    δδ    δαα",
      "α##δδαδ##δαδδ##α",
      "δ##############δ",
      "δ###  #########δ",
      "δ###  #########δ",
      "α###  #########α",
      "δ###  #########δ",
      "δ###cc#########δ",
      "δ###dd#########δ",
      "δ###### #######δ",
      "α##############α",
      "δ##############δ",
      "δ##############δ",
      "δ##############δ",
      "α##############α",
      "ααδαδαδαδδααδδαα"
    ]
  ],
  "refpalette": "rotwire:furnished_facades"
}
