{
  "xsize": 16,
  "zsize": 16,
  "slices": [
    [
      "###    ##    ###",
      "################",
      "################",
      "################",
      "################",
      "####  ##########",
      "####  ##########",
      "####  ##########",
      "####cc##########",
      "################",
      "################",
      "################",
      "################",
      "################",
      "################",
      "################"
    ],
    [
      "ααδδδδδδδ    δαα",
      "α##    ⓒⓑδαδδ##α",
      "δ#F      ①   F#δ",
      "δ#  cc        #δ",
      "δ#  dd       F#δ",
      "α#    #  ######α",
      "δ     :        δ",
      "δ     :      . δ",
      "δ     :      . δ",
      "δ              δ",
      "α#     ##     #α",
      "δ#            #δ",
      "δ#            #δ",
      "δ#            #δ",
      "α#####ⓜⓛⓗⓖ#####α",
      "ααδαδαδαδδααδδαα"
    ],
    [
      "ααη    δδ    δαα",
      "α#a      ηαηηa#α",
      "ηa            aη",
      "δa            aδ",
      "δa  cc        aδ",
      "α#aadd#  #aaaa#α",
      "η              η",
      "δ -          - δ",
      "δ -          - δ",
      "δ              δ",
      "α#     ##     #α",
      "δa            aδ",
      "δa            aδ",
      "δa            aδ",
      "α#aaa#    #aaa#α",
      "ααηαδαηαδδααδδαα"
    ],
    [
      "ααη    δδ    δαα",
      "α#a      ηαηηa#α",
      "ηa            aη",
      "δa            aδ",
      "δa            aδ",
      "α#aacc####aaaa#α",
      "η   dd         η",
      "δ              δ",
      "δ              δ",
      "δ              δ",
      "α#     ##     #α",
      "δa            aδ",
      "δa            aδ",
      "δa            aδ",
      "α#aaa#    #aaa#α",
      "ααηαδαηαδδααδδαα"
    ],
    [
      "ααη    δδ    δαα",
      "α#aηηαηLLηαηηa#α",
      "ηa            aη",
      "δa            aδ",
      "δa    E  E    aδ",
      "α###  #########α",
      "η⑪  cc        ⑬η",
      "δ⑭  dd        ⑯δ",
      "δ⑭            ⑯δ",
      "δ⑪            ⑬δ",
      "α#E   ###    E#α",
      "δa            aδ",
      "δa            aδ",
      "δa            aδ",
      "α#aaa#    #aaa#α",
      "ααηαδαηαδδααδδαα"
    ],
    [
      "ααδ    δδ    δαα",
      "α##δδαδ##δαδδ##α",
      "δ##############δ",
      "δ###  #########δ",
      "δ###  #########δ",
      "α###  #########α",
      "δ###  #########δ",
      "δ###cc#########δ",
      "δ###dd#########δ",
      "δ###### #######δ",
      "α##############α",
      "δ##############δ",
      "δ##############δ",
      "δ##############δ",
      "α##############α",
      "ααδαδαδαδδααδδαα"
    ]
  ],
  "refpalette": "rotwire:furnished_facades"
}
