{
  "xsize": 16,
  "zsize": 16,
  "slices": [
    [
      "###    ##    ###",
      "################",
      "################",
      "################",
      "################",
      "####  ##########",
      "####  ##########",
      "####  ##########",
      "####cc##########",
      "################",
      "################",
      "################",
      "################",
      "################",
      "################",
      "################"
    ],
    [
      "ααδδδδδδδ    δαα",
      "α##    ⓛⓐδαδδ##α",
      "δ#          #D#δ",
      "δ#  cc      #D#δ",
      "δ#  dd:     #D#δ",
      "α#    :     ###α",
      "δ     :        δ",
      "δF    : ④⑱⑤   Lδ",
      "δF    :       Lδ",
      "δ              δ",
      "α#     ##     #α",
      "δ#            #δ",
      "δ#    . .     #δ",
      "δ#            #δ",
      "α#####L⑥⑦L#####α",
      "ααδαδαδαδδααδδαα"
    ],
    [
      "ααη    δδ    δαα",
      "α#a      ηαηηa#α",
      "ηa           Kaη",
      "δa           Kaδ",
      "δa  cc       Kaδ",
      "α#  dd        #α",
      "η              η",
      "δ             Lδ",
      "δ             Lδ",
      "δ              δ",
      "α#     ##     #α",
      "δa            aδ",
      "δa    - -     aδ",
      "δa            aδ",
      "α#aaa#L  L#aaa#α",
      "ααηαδαηαδδααδδαα"
    ],
    [
      "ααη    δδ    δαα",
      "α#a    ⑫⑫ηαηηa#α",
      "ηa            aη",
      "δa            aδ",
      "δa            aδ",
      "α#  cc        #α",
      "η   dd         η",
      "δ              δ",
      "δ              δ",
      "δ              δ",
      "α#     ##     #α",
      "δa            aδ",
      "δa            aδ",
      "δa            aδ",
      "α#aaa#LⓑⓑL#aaa#α",
      "ααηαδαηαδδααδδαα"
    ],
    [
      "ααη    δδ    δαα",
      "α#aηηαη  ηαηηa#α",
      "ηa            aη",
      "δa            aδ",
      "δa            aδ",
      "α#E          E#α",
      "η   cc         η",
      "δ   dd         δ",
      "δ              δ",
      "δ              δ",
      "α#E   ###    E#α",
      "δa            aδ",
      "δa            aδ",
      "δa            aδ",
      "α#aaa#    #aaa#α",
      "ααηαδαηαδδααδδαα"
    ],
    [
      "ααδ    δδ    δαα",
      "α##δδαδ##δαδδ##α",
      "δ##############δ",
      "δ###  #########δ",
      "δ###  #########δ",
      "α###  #########α",
      "δ###  #########δ",
      "δ###cc#########δ",
      "δ###dd#########δ",
      "δ###### #######δ",
      "α##############α",
      "δ##############δ",
      "δ##############δ",
      "δ##############δ",
      "α##############α",
      "ααδαδαδαδδααδδαα"
    ]
  ],
  "refpalette": "rotwire:furnished_facades"
}
