{
  "xsize": 16,
  "zsize": 16,
  "slices": [
    [
      "################",
      "################",
      "################",
      "################",
      "################",
      "################",
      "################",
      "################",
      "################",
      "############  ##",
      "############  ##",
      "############  ##",
      "############cc##",
      "################",
      "################",
      "################"
    ],
    [
      "##a#a#a##a#a#a##",
      "#⑨L#   ⑨ⓓ ⓒⓑ#  #",
      "a⑧ #F  ⑧  ① #  a",
      "#  #F      L#  #",
      "a  #$      L#  a",
      "#  #        #  #",
      "a              a",
      "#  #        cc #",
      "#  #       :dd:#",
      "a  #       :  :a",
      "#  ########:  :#",
      "a      ⑫⑫  :  :a",
      "#          :  :#",
      "a              a",
      "#    F    F    #",
      "##a#a#a##a#a#a##"
    ],
    [
      "##a#a#a##a#a#a##",
      "#  #        #  #",
      "a  #        #  a",
      "#  #       L#  #",
      "a  #*      L#  a",
      "#  #        #  #",
      "a              a",
      "#  #           #",
      "#  #        cc #",
      "a  #        dd a",
      "#  #########   #",
      "a      ⑫⑫      a",
      "#              #",
      "a              a",
      "#              #",
      "##a#a#a##a#a#a##"
    ],
    [
      "################",
      "#  #        #  #",
      "#  #        #  #",
      "#  #        #  #",
      "#  #        #  #",
      "#  #        #  #",
      "#  #           #",
      "#  #           #",
      "#  #           #",
      "#  #        cc #",
      "#  #########dd #",
      "#              #",
      "#              #",
      "#              #",
      "#              #",
      "################"
    ],
    [
      "##a#a#a##a#a#a##",
      "#LL#        #  #",
      "a  #        #  a",
      "#  #        #  #",
      "a  #        #  a",
      "#  #        #  #",
      "a  #        #  a",
      "#  #           #",
      "#  #           #",
      "a  #           a",
      "#  #########cc #",
      "a       E   dd a",
      "#              #",
      "a              a",
      "#              #",
      "##a#a#a##a#a#a##"
    ],
    [
      "##a#a#a##a#a#a##",
      "#LL#        #  #",
      "a  #        #  a",
      "#  #        #  #",
      "a  #        #  a",
      "#  #        #  #",
      "a  #        #  a",
      "#  #           #",
      "#  #           #",
      "a  #           a",
      "#  #########   #",
      "a       {   cc a",
      "#           dd #",
      "a              a",
      "#              #",
      "##a#a#a##a#a#a##"
    ]
  ],
  "refpalette": "biohazard:handcrafted_furnishings"
}
