{
  "xsize": 16,
  "zsize": 16,
  "slices": [
    [
      "################",
      "################",
      "################",
      "################",
      "################",
      "################",
      "################",
      "################",
      "################",
      "############  ##",
      "############  ##",
      "############  ##",
      "############cc##",
      "################",
      "################",
      "################"
    ],
    [
      "##a#a#a##a#a#a##",
      "#    :  ⑨ⓓ:    #",
      "a    :  ⑧ :    a",
      "#  # :    : #  #",
      "a    :    :    a",
      "#:: ::    :: ::#",
      "a              a",
      "#           cc #",
      "#          :dd:#",
      "a          :  :a",
      "###########:  :#",
      "a  FFF    #:  :a",
      "#F         :  :#",
      "a              a",
      "#⑥⑦       #    #",
      "##a#a#a##a#a#a##"
    ],
    [
      "##a#a#a##a#a#a##",
      "#    :    :    #",
      "a    :    :    a",
      "#  # :    : #  #",
      "a    :    :    a",
      "#:: ::    :: ::#",
      "a              a",
      "#              #",
      "#           cc #",
      "a           dd a",
      "###########    #",
      "a         #    a",
      "#              #",
      "a              a",
      "#         #    #",
      "##a#a#a##a#a#a##"
    ],
    [
      "################",
      "######    ######",
      "### ##    ## ###",
      "######    ######",
      "######    ######",
      "######    ######",
      "#              #",
      "#              #",
      "#              #",
      "#           cc #",
      "########### dd #",
      "#         #    #",
      "#         #    #",
      "#         #    #",
      "#         #    #",
      "################"
    ],
    [
      "##a#a#a##a#a#a##",
      "#    :    :    #",
      "a    :    :    a",
      "# 1  :    :  1 #",
      "a  C :    : C  a",
      "#:::::    :::::#",
      "a              a",
      "#              #",
      "#              #",
      "a              a",
      "########### cc #",
      "a         # dd a",
      "#  E      #    #",
      "a         #    a",
      "#         #    #",
      "##a#a#a##a#a#a##"
    ],
    [
      "##a#a#a##a#a#a##",
      "#    :    :    #",
      "a    :    :    a",
      "#    :    :    #",
      "a    :    :    a",
      "#:::::    :::::#",
      "a              a",
      "#              #",
      "#              #",
      "a              a",
      "###########    #",
      "a         # cc a",
      "#  {      # dd #",
      "a         #    a",
      "#         #    #",
      "##a#a#a##a#a#a##"
    ]
  ],
  "refpalette": "biohazard:handcrafted_furnishings"
}
