{
  "xsize": 16,
  "zsize": 16,
  "slices": [
    [
      "################",
      "################",
      "################",
      "################",
      "################",
      "################",
      "################",
      "################",
      "################",
      "#######l########",
      "################",
      "################",
      "################",
      "################",
      "################",
      "################"
    ],
    [
      "##a#a#a##a#a#a##",
      "#⑨L#   ⑨ⓓ ⓒⓑ#  #",
      "a⑧ #F  ⑧  ① #  a",
      "#  #F      L#  #",
      "a  #$      L#  a",
      "#  #        #  #",
      "a              a",
      "#  #        #  #",
      "#  #        #  #",
      "a  #   l    #  a",
      "#  ##########  #",
      "a      ⑫⑫      a",
      "#              #",
      "a              a",
      "#    F    F    #",
      "##a#a#a##a#a#a##"
    ],
    [
      "##a#a#a##a#a#a##",
      "#  #        #  #",
      "a  #        #  a",
      "#  #       L#  #",
      "a  #*      L#  a",
      "#  #        #  #",
      "a              a",
      "#  #        #  #",
      "#  #        #  #",
      "a  #   l    #  a",
      "#  ##########  #",
      "a      ⑫⑫      a",
      "#              #",
      "a              a",
      "#              #",
      "##a#a#a##a#a#a##"
    ],
    [
      "################",
      "#  #        #  #",
      "#  #        #  #",
      "#  #        #  #",
      "#  #        #  #",
      "#  #        #  #",
      "#  #        #  #",
      "#  #        #  #",
      "#  #        #  #",
      "#  #   l    #  #",
      "#  ##########  #",
      "#              #",
      "#              #",
      "#              #",
      "#              #",
      "################"
    ],
    [
      "##a#a#a##a#a#a##",
      "#LL#        #  #",
      "a  #        #  a",
      "#  #        #  #",
      "a  #        #  a",
      "#  #        #  #",
      "a  #        #  a",
      "#  #        #  #",
      "#  #        #  #",
      "a  #   l    #  a",
      "#  ##########  #",
      "a       E      a",
      "#              #",
      "a              a",
      "#              #",
      "##a#a#a##a#a#a##"
    ],
    [
      "##a#a#a##a#a#a##",
      "#LL#        #  #",
      "a  #        #  a",
      "#  #        #  #",
      "a  #        #  a",
      "#  #        #  #",
      "a  #        #  a",
      "#  #        #  #",
      "#  #        #  #",
      "a  #   l    #  a",
      "#  ##########  #",
      "a       {      a",
      "#              #",
      "a              a",
      "#              #",
      "##a#a#a##a#a#a##"
    ]
  ],
  "refpalette": "biohazard:handcrafted_furnishings"
}
