{
  "xsize": 16,
  "zsize": 16,
  "slices": [
    [
      "################",
      "################",
      "################",
      "################",
      "################",
      "################",
      "################",
      "################",
      "################",
      "############  ##",
      "############  ##",
      "############  ##",
      "############cc##",
      "################",
      "################",
      "################"
    ],
    [
      "##a#a#a##a#a#a##",
      "#⑮ⓐⓛ           #",
      "a              a",
      "#              #",
      "a              a",
      "#              #",
      "a    ## ##     a",
      "#④⑱⑤ #   #  cc #",
      "#    #   # :dd:#",
      "a   *#   # :  :a",
      "## ########:  :#",
      "a     FFF  :  :a",
      "#          :  :#",
      "a              a",
      "#        ⑥⑦    #",
      "##a#a#a##a#a#a##"
    ],
    [
      "##a#a#a##a#a#a##",
      "#              #",
      "a              a",
      "#              #",
      "a              a",
      "#              #",
      "a    ## ##     a",
      "#    #   #     #",
      "#    #   #  cc #",
      "a    #   #  dd a",
      "## ########a  ##",
      "a              a",
      "#              #",
      "a              a",
      "#              #",
      "##a#a#a##a#a#a##"
    ],
    [
      "################",
      "#              #",
      "#          ### #",
      "#          ### #",
      "#          ### #",
      "#              #",
      "#    #####     #",
      "#    #   #     #",
      "#    #   #     #",
      "#    #   #  cc #",
      "############dd##",
      "#              #",
      "#              #",
      "#              #",
      "#              #",
      "################"
    ],
    [
      "##a#a#a##a#a#a##",
      "#              #",
      "a          { { a",
      "#           C  #",
      "a          { { a",
      "#              #",
      "a    #####     a",
      "#    #  E#     #",
      "#    #   #     #",
      "a    #   #     a",
      "###########acc##",
      "a           dd a",
      "#              #",
      "a              a",
      "#              #",
      "##a#a#a##a#a#a##"
    ],
    [
      "##a#a#a##a#a#a##",
      "#              #",
      "a          { { a",
      "#              #",
      "a          { { a",
      "#              #",
      "a    #####     a",
      "#    #  {#     #",
      "#    #   #     #",
      "a    #   #     a",
      "#####1######  ##",
      "a    #      cc a",
      "#    :      dd #",
      "a    :         a",
      "#    #         #",
      "##a#a#a##a#a#a##"
    ]
  ],
  "refpalette": "biohazard:handcrafted_furnishings"
}
