{
  "xsize": 16,
  "zsize": 16,
  "slices": [
    [
      "  ############  ",
      " ############## ",
      "################",
      "################",
      " ###############",
      " ###############",
      " ###############",
      " ###############",
      " ###############",
      " ###########  ##",
      " ###########  ##",
      " ###########  ##",
      "############cc##",
      "################",
      " ############## ",
      "  ############  "
    ],
    [
      "  αααξααααξααα  ",
      " ξ F      QQQ ξ ",
      "α              α",
      "α        ④③③⑤  ξ",
      " α       ④③③⑤  α",
      " ξ             ξ",
      " α             α",
      " α  L       cc α",
      " α FL      #dd ξ",
      " α CL      #   α",
      " ξ####### ##   ξ",
      " αⓐⓓⓐLⓐ⑫⑫      α",
      "α              ξ",
      "α              α",
      " ξⓜⓛ          ξ ",
      "  αααξααααξααα  "
    ],
    [
      "  ηηηξηηηηξηηη  ",
      " η        **  η ",
      "η              η",
      "η              ξ",
      " η             η",
      " ξ             ξ",
      " η             η",
      " η  L          η",
      " η  L      #cc ξ",
      " η  L      #dd η",
      " ξ::##### ##  #ξ",
      " η     ⑫⑫      η",
      "η              ξ",
      "η              η",
      " η            η ",
      "  ηηηξηηηηξηηη  "
    ],
    [
      "  ηηηξηηηηξηηη  ",
      " η            η ",
      "η              η",
      "η              ξ",
      " η             η",
      " ξ             ξ",
      " η             η",
      " η             η",
      " η             ξ",
      " η          cc η",
      " ξ::########dd#ξ",
      " η             η",
      "η              ξ",
      "η              η",
      " η            η ",
      "  ηηηξηηηηξηηη  "
    ],
    [
      "  ηηηξηηηηξηηη  ",
      " η            η ",
      "η              η",
      "η              ξ",
      " η             η",
      " ξ             ξ",
      " η             η",
      " η             η",
      " η             ξ",
      " η   E         η",
      " ξ::########cc#ξ",
      " η   E      dd η",
      "η              ξ",
      "η              η",
      " η            η ",
      "  ηηηξηηηηξηηη  "
    ],
    [
      "  αααξααααξααα  ",
      " ξ            ξ ",
      "α              α",
      "α              ξ",
      " α             α",
      " ξ             ξ",
      " α             α",
      " α             α",
      " α             ξ",
      " α   {         α",
      " ξ##########  #ξ",
      " α   {      cc α",
      "α           dd ξ",
      "α              α",
      " ξ            ξ ",
      "  αααξααααξααα  "
    ]
  ],
  "refpalette": "biohazard:furnished_facades"
}
