{
  "xsize": 16,
  "zsize": 16,
  "slices": [
    [
      "################",
      "################",
      "################",
      "################",
      "################",
      "################",
      "################",
      "################",
      "################",
      "#######l########",
      "################",
      "################",
      "################",
      "################",
      "################",
      "################"
    ],
    [
      "##a#a#a##a#a#a##",
      "# QQ #LLLL#   F#",
      "a    #    #②   a",
      "#          ③  F#",
      "a    #    #①   a",
      "### ##    ## ###",
      "a    ## ##L    a",
      "#    #   #     #",
      "#    #         #",
      "a    # l #     a",
      "#::::####1## ###",
      "a    :   L#    a",
      "#    :    #  . #",
      "a    :       . a",
      "#C C :⑥⑦  #    #",
      "##a#a#a##a#a#a##"
    ],
    [
      "##a#a#a##a#a#a##",
      "# ** #L⑫⑫L#    #",
      "a    #    #    a",
      "#              #",
      "a    #    #    a",
      "### ##    ## ###",
      "a    ## ##L    a",
      "#    #   #     #",
      "#    #         #",
      "a    # l #     a",
      "#::::####### ###",
      "a    :   L#    a",
      "#    :    #  - #",
      "a    :       - a",
      "#    :    #    #",
      "##a#a#a##a#a#a##"
    ],
    [
      "################",
      "#    #L⑫⑫L#    #",
      "#    #    #    #",
      "#    #    #    #",
      "#    #    #    #",
      "######    ######",
      "#    #####L    #",
      "#    #   #     #",
      "#    #   #     #",
      "#    # l #     #",
      "#::::###########",
      "#    :    #    #",
      "#    :    #    #",
      "#    :    #    #",
      "#    :    #    #",
      "################"
    ],
    [
      "##a#a#a##a#a#a##",
      "#    #    #    #",
      "a    #    #    a",
      "#    #    # E  #",
      "a    #    #    a",
      "######    ######",
      "a    #####     a",
      "#    #  E#     #",
      "#    #   #     #",
      "a    # l #     a",
      "################",
      "a    #    #    a",
      "#    #    #    #",
      "a    #    #    a",
      "#    #    #    #",
      "##a#a#a##a#a#a##"
    ],
    [
      "##a#a#a##a#a#a##",
      "#    #    #    #",
      "a    #    #    a",
      "#    #    # {  #",
      "a    #    #    a",
      "######    ######",
      "a    #####     a",
      "#    #  {#     #",
      "#    #   #     #",
      "a    # l #     a",
      "#####1##########",
      "a    #    #    a",
      "#    #    #    #",
      "a    #    #    a",
      "#    #    #    #",
      "##a#a#a##a#a#a##"
    ]
  ],
  "refpalette": "biohazard:handcrafted_furnishings"
}
