{
  "xsize": 16,
  "zsize": 16,
  "slices": [
    [
      "################",
      "################",
      "################",
      "################",
      "################",
      "################",
      "################",
      "################",
      "################",
      "############  ##",
      "############  ##",
      "############  ##",
      "############cc##",
      "################",
      "################",
      "################"
    ],
    [
      "##a#a#a##a#a#a##",
      "#  F      QQQ  #",
      "a              a",
      "#        ④③③⑤  #",
      "a        ④③③⑤  a",
      "#             F#",
      "a              a",
      "#   L       cc #",
      "#  FL      :dd:#",
      "a  CL      :  :a",
      "###########:  :#",
      "a ⓐⓓⓐLⓐ⑫⑫  :  :a",
      "#          :  :#",
      "a              a",
      "# ⓜⓛ           #",
      "##a#a#a##a#a#a##"
    ],
    [
      "##a#a#a##a#a#a##",
      "#         **   #",
      "a              a",
      "#              #",
      "a              a",
      "#              #",
      "a              a",
      "#   L          #",
      "#   L       cc #",
      "a   L       dd a",
      "##::########  ##",
      "a      ⑫⑫      a",
      "#              #",
      "a              a",
      "#              #",
      "##a#a#a##a#a#a##"
    ],
    [
      "################",
      "#              #",
      "#              #",
      "#              #",
      "#              #",
      "#              #",
      "#              #",
      "#              #",
      "#              #",
      "#           cc #",
      "##::########dd##",
      "#              #",
      "#              #",
      "#              #",
      "#              #",
      "################"
    ],
    [
      "##a#a#a##a#a#a##",
      "#              #",
      "a              a",
      "#              #",
      "a              a",
      "#              #",
      "a              a",
      "#              #",
      "#              #",
      "a    E         a",
      "##::########cc##",
      "a    E      dd a",
      "#              #",
      "a              a",
      "#              #",
      "##a#a#a##a#a#a##"
    ],
    [
      "##a#a#a##a#a#a##",
      "#              #",
      "a              a",
      "#              #",
      "a              a",
      "#              #",
      "a              a",
      "#              #",
      "#              #",
      "a    {         a",
      "############  ##",
      "a    {      cc a",
      "#           dd #",
      "a              a",
      "#              #",
      "##a#a#a##a#a#a##"
    ]
  ],
  "refpalette": "biohazard:handcrafted_furnishings"
}
