{
  "xsize": 16,
  "zsize": 16,
  "slices": [
    [
      "################",
      "################",
      "################",
      "################",
      "################",
      "################",
      "################",
      "################",
      "################",
      "############  ##",
      "############  ##",
      "############  ##",
      "############cc##",
      "################",
      "################",
      "################"
    ],
    [
      "##a#a#a##a#a#a##",
      "# QQ #LLLL#   F#",
      "a    #    #②   a",
      "#          ③  F#",
      "a    #    #①   a",
      "### ##    ## ###",
      "a    ## ##L    a",
      "#    #   #  cc #",
      "#    #     :dd:#",
      "a    #   # :  :a",
      "#::::####1#:  :#",
      "a    :   L#:  :a",
      "#    :    #:  :#",
      "a    :         a",
      "#C C :⑥⑦  #    #",
      "##a#a#a##a#a#a##"
    ],
    [
      "##a#a#a##a#a#a##",
      "# ** #L⑫⑫L#    #",
      "a    #    #    a",
      "#              #",
      "a    #    #    a",
      "### ##    ## ###",
      "a    ## ##L    a",
      "#    #   #     #",
      "#    #      cc #",
      "a    #   #  dd a",
      "#::::#######  ##",
      "a    :   L#    a",
      "#    :    #    #",
      "a    :         a",
      "#    :    #    #",
      "##a#a#a##a#a#a##"
    ],
    [
      "################",
      "#    #L⑫⑫L#    #",
      "#    #    #    #",
      "#    #    #    #",
      "#    #    #    #",
      "######    ######",
      "#    #####L    #",
      "#    #   #     #",
      "#    #   #     #",
      "#    #   #  cc #",
      "#::::#######dd##",
      "#    :    #    #",
      "#    :    #    #",
      "#    :    #    #",
      "#    :    #    #",
      "################"
    ],
    [
      "##a#a#a##a#a#a##",
      "#    #    #    #",
      "a    #    #    a",
      "#    #    # E  #",
      "a    #    #    a",
      "######    ######",
      "a    #####     a",
      "#    #  E#     #",
      "#    #   #     #",
      "a    #   #     a",
      "############cc##",
      "a    #    # dd a",
      "#    #    #    #",
      "a    #    #    a",
      "#    #    #    #",
      "##a#a#a##a#a#a##"
    ],
    [
      "##a#a#a##a#a#a##",
      "#    #    #    #",
      "a    #    #    a",
      "#    #    # {  #",
      "a    #    #    a",
      "######    ######",
      "a    #####     a",
      "#    #  {#     #",
      "#    #   #     #",
      "a    #   #     a",
      "#####1######  ##",
      "a    #    # cc a",
      "#    #    # dd #",
      "a    #    #    a",
      "#    #    #    #",
      "##a#a#a##a#a#a##"
    ]
  ],
  "refpalette": "biohazard:handcrafted_furnishings"
}
