{
  "xsize": 16,
  "zsize": 16,
  "slices": [
    [
      "################",
      "################",
      "################",
      "################",
      "################",
      "################",
      "################",
      "################",
      "################",
      "############  ##",
      "############  ##",
      "############  ##",
      "############cc##",
      "################",
      "################",
      "################"
    ],
    [
      "##a#a#a##a#a#a##",
      "#  ⓕⓓ ⓐⓛ       #",
      "a  ⓔ           a",
      "#              #",
      "a   QQQLCQQQ   a",
      "#   Q#####1Q   #",
      "a   Q#LLLL#    a",
      "#   F#      cc #",
      "#   F#     :dd:#",
      "a   Q#    #:  :a",
      "#   Q#####1:  :#",
      "a   QQQFFQQ:  :a",
      "#          :  :#",
      "a              a",
      "#         ⓗⓖ   #",
      "##a#a#a##a#a#a##"
    ],
    [
      "##a#a#a##a#a#a##",
      "#              #",
      "a              a",
      "#              #",
      "a   *     *e   a",
      "#    ######    #",
      "a    #L⑮⑮L#    a",
      "#    #         #",
      "#    #      cc #",
      "a    #    #*dd a",
      "#    ######    #",
      "a   *    *     a",
      "#              #",
      "a              a",
      "#              #",
      "##a#a#a##a#a#a##"
    ],
    [
      "################",
      "#              #",
      "#              #",
      "#              #",
      "#              #",
      "#    ######    #",
      "#    #LLLL#    #",
      "#    #    #    #",
      "#    #    #    #",
      "#    #    # cc #",
      "#    ###### dd #",
      "#              #",
      "#              #",
      "#              #",
      "#              #",
      "################"
    ],
    [
      "##a#a#a##a#a#a##",
      "#              #",
      "a              a",
      "#              #",
      "a              a",
      "#    ######    #",
      "a    #L⑮⑮L#    a",
      "#    #    #    #",
      "#    #    #    #",
      "a    #    #    a",
      "#    ###### cc #",
      "a           dd a",
      "#  E           #",
      "a              a",
      "#              #",
      "##a#a#a##a#a#a##"
    ],
    [
      "##a#a#a##a#a#a##",
      "#              #",
      "a              a",
      "#              #",
      "a              a",
      "#    ######    #",
      "a    #LLLL#    a",
      "#    #    #    #",
      "#    #    #    #",
      "a    #    #    a",
      "#    ######    #",
      "a           cc a",
      "#  {        dd #",
      "a              a",
      "#              #",
      "##a#a#a##a#a#a##"
    ]
  ],
  "refpalette": "biohazard:handcrafted_furnishings"
}
