{
  "xsize": 16,
  "zsize": 16,
  "slices": [
    [
      "################",
      "################",
      "################",
      "################",
      "################",
      "################",
      "################",
      "################",
      "################",
      "#######l########",
      "################",
      "################",
      "################",
      "################",
      "################",
      "################"
    ],
    [
      "##a#a#a##a#a#a##",
      "#  ⓕⓓ ⓐⓛ       #",
      "a  ⓔ           a",
      "#              #",
      "a   QQQLCQQQ   a",
      "#   Q#####1Q   #",
      "a   Q#LLLL#Q   a",
      "#   F#         #",
      "#   F#         #",
      "a   Q# l  #Q   a",
      "#   Q#####1Q   #",
      "a   QQQFFQQQ   a",
      "#              #",
      "a              a",
      "#         ⓗⓖ   #",
      "##a#a#a##a#a#a##"
    ],
    [
      "##a#a#a##a#a#a##",
      "#              #",
      "a              a",
      "#              #",
      "a   *     *e   a",
      "#    ######    #",
      "a    #L⑮⑮L#*   a",
      "#    #         #",
      "#    #         #",
      "a    # l  #*   a",
      "#    ######    #",
      "a   *    *     a",
      "#              #",
      "a              a",
      "#              #",
      "##a#a#a##a#a#a##"
    ],
    [
      "################",
      "#              #",
      "#              #",
      "#              #",
      "#              #",
      "#    ######    #",
      "#    #LLLL#    #",
      "#    #    #    #",
      "#    #    #    #",
      "#    # l  #    #",
      "#    ######    #",
      "#              #",
      "#              #",
      "#              #",
      "#              #",
      "################"
    ],
    [
      "##a#a#a##a#a#a##",
      "#              #",
      "a              a",
      "#              #",
      "a              a",
      "#    ######    #",
      "a    #L⑮⑮L#    a",
      "#    #    #    #",
      "#    #    #    #",
      "a    # l  #    a",
      "#    ######    #",
      "a              a",
      "#  E           #",
      "a              a",
      "#              #",
      "##a#a#a##a#a#a##"
    ],
    [
      "##a#a#a##a#a#a##",
      "#              #",
      "a              a",
      "#              #",
      "a              a",
      "#    ######    #",
      "a    #LLLL#    a",
      "#    #    #    #",
      "#    #    #    #",
      "a    # l  #    a",
      "#    ######    #",
      "a              a",
      "#  {           #",
      "a              a",
      "#              #",
      "##a#a#a##a#a#a##"
    ]
  ],
  "refpalette": "biohazard:handcrafted_furnishings"
}
