{
  "xsize": 16,
  "zsize": 16,
  "slices": [
    [
      "  ############  ",
      " ############## ",
      "################",
      "################",
      " ###############",
      " ###############",
      " ###############",
      " ###############",
      " ###############",
      " ###########  ##",
      " ###########  ##",
      " ###########  ##",
      "############cc##",
      "################",
      " ############## ",
      "  ############  "
    ],
    [
      "  αααξααααξααα  ",
      " ξⓐⓛ⑮④        ξ ",
      "α              α",
      "α              ξ",
      " α             α",
      " ξ             ξ",
      " α   ## ##     α",
      " α⑱⑤ #F F#  cc α",
      " α   #F F# #dd ξ",
      " α  *#FFF# #   α",
      " ξ #########  #ξ",
      " α    FFF      α",
      "α              ξ",
      "α              α",
      " ξ       ⑥⑦   ξ ",
      "  αααξααααξααα  "
    ],
    [
      "  ηηηξηηηηξηηη  ",
      " η            η ",
      "η              η",
      "η              ξ",
      " η             η",
      " ξ             ξ",
      " η   ## ##     η",
      " η   #   #     η",
      " η   #   #  cc ξ",
      " η   #   # #dd η",
      " ξ #########  #ξ",
      " η             η",
      "η              ξ",
      "η              η",
      " η            η ",
      "  ηηηξηηηηξηηη  "
    ],
    [
      "  ηηηξηηηηξηηη  ",
      " η            η ",
      "η          ### η",
      "η          ### ξ",
      " η         ### η",
      " ξ             ξ",
      " η   #####     η",
      " η   #   #     η",
      " η   #   #     ξ",
      " η   #   #  cc η",
      " ξ##########dd#ξ",
      " η             η",
      "η              ξ",
      "η              η",
      " η            η ",
      "  ηηηξηηηηξηηη  "
    ],
    [
      "  ηηηξηηηηξηηη  ",
      " η            η ",
      "η          { { η",
      "η           C  ξ",
      " η         { { η",
      " ξ             ξ",
      " η   #####     η",
      " η   #  E#     η",
      " η   #   #     ξ",
      " η   #   #     η",
      " ξ#########acc#ξ",
      " η          dd η",
      "η              ξ",
      "η              η",
      " η            η ",
      "  ηηηξηηηηξηηη  "
    ],
    [
      "  αααξααααξααα  ",
      " ξ            ξ ",
      "α          { { α",
      "α              ξ",
      " α         { { α",
      " ξ             ξ",
      " α   #####     α",
      " α   #  {#     α",
      " α   #   #     ξ",
      " α   #   #     α",
      " ξ###1######  #ξ",
      " α   #      cc α",
      "α    :      dd ξ",
      "α    :         α",
      " ξ   #        ξ ",
      "  αααξααααξααα  "
    ]
  ],
  "refpalette": "biohazard:furnished_facades"
}
