{
  "xsize": 16,
  "zsize": 16,
  "slices": [
    [
      "################",
      "################",
      "################",
      "################",
      "################",
      "################",
      "################",
      "################",
      "################",
      "############  ##",
      "############  ##",
      "############  ##",
      "############cc##",
      "################",
      "################",
      "################"
    ],
    [
      "##a#a#a##a#a#a##",
      "#            ⓓⓕ#",
      "a $$$$    $$$$ⓔa",
      "# $QQ$    $QQ$ #",
      "a $QQ$    $QQ$ a",
      "# $$$$   ②$$$$ #",
      "a        ③     a",
      "#        ①  cc #",
      "#          :dd:#",
      "a          :  :a",
      "#:::::###:::  :#",
      "a          :  :a",
      "#L         :  :#",
      "a              a",
      "#      ⑥⑦      #",
      "##a#a#a##a#a#a##"
    ],
    [
      "##a#a#a##a#a#a##",
      "#              #",
      "a ++++    ++++ a",
      "# +W≈+    +≈W+ #",
      "a +≈W+    +W≈+ a",
      "# ++++    ++++ #",
      "a              a",
      "#              #",
      "#           cc #",
      "a           dd a",
      "#:::::###:::  :#",
      "a              a",
      "#L             #",
      "a              a",
      "#              #",
      "##a#a#a##a#a#a##"
    ],
    [
      "################",
      "#              #",
      "# ++++    ++++ #",
      "# +WW+    +WW+ #",
      "# +WW+    +WW+ #",
      "# ++++    ++++ #",
      "#              #",
      "#              #",
      "#              #",
      "#           cc #",
      "#:::::###:::dd:#",
      "#              #",
      "#              #",
      "#              #",
      "#              #",
      "################"
    ],
    [
      "##a#a#a##a#a#a##",
      "#              #",
      "a ++++    ++++ a",
      "# +WW+    +WW+ #",
      "a +WW+    +WW+ a",
      "# ++++    ++++ #",
      "a              a",
      "#              #",
      "#              #",
      "a              a",
      "#:::::###:::cc:#",
      "a       E   dd a",
      "#              #",
      "a              a",
      "#              #",
      "##a#a#a##a#a#a##"
    ],
    [
      "##a#a#a##a#a#a##",
      "#              #",
      "a ++++    ++++ a",
      "# +WW+    +WW+ #",
      "a +WW+    +WW+ a",
      "# ++++    ++++ #",
      "a              a",
      "#              #",
      "#              #",
      "a              a",
      "#:::::###:::  :#",
      "a       {   cc a",
      "#           dd #",
      "a              a",
      "#              #",
      "##a#a#a##a#a#a##"
    ]
  ],
  "refpalette": "biohazard:handcrafted_furnishings"
}
