{
    "xsize":  16,
    "zsize":  16,
    "slices":  [
                   [
                       "################",
                       "################",
                       "################",
                       "################",
                       "################",
                       "################",
                       "################",
                       "################",
                       "################",
                       "#######l########",
                       "################",
                       "################",
                       "################",
                       "################",
                       "################",
                       "################"
                   ],
                   [
                       "##a#a#a##a#a#a##",
                       "#  F      QQQ  #",
                       "a              a",
                       "#              #",
                       "a              a",
                       "#             F#",
                       "afg            a",
                       "#              #",
                       "# j            #",
                       "a      l       a",
                       "############  ##",
                       "a              a",
                       "#              #",
                       "a   y BzC      a",
                       "#   k A        #",
                       "##a#a#a##a#a#a##"
                   ],
                   [
                       "##a#a#a##a#a#a##",
                       "#         **   #",
                       "a              a",
                       "#              #",
                       "a              a",
                       "#              #",
                       "a              a",
                       "#              #",
                       "#              #",
                       "a      l       a",
                       "##::########  ##",
                       "a              a",
                       "#              #",
                       "a              a",
                       "#              #",
                       "##a#a#a##a#a#a##"
                   ],
                   [
                       "################",
                       "#              #",
                       "#              #",
                       "#              #",
                       "#              #",
                       "#              #",
                       "#              #",
                       "#              #",
                       "#              #",
                       "#      l       #",
                       "##::############",
                       "#              #",
                       "#              #",
                       "#              #",
                       "#              #",
                       "################"
                   ],
                   [
                       "##a#a#a##a#a#a##",
                       "#              #",
                       "a              a",
                       "#              #",
                       "a              a",
                       "#              #",
                       "a              a",
                       "#              #",
                       "#              #",
                       "a    E l       a",
                       "##::############",
                       "a    E         a",
                       "#              #",
                       "a              a",
                       "#              #",
                       "##a#a#a##a#a#a##"
                   ],
                   [
                       "##a#a#a##a#a#a##",
                       "#              #",
                       "a              a",
                       "#              #",
                       "a              a",
                       "#              #",
                       "a              a",
                       "#              #",
                       "#              #",
                       "a    { l       a",
                       "################",
                       "a    {         a",
                       "#              #",
                       "a              a",
                       "#              #",
                       "##a#a#a##a#a#a##"
                   ]
               ],
    "refpalette":  "biohazard:handcrafted_furnishings"
}
