{
  "xsize": 16,
  "zsize": 16,
  "slices": [
    [
      "  ############  ",
      " ############## ",
      "################",
      "################",
      " ###############",
      " ###############",
      " ###############",
      " ###############",
      " ###############",
      " ###########  ##",
      " ###########  ##",
      " ###########  ##",
      "############cc##",
      "################",
      " ############## ",
      "  ############  "
    ],
    [
      "  αααξααααξααα  ",
      " ξⓕ          ⓓξ ",
      "α $$$$    $$$$ⓔα",
      "α $QQ$    $$$$ ξ",
      " α$QQ$    $$$$ α",
      " ξ$$$$   ②$    ξ",
      " α       ③     α",
      " α       ①  cc α",
      " α         :dd:ξ",
      " α         :  :α",
      " ξ::::# #:::  :ξ",
      " α         :  :α",
      "αL         :  :ξ",
      "α              α",
      " ξ     ⑥⑦     ξ ",
      "  αααξααααξααα  "
    ],
    [
      "  ηηηξηηηηξηηη  ",
      " η            η ",
      "η ++++    ++++ η",
      "η +W≈+    +≈W+ ξ",
      " η+≈W+    +W≈+ η",
      " ξ++++    +    ξ",
      " η             η",
      " η             η",
      " η          cc ξ",
      " η          dd η",
      " ξ::::# #:::  :ξ",
      " η             η",
      "ηL             ξ",
      "η              η",
      " η            η ",
      "  ηηηξηηηηξηηη  "
    ],
    [
      "  ηηηξηηηηξηηη  ",
      " η            η ",
      "η ++++    ++++ η",
      "η +WW+    +WW+ ξ",
      " η+WW+    +WW+ η",
      " ξ++++    +    ξ",
      " η             η",
      " η             η",
      " η             ξ",
      " η          cc η",
      " ξ::::###:::dd:ξ",
      " η             η",
      "η              ξ",
      "η              η",
      " η            η ",
      "  ηηηξηηηηξηηη  "
    ],
    [
      "  ηηηξηηηηξηηη  ",
      " η            η ",
      "η ++++    ++++ η",
      "η +WW+    +WW+ ξ",
      " η+WW+    +WW+ η",
      " ξ++++    ++++ ξ",
      " η             η",
      " η             η",
      " η             ξ",
      " η             η",
      " ξ::::###:::cc:ξ",
      " η      E   dd η",
      "η              ξ",
      "η              η",
      " η            η ",
      "  ηηηξηηηηξηηη  "
    ],
    [
      "  αααξααααξααα  ",
      " ξ            ξ ",
      "α ++++    ++++ α",
      "α +WW+    +WW+ ξ",
      " α+WW+    +WW+ α",
      " ξ++++    ++++ ξ",
      " α             α",
      " α             α",
      " α             ξ",
      " α             α",
      " ξ::::###:::  :ξ",
      " α      {   cc α",
      "α           dd ξ",
      "α              α",
      " ξ            ξ ",
      "  αααξααααξααα  "
    ]
  ],
  "refpalette": "biohazard:furnished_facades"
}
