{
  "xsize": 16,
  "zsize": 16,
  "slices": [
    [
      "################",
      "################",
      "################",
      "################",
      "################",
      "################",
      "################",
      "################",
      "################",
      "############  ##",
      "############  ##",
      "############  ##",
      "############cc##",
      "################",
      "################",
      "################"
    ],
    [
      "##a#a#a##a#a#a##",
      "#        ⓒⓑ    #",
      "a        ①     a",
      "#  . .         #",
      "a              a",
      "#  . .         #",
      "a              a",
      "#           cc #",
      "#          :dd:#",
      "a          :  :a",
      "#  # LL#  L:  :#",
      "a          :  :a",
      "#          :  :#",
      "a              a",
      "#    ⓗⓖ ⓜⓛ  F  #",
      "##a#a#a##a#a#a##"
    ],
    [
      "##a#a#a##a#a#a##",
      "#              #",
      "a              a",
      "#  - -         #",
      "a              a",
      "#  - -         #",
      "a              a",
      "#              #",
      "#           cc #",
      "a           dd a",
      "#  # LL#  LL   #",
      "a              a",
      "#  E           #",
      "a              a",
      "#              #",
      "##a#a#a##a#a#a##"
    ],
    [
      "################",
      "#              #",
      "#              #",
      "#              #",
      "#              #",
      "#              #",
      "#              #",
      "#              #",
      "#              #",
      "#           cc #",
      "############dd##",
      "############  ##",
      "############  ##",
      "###########    #",
      "################",
      "################"
    ],
    [
      "##a#a#a##a#a#a##",
      "#              #",
      "a              a",
      "#              #",
      "a          E   a",
      "#              #",
      "a              a",
      "#              #",
      "#              #",
      "a              a",
      "#      #    cc #",
      "a           dd a",
      "#  . .    .    #",
      "a              a",
      "#FⓑⓑF      FⓑⓑF#",
      "##a#a#a##a#a#a##"
    ],
    [
      "##a#a#a##a#a#a##",
      "#              #",
      "a              a",
      "#              #",
      "a          {   a",
      "#              #",
      "a              a",
      "#              #",
      "#              #",
      "a              a",
      "#      #       #",
      "a           cc a",
      "#  - -    - dd #",
      "a              a",
      "#              #",
      "##a#a#a##a#a#a##"
    ]
  ],
  "refpalette": "biohazard:handcrafted_furnishings"
}
