{
  "xsize": 16,
  "zsize": 16,
  "slices": [
    [
      "  ############  ",
      " ############## ",
      "################",
      "################",
      " ###############",
      " ###############",
      " ###############",
      " ###############",
      " ###############",
      " ###########  ##",
      " ###########  ##",
      " ###########  ##",
      "############cc##",
      "################",
      " ############## ",
      "  ############  "
    ],
    [
      "  αααξααααξααα  ",
      " ξⓘⓘC#LLLL#   ξ ",
      "α    #    #②   α",
      "α          ③  Fξ",
      " α   #    #①   α",
      " ξ# ##    #    ξ",
      " α   ## ##     α",
      " α   #   #  cc α",
      " α   #     #dd ξ",
      " α   #   # #   α",
      " ξ:::####1##  #ξ",
      " α   :   L#    α",
      "α    :    #    ξ",
      "α    :         α",
      " ξ C :⑥⑦  #   ξ ",
      "  αααξααααξααα  "
    ],
    [
      "  ηηηξηηηηξηηη  ",
      " η** #L⑫⑫L#   η ",
      "η    #    #    η",
      "η              ξ",
      " η   #    #    η",
      " ξ# ##    #    ξ",
      " η   ## ##     η",
      " η   #   #     η",
      " η   #      cc ξ",
      " η   #   #  dd η",
      " ξ:::#######  #ξ",
      " η   :   L#    η",
      "η    :    #    ξ",
      "η    :         η",
      " η   :    #   η ",
      "  ηηηξηηηηξηηη  "
    ],
    [
      "  ηηηξηηηηξηηη  ",
      " η   #L⑫⑫L#   η ",
      "η    #    #    η",
      "η    #    #    ξ",
      " η   #    #    η",
      " ξ####    #    ξ",
      " η   #####     η",
      " η   #   #     η",
      " η   #   #     ξ",
      " η   #   #  cc η",
      " ξ:::#######dd#ξ",
      " η   :    #    η",
      "η    :    #    ξ",
      "η    :         η",
      " η   :    #   η ",
      "  ηηηξηηηηξηηη  "
    ],
    [
      "  ηηηξηηηηξηηη  ",
      " η   #    #   η ",
      "η    #    #    η",
      "η    #    # E  ξ",
      " η   #    #    η",
      " ξ####    #####ξ",
      " η   #####     η",
      " η   #  E#     η",
      " η   #   #     ξ",
      " η   #   #     η",
      " ξ##########cc#ξ",
      " η   #    # dd η",
      "η    #    #    ξ",
      "η    #    #    η",
      " η   #    #   η ",
      "  ηηηξηηηηξηηη  "
    ],
    [
      "  αααξααααξααα  ",
      " ξ   #    #   ξ ",
      "α    #    #    α",
      "α    #    # {  ξ",
      " α   #    #    α",
      " ξ####    #####ξ",
      " α   #####     α",
      " α   #  {#     α",
      " α   #   #     ξ",
      " α   #   #     α",
      " ξ###1######  #ξ",
      " α   #    # cc α",
      "α    #    # dd ξ",
      "α    #    #    α",
      " ξ   #    #   ξ ",
      "  αααξααααξααα  "
    ]
  ],
  "refpalette": "biohazard:furnished_facades"
}
