{
  "xsize": 16,
  "zsize": 16,
  "slices": [
    [
      "  ############  ",
      " ############## ",
      "################",
      "################",
      " ###############",
      " ###############",
      " ###############",
      " ###############",
      " ###############",
      " ###########  ##",
      " ###########  ##",
      " ###########  ##",
      "############cc##",
      "################",
      " ############## ",
      "  ############  "
    ],
    [
      "  αααξααααξααα  ",
      " ξⓖⓕⓓ ⓐⓛ      ξ ",
      "α  ⓔ           α",
      "α              ξ",
      " α  L⑲ⓑLCⓑ⑲L   α",
      " ξ  ⑯#####1    ξ",
      " α  ⑩#LLLL     α",
      " α  F#      cc α",
      " α  F#      dd ξ",
      " α  ⑩#    #    α",
      " ξ  ⑯#####1    ξ",
      " α  F⑫⑫FF⑫ⓒ    α",
      "α              ξ",
      "α              α",
      " ξ        ⓗ   ξ ",
      "  αααξααααξααα  "
    ],
    [
      "  ηηηξηηηηξηηη  ",
      " η            η ",
      "η              η",
      "η              ξ",
      " η  *     *e   η",
      " ξ   ######    ξ",
      " η   #L⑮⑮L     η",
      " η   #         η",
      " η   #      cc ξ",
      " η   #    # dd η",
      " ξ   ######    ξ",
      " η  *    *     η",
      "η              ξ",
      "η              η",
      " η            η ",
      "  ηηηξηηηηξηηη  "
    ],
    [
      "  ηηηξηηηηξηηη  ",
      " η            η ",
      "η              η",
      "η              ξ",
      " η             η",
      " ξ   ######    ξ",
      " η   #LLLL     η",
      " η   #    #    η",
      " η   #    #    ξ",
      " η   #    # cc η",
      " ξ   ###### dd ξ",
      " η             η",
      "η              ξ",
      "η              η",
      " η            η ",
      "  ηηηξηηηηξηηη  "
    ],
    [
      "  ηηηξηηηηξηηη  ",
      " η            η ",
      "η              η",
      "η              ξ",
      " η             η",
      " ξ   ######    ξ",
      " η   #L⑮⑮L#    η",
      " η   #    #    η",
      " η   #    #    ξ",
      " η   #    #    η",
      " ξ   ###### cc ξ",
      " η          dd η",
      "η  E           ξ",
      "η              η",
      " η            η ",
      "  ηηηξηηηηξηηη  "
    ],
    [
      "  αααξααααξααα  ",
      " ξ            ξ ",
      "α              α",
      "α              ξ",
      " α             α",
      " ξ   ######    ξ",
      " α   #LLLL#    α",
      " α   #    #    α",
      " α   #    #    ξ",
      " α   #    #    α",
      " ξ   ######    ξ",
      " α          cc α",
      "α  {        dd ξ",
      "α              α",
      " ξ            ξ ",
      "  αααξααααξααα  "
    ]
  ],
  "refpalette": "biohazard:furnished_facades"
}
