{
  "xsize": 16,
  "zsize": 16,
  "slices": [
    [
      "################",
      "################",
      "################",
      "################",
      "################",
      "################",
      "################",
      "################",
      "################",
      "#######l########",
      "################",
      "################",
      "################",
      "################",
      "################",
      "################"
    ],
    [
      "##a#a#a##a#a#a##",
      "#  F      QQQ  #",
      "a              a",
      "#        ④③③⑤  #",
      "a        ④③③⑤  a",
      "#             F#",
      "a              a",
      "#   L          #",
      "#  FL          #",
      "a  CL  l       a",
      "############  ##",
      "a ⓐⓓⓐLⓐ⑫⑫      a",
      "#              #",
      "a              a",
      "# ⓜⓛ           #",
      "##a#a#a##a#a#a##"
    ],
    [
      "##a#a#a##a#a#a##",
      "#         **   #",
      "a              a",
      "#              #",
      "a              a",
      "#              #",
      "a              a",
      "#   L          #",
      "#   L          #",
      "a   L  l       a",
      "##::########  ##",
      "a      ⑫⑫      a",
      "#              #",
      "a              a",
      "#              #",
      "##a#a#a##a#a#a##"
    ],
    [
      "################",
      "#              #",
      "#              #",
      "#              #",
      "#              #",
      "#              #",
      "#              #",
      "#              #",
      "#              #",
      "#      l       #",
      "##::############",
      "#              #",
      "#              #",
      "#              #",
      "#              #",
      "################"
    ],
    [
      "##a#a#a##a#a#a##",
      "#              #",
      "a              a",
      "#              #",
      "a              a",
      "#              #",
      "a              a",
      "#              #",
      "#              #",
      "a    E l       a",
      "##::############",
      "a    E         a",
      "#              #",
      "a              a",
      "#              #",
      "##a#a#a##a#a#a##"
    ],
    [
      "##a#a#a##a#a#a##",
      "#              #",
      "a              a",
      "#              #",
      "a              a",
      "#              #",
      "a              a",
      "#              #",
      "#              #",
      "a    { l       a",
      "################",
      "a    {         a",
      "#              #",
      "a              a",
      "#              #",
      "##a#a#a##a#a#a##"
    ]
  ],
  "refpalette": "biohazard:handcrafted_furnishings"
}
