{
    "xsize":  16,
    "zsize":  16,
    "slices":  [
                   [
                       "#$$#$$#$$#$$#$$#",
                       "$##############$",
                       "$###1##########$",
                       "################",
                       "$#####1########$",
                       "$##############$",
                       "################",
                       "$##############$",
                       "$##############$",
                       "#######l########",
                       "$##############$",
                       "$##############$",
                       "################",
                       "$##############$",
                       "$##############$",
                       "#$$#$$#$$#$$#$$#"
                   ],
                   [
                       "################",
                       "#          fg  #",
                       "#   ###     b  #",
                       "#   ###     c  #",
                       "#   ###     a  #",
                       "#              #",
                       "##########     #",
                       "#        #     #",
                       "#        #     #",
                       "#      l #     #",
                       "#  #######    F#",
                       "#   i z      gF#",
                       "#   h         L#",
                       "#              #",
                       "#              #",
                       "################"
                   ],
                   [
                       "#aa#aa#aa#aa#aa#",
                       "a              a",
                       "a              a",
                       "#    C         #",
                       "a              a",
                       "a              a",
                       "####aaa###     #",
                       "a        #     a",
                       "a        #     a",
                       "#      l #     #",
                       "a  #######     a",
                       "a              a",
                       "#             L#",
                       "a              a",
                       "a              a",
                       "#aa#aa#aa#aa#aa#"
                   ],
                   [
                       "#aa#aa#aa#aa#aa#",
                       "a              a",
                       "a              a",
                       "#              #",
                       "a              a",
                       "a       E      a",
                       "##########     #",
                       "a       E#     a",
                       "a        #     a",
                       "#      l #     #",
                       "a  #######     a",
                       "a              a",
                       "#             L#",
                       "a              a",
                       "a              a",
                       "#aa#aa#aa#aa#aa#"
                   ],
                   [
                       "################",
                       "################",
                       "################",
                       "################",
                       "################",
                       "################",
                       "################",
                       "################",
                       "################",
                       "#######l########",
                       "################",
                       "################",
                       "################",
                       "################",
                       "################",
                       "################"
                   ],
                   [
                       "################",
                       "################",
                       "################",
                       "################",
                       "################",
                       "################",
                       "################",
                       "################",
                       "################",
                       "#######l########",
                       "################",
                       "################",
                       "################",
                       "################",
                       "################",
                       "################"
                   ]
               ],
    "refpalette":  "biohazard:handcrafted_furnishings"
}
