{
    "xsize":  16,
    "zsize":  16,
    "slices":  [
                   [
                       "#$$#$$#$$#$$#$$#",
                       "$##############$",
                       "$##############$",
                       "################",
                       "$##############$",
                       "$##############$",
                       "################",
                       "$##############$",
                       "$##############$",
                       "#######l########",
                       "$##############$",
                       "$##############$",
                       "################",
                       "$##############$",
                       "$##############$",
                       "#$$#$$#$$#$$#$$#"
                   ],
                   [
                       "################",
                       "#        # fg  #",
                       "#       F#  b  #",
                       "#       F#  c  #",
                       "#        #  a  #",
                       "#              #",
                       "#        #     #",
                       "#        #     #",
                       "#        #     #",
                       "####   l #     #",
                       "# C#######     #",
                       "#   i z      g #",
                       "#   h          #",
                       "#       1   1  #",
                       "#  FF          #",
                       "################"
                   ],
                   [
                       "#aa#aa#aa#aa#aa#",
                       "a        #     a",
                       "a        #     a",
                       "#        #     #",
                       "a        #     a",
                       "a              a",
                       "#        #     #",
                       "a        #     a",
                       "a        #     a",
                       "####   l #     #",
                       "a  #######     a",
                       "a              a",
                       "#              #",
                       "a              a",
                       "a              a",
                       "#aa#aa#aa#aa#aa#"
                   ],
                   [
                       "#aa#aa#aa#aa#aa#",
                       "a        #     a",
                       "a        #     a",
                       "#        #     #",
                       "a        #     a",
                       "a        #     a",
                       "#       E#     #",
                       "a        #     a",
                       "a        #     a",
                       "####   l #     #",
                       "a  #######     a",
                       "a              a",
                       "#              #",
                       "a              a",
                       "a              a",
                       "#aa#aa#aa#aa#aa#"
                   ],
                   [
                       "################",
                       "################",
                       "################",
                       "################",
                       "################",
                       "################",
                       "################",
                       "################",
                       "################",
                       "#######l########",
                       "################",
                       "################",
                       "################",
                       "################",
                       "################",
                       "################"
                   ],
                   [
                       "################",
                       "################",
                       "################",
                       "################",
                       "################",
                       "################",
                       "################",
                       "################",
                       "################",
                       "#######l########",
                       "################",
                       "################",
                       "################",
                       "################",
                       "################",
                       "################"
                   ]
               ],
    "refpalette":  "biohazard:handcrafted_furnishings"
}
