{
  "xsize": 16,
  "zsize": 16,
  "slices": [
    [
      "#$$#        #$$#",
      "$##############$",
      "$##############$",
      "################",
      "$##############$",
      "$##############$",
      "################",
      "$##########  ##$",
      "$##########  ##$",
      "###########  ###",
      "$##########cc##$",
      "$##############$",
      "################",
      "$##############$",
      "$##############$",
      "#$$#        #$$#"
    ],
    [
      "μμββ        ββμμ",
      "μⓓⓐⓕβμββββμβⓛ⑫⑫μ",
      "β  ⓔ μ         β",
      "β    μ         β",
      "β    μ         β",
      "μ    μ     cc  μ",
      "β         :dd: β",
      "β         :  : β",
      "β         :  : β",
      "β         :  : β",
      "μ     ### :  : μ",
      "β              β",
      "β              β",
      "β              β",
      "μ   βμββββμβ ⓖⓗμ",
      "μμββ        ββμμ"
    ],
    [
      "μμθθ        θθμμ",
      "μe  θμθθθθμθ  Lμ",
      "θ    μ         θ",
      "θ    μ         θ",
      "θ    μ         θ",
      "μ    μ         μ",
      "θ          cc  θ",
      "θ          dd  θ",
      "θ              θ",
      "θ              θ",
      "μ     ###      μ",
      "θ              θ",
      "θ              θ",
      "θ              θ",
      "μ   θμθθθθμθ   μ",
      "μμθθ        θθμμ"
    ],
    [
      "μμθθ        θθμμ",
      "μ   θμθθθθμθ   μ",
      "θ    μ         θ",
      "θ    μ         θ",
      "θ    μ         θ",
      "μ    μ         μ",
      "θ              θ",
      "θ          cc  θ",
      "θ          dd  θ",
      "θ              θ",
      "μ     ###      μ",
      "θ      %       θ",
      "θ              θ",
      "θ              θ",
      "μ   θμθθθθμθ   μ",
      "μμθθ        θθμμ"
    ],
    [
      "μμθθ        θθμμ",
      "μ###θμθθθθμθ###μ",
      "θ##############θ",
      "θ##############θ",
      "θ##############θ",
      "μ##########  ##μ",
      "θ##########  ##θ",
      "θ##########  ##θ",
      "θ##########cc##θ",
      "θ###### ###dd##θ",
      "μ##########  ##μ",
      "θ##############θ",
      "θ##############θ",
      "θ##############θ",
      "μ###θμθθθθμθ###μ",
      "μμθθ        θθμμ"
    ],
    [
      "μμββ        ββμμ",
      "μ###βμββββμβ###μ",
      "β##############β",
      "β##############β",
      "β##############β",
      "μ##########  ##μ",
      "β##########  ##β",
      "β##########  ##β",
      "β##########  ##β",
      "β###### ###cc##β",
      "μ##########dd##μ",
      "β##############β",
      "β##############β",
      "β##############β",
      "μ###βμββββμβ###μ",
      "μμββ        ββμμ"
    ]
  ],
  "refpalette": "biohazard:furnished_facades"
}
