{
  "xsize": 16,
  "zsize": 16,
  "slices": [
    [
      "#$$#        #$$#",
      "$##############$",
      "$###1##########$",
      "################",
      "$#####1########$",
      "$##############$",
      "################",
      "$##########  ##$",
      "$##########  ##$",
      "###########  ###",
      "$##########cc##$",
      "$##############$",
      "################",
      "$##############$",
      "$##############$",
      "#$$#        #$$#"
    ],
    [
      "μμββ        ββμμ",
      "μLⓒⓑβμββββμβⓓ  μ",
      "β ① ###        β",
      "β   ###        β",
      "β   ###        β",
      "μ          cc  μ",
      "β# #######:dd: β",
      "β        #:  : β",
      "β       ⑬#:  : β",
      "β       ⑬#:  : β",
      "μ  #######:  : μ",
      "β              β",
      "β             Lβ",
      "β              β",
      "μⓑⓑLβμββββμβ   μ",
      "μμββ        ββμμ"
    ],
    [
      "μμθθ        θθμμ",
      "μL  θμθθθθμθ   μ",
      "θ              θ",
      "θ    C         θ",
      "θ              θ",
      "μ              μ",
      "θ# #aaa### cc  θ",
      "θ        # dd  θ",
      "θ        #     θ",
      "θ        #     θ",
      "μ  #######     μ",
      "θ              θ",
      "θ             Lθ",
      "θ              θ",
      "μ  eθμθθθθμθ   μ",
      "μμθθ        θθμμ"
    ],
    [
      "μμθθ        θθμμ",
      "μL  θμθθθθμθ   μ",
      "θ              θ",
      "θ              θ",
      "θ              θ",
      "μ       E      μ",
      "θ#########     θ",
      "θ       E# cc  θ",
      "θ        # dd  θ",
      "θ       ⑯#     θ",
      "μ  #######     μ",
      "θ              θ",
      "θ             Lθ",
      "θ              θ",
      "μ   θμθθθθμθ   μ",
      "μμθθ        θθμμ"
    ],
    [
      "μμθθ        θθμμ",
      "μ###θμθθθθμθ###μ",
      "θ##############θ",
      "θ##############θ",
      "θ##############θ",
      "μ##########  ##μ",
      "θ##########  ##θ",
      "θ##########  ##θ",
      "θ##########cc##θ",
      "θ###### ###dd##θ",
      "μ##########  ##μ",
      "θ##############θ",
      "θ##############θ",
      "θ##############θ",
      "μ###θμθθθθμθ###μ",
      "μμθθ        θθμμ"
    ],
    [
      "μμββ        ββμμ",
      "μ###βμββββμβ###μ",
      "β##############β",
      "β##############β",
      "β##############β",
      "μ##########  ##μ",
      "β##########  ##β",
      "β##########  ##β",
      "β##########  ##β",
      "β###### ###cc##β",
      "μ##########dd##μ",
      "β##############β",
      "β##############β",
      "β##############β",
      "μ###βμββββμβ###μ",
      "μμββ        ββμμ"
    ]
  ],
  "refpalette": "biohazard:furnished_facades"
}
