{
  "xsize": 16,
  "zsize": 16,
  "slices": [
    [
      "#$$#$$#$$#$$#$$#",
      "$##############$",
      "$##############$",
      "################",
      "$##############$",
      "$##############$",
      "################",
      "$##############$",
      "$##############$",
      "#######l########",
      "$##############$",
      "$##############$",
      "################",
      "$##############$",
      "$##############$",
      "#$$#$$#$$#$$#$$#"
    ],
    [
      "################",
      "#    ⑨ⓓ  #     #",
      "#    ⑧  F#     #",
      "#       F#     #",
      "#        #     #",
      "#              #",
      "#        #     #",
      "#        #     #",
      "#        #     #",
      "####   l #     #",
      "# C#######     #",
      "#              #",
      "#              #",
      "#       1   1  #",
      "#⑥⑦FF          #",
      "################"
    ],
    [
      "#aa#aa#aa#aa#aa#",
      "a        #     a",
      "a        #     a",
      "#        #     #",
      "a        #     a",
      "a              a",
      "#        #     #",
      "a        #     a",
      "a        #     a",
      "####   l #     #",
      "a  #######     a",
      "a              a",
      "#              #",
      "a              a",
      "a              a",
      "#aa#aa#aa#aa#aa#"
    ],
    [
      "#aa#aa#aa#aa#aa#",
      "a        #     a",
      "a        #     a",
      "#        #     #",
      "a        #     a",
      "a        #     a",
      "#       E#     #",
      "a        #     a",
      "a        #     a",
      "####   l #     #",
      "a  #######     a",
      "a              a",
      "#              #",
      "a              a",
      "a              a",
      "#aa#aa#aa#aa#aa#"
    ],
    [
      "################",
      "################",
      "################",
      "################",
      "################",
      "################",
      "################",
      "################",
      "################",
      "#######l########",
      "################",
      "################",
      "################",
      "################",
      "################",
      "################"
    ],
    [
      "################",
      "################",
      "################",
      "################",
      "################",
      "################",
      "################",
      "################",
      "################",
      "#######l########",
      "################",
      "################",
      "################",
      "################",
      "################",
      "################"
    ]
  ],
  "refpalette": "biohazard:handcrafted_furnishings"
}
