{
    "xsize":  16,
    "zsize":  16,
    "slices":  [
                   [
                       "#$$#$$#$$#$$#$$#",
                       "$##############$",
                       "$##############$",
                       "################",
                       "$##############$",
                       "$##############$",
                       "################",
                       "$##############$",
                       "$##############$",
                       "#######l########",
                       "$##############$",
                       "$##############$",
                       "################",
                       "$##############$",
                       "$##############$",
                       "#$$#$$#$$#$$#$$#"
                   ],
                   [
                       "################",
                       "#          fg  #",
                       "#           b  #",
                       "#           c  #",
                       "#           a  #",
                       "#              #",
                       "#              #",
                       "#              #",
                       "#              #",
                       "#      l       #",
                       "#     ###      #",
                       "#   i z      g #",
                       "#   h          #",
                       "#              #",
                       "#              #",
                       "################"
                   ],
                   [
                       "#aa#aa#aa#aa#aa#",
                       "a              a",
                       "a              a",
                       "#              #",
                       "a              a",
                       "a              a",
                       "#              #",
                       "a              a",
                       "a              a",
                       "#      l       #",
                       "a     ###      a",
                       "a              a",
                       "#              #",
                       "a              a",
                       "a              a",
                       "#aa#aa#aa#aa#aa#"
                   ],
                   [
                       "#aa#aa#aa#aa#aa#",
                       "a              a",
                       "a              a",
                       "#              #",
                       "a              a",
                       "a              a",
                       "#              #",
                       "a              a",
                       "a              a",
                       "#      l       #",
                       "a     ###      a",
                       "a      %       a",
                       "#              #",
                       "a              a",
                       "a              a",
                       "#aa#aa#aa#aa#aa#"
                   ],
                   [
                       "################",
                       "################",
                       "################",
                       "################",
                       "################",
                       "################",
                       "################",
                       "################",
                       "################",
                       "#######l########",
                       "################",
                       "################",
                       "################",
                       "################",
                       "################",
                       "################"
                   ],
                   [
                       "################",
                       "################",
                       "################",
                       "################",
                       "################",
                       "################",
                       "################",
                       "################",
                       "################",
                       "#######l########",
                       "################",
                       "################",
                       "################",
                       "################",
                       "################",
                       "################"
                   ]
               ],
    "refpalette":  "biohazard:handcrafted_furnishings"
}
