{
  "xsize": 16,
  "zsize": 16,
  "slices": [
    [
      "#$$#$$#$$#$$#$$#",
      "$##############$",
      "$###1##########$",
      "################",
      "$#####1########$",
      "$##############$",
      "################",
      "$##########  ##$",
      "$##########  ##$",
      "###########  ###",
      "$##########cc##$",
      "$##############$",
      "################",
      "$##############$",
      "$##############$",
      "#$$#$$#$$#$$#$$#"
    ],
    [
      "################",
      "# ⓒⓑ      ⑨ⓓ   #",
      "# ① ###   ⑧    #",
      "#   ###        #",
      "#   ###        #",
      "#          cc  #",
      "##########:dd: #",
      "#        #:  : #",
      "#       ⑬#:  : #",
      "#       ⑬#:  : #",
      "#  #######:  :F#",
      "#             F#",
      "#             L#",
      "#              #",
      "#              #",
      "################"
    ],
    [
      "#aa#aa#aa#aa#aa#",
      "a              a",
      "a              a",
      "#    C         #",
      "a              a",
      "a              a",
      "####aaa### cc  #",
      "a        # dd  a",
      "a        #     a",
      "#        #     #",
      "a  #######     a",
      "a              a",
      "#             L#",
      "a              a",
      "a              a",
      "#aa#aa#aa#aa#aa#"
    ],
    [
      "#aa#aa#aa#aa#aa#",
      "a              a",
      "a              a",
      "#              #",
      "a              a",
      "a       E      a",
      "##########     #",
      "a       E# cc  a",
      "a        # dd  a",
      "#       ⑯#     #",
      "a  #######     a",
      "a              a",
      "#             L#",
      "a              a",
      "a              a",
      "#aa#aa#aa#aa#aa#"
    ],
    [
      "################",
      "################",
      "################",
      "################",
      "################",
      "###########  ###",
      "###########  ###",
      "###########  ###",
      "###########cc###",
      "####### ###dd###",
      "###########  ###",
      "################",
      "################",
      "################",
      "################",
      "################"
    ],
    [
      "################",
      "################",
      "################",
      "################",
      "################",
      "###########  ###",
      "###########  ###",
      "###########  ###",
      "###########  ###",
      "####### ###cc###",
      "###########dd###",
      "################",
      "################",
      "################",
      "################",
      "################"
    ]
  ],
  "refpalette": "biohazard:handcrafted_furnishings"
}
