{
  "xsize": 16,
  "zsize": 16,
  "slices": [
    [
      "#$$#$$#$$#$$#$$#",
      "$##############$",
      "$###1##########$",
      "################",
      "$#####1########$",
      "$##############$",
      "################",
      "$##########  ##$",
      "$##########  ##$",
      "###########  ###",
      "$##########cc##$",
      "$##############$",
      "################",
      "$##############$",
      "$##############$",
      "#$$#$$#$$#$$#$$#"
    ],
    [
      "################",
      "#⑮⑫⑮     #ⓕ    #",
      "#        #ⓔ  # #",
      "#        #     #",
      "#        #     #",
      "#        # cc  #",
      "##########:dd: #",
      "#   ④⑱⑤   :  : #",
      "#         :  : #",
      "#         :  : #",
      "#     ### :  : #",
      "#              #",
      "#              #",
      "#              #",
      "#FF     ⓜⓛ     #",
      "################"
    ],
    [
      "#aa#aa#aa#aa#aa#",
      "a        :     a",
      "a        :   * a",
      "#        :     #",
      "a        :     a",
      "a        :     a",
      "#::::::::# cc  #",
      "a          dd  a",
      "a              a",
      "#              #",
      "a     ###      a",
      "a              a",
      "#              #",
      "a              a",
      "a              a",
      "#aa#aa#aa#aa#aa#"
    ],
    [
      "#aa#aa#aa#aa#aa#",
      "a        :     a",
      "a        :     a",
      "#        :     #",
      "a        :     a",
      "a        :     a",
      "#::::::::#     #",
      "a          cc  a",
      "a          dd  a",
      "#              #",
      "a     ###      a",
      "a      E       a",
      "#              #",
      "a              a",
      "a              a",
      "#aa#aa#aa#aa#aa#"
    ],
    [
      "################",
      "################",
      "################",
      "################",
      "################",
      "###########  ###",
      "###########  ###",
      "###########  ###",
      "###########cc###",
      "####### ###dd###",
      "###########  ###",
      "################",
      "################",
      "################",
      "################",
      "################"
    ],
    [
      "################",
      "################",
      "################",
      "################",
      "################",
      "###########  ###",
      "###########  ###",
      "###########  ###",
      "###########  ###",
      "####### ###cc###",
      "###########dd###",
      "################",
      "################",
      "################",
      "################",
      "################"
    ]
  ],
  "refpalette": "biohazard:handcrafted_furnishings"
}
