{
  "xsize": 16,
  "zsize": 16,
  "slices": [
    [
      "#$$#        #$$#",
      "$##############$",
      "$##############$",
      "################",
      "$##############$",
      "$##############$",
      "################",
      "$##########  ##$",
      "$##########  ##$",
      "###########  ###",
      "$##########cc##$",
      "$##############$",
      "################",
      "$##############$",
      "$##############$",
      "#$$#        #$$#"
    ],
    [
      "μμββ        ββμμ",
      "μⓕⓓⓐβμββββμβ⑮⑮ μ",
      "βⓔ      F#     β",
      "β       F#     β",
      "β        #     β",
      "μ          cc  μ",
      "β        #:dd: β",
      "β        #:  : β",
      "β        #:  : β",
      "β ##     #:  : β",
      "μ C#######:  : μ",
      "β              β",
      "β              β",
      "β       1   1  β",
      "μ⑥⑦Fβμββββμβ   μ",
      "μμββ        ββμμ"
    ],
    [
      "μμθθ        θθμμ",
      "μ   θμθθθθμθ   μ",
      "θ        #     θ",
      "θ        #     θ",
      "θ        #     θ",
      "μ              μ",
      "θ        # cc  θ",
      "θ        # dd  θ",
      "θ        #     θ",
      "θ ##     #     θ",
      "μ  #######     μ",
      "θ              θ",
      "θ              θ",
      "θ              θ",
      "μ   θμθθθθμθ   μ",
      "μμθθ        θθμμ"
    ],
    [
      "μμθθ        θθμμ",
      "μ   θμθθθθμθ   μ",
      "θ        #     θ",
      "θ        #     θ",
      "θ        #     θ",
      "μ        #     μ",
      "θ       E#     θ",
      "θ        # cc  θ",
      "θ        # dd  θ",
      "θ###     #     θ",
      "μ  #######     μ",
      "θ              θ",
      "θ              θ",
      "θ              θ",
      "μ   θμθθθθμθ   μ",
      "μμθθ        θθμμ"
    ],
    [
      "μμθθ        θθμμ",
      "μ###θμθθθθμθ###μ",
      "θ##############θ",
      "θ##############θ",
      "θ##############θ",
      "μ##########  ##μ",
      "θ##########  ##θ",
      "θ##########  ##θ",
      "θ##########cc##θ",
      "θ###### ###dd##θ",
      "μ##########  ##μ",
      "θ##############θ",
      "θ##############θ",
      "θ##############θ",
      "μ###θμθθθθμθ###μ",
      "μμθθ        θθμμ"
    ],
    [
      "μμββ        ββμμ",
      "μ###βμββββμβ###μ",
      "β##############β",
      "β##############β",
      "β##############β",
      "μ##########  ##μ",
      "β##########  ##β",
      "β##########  ##β",
      "β##########  ##β",
      "β###### ###cc##β",
      "μ##########dd##μ",
      "β##############β",
      "β##############β",
      "β##############β",
      "μ###βμββββμβ###μ",
      "μμββ        ββμμ"
    ]
  ],
  "refpalette": "biohazard:furnished_facades"
}
