{
  "xsize": 16,
  "zsize": 16,
  "slices": [
    [
      "#$$#   ##   #$$#",
      "$##############$",
      "$##############$",
      "################",
      "$##############$",
      "$##############$",
      "################",
      "$##############$",
      "$##############$",
      "################",
      "$##############$",
      "$##############$",
      "################",
      "$##############$",
      "$##############$",
      "#$$#        #$$#"
    ],
    [
      "μμββ  μ  μ  ββμμ",
      "μⓓⓐⓕβμβ  βμβⓛⓗⓖμ",
      "β  ⓔ           β",
      "β              β",
      "β              β",
      "μ          cc  μ",
      "β         :dd: β",
      "β         :  : β",
      "β         :  : β",
      "β         :  : β",
      "μ     ### :  : μ",
      "β              β",
      "β              β",
      "β              β",
      "μ   βμββββμβ   μ",
      "μμββ        ββμμ"
    ],
    [
      "μμθθ  μ  μ  θθμμ",
      "μ   θμθ  θμθ   μ",
      "θ              θ",
      "θ              θ",
      "θ              θ",
      "μ              μ",
      "θ          cc  θ",
      "θ          dd  θ",
      "θ              θ",
      "θ              θ",
      "μ     ###      μ",
      "θ              θ",
      "θ              θ",
      "θ              θ",
      "μ   θμθθθθμθ   μ",
      "μμθθ        θθμμ"
    ],
    [
      "μμθθ  μ  μ  θθμμ",
      "μ   θμθ  θμθ   μ",
      "θ              θ",
      "θ              θ",
      "θ              θ",
      "μ              μ",
      "θ              θ",
      "θ          cc  θ",
      "θ          dd  θ",
      "θ              θ",
      "μ     ###      μ",
      "θ      %       θ",
      "θ              θ",
      "θ              θ",
      "μ   θμθθθθμθ   μ",
      "μμθθ        θθμμ"
    ],
    [
      "μμθθ  μμμμ  θθμμ",
      "μ###θμθθθθμθ###μ",
      "θ##############θ",
      "θ##############θ",
      "θ##############θ",
      "μ##########  ##μ",
      "θ##########  ##θ",
      "θ##########  ##θ",
      "θ##########cc##θ",
      "θ###### ###dd##θ",
      "μ##########  ##μ",
      "θ##############θ",
      "θ##############θ",
      "θ##############θ",
      "μ###θμθθθθμθ###μ",
      "μμθθ        θθμμ"
    ],
    [
      "μμββ        ββμμ",
      "μ###βμββββμβ###μ",
      "β##############β",
      "β##############β",
      "β##############β",
      "μ##########  ##μ",
      "β##########  ##β",
      "β##########  ##β",
      "β##########  ##β",
      "β###### ###cc##β",
      "μ##########dd##μ",
      "β##############β",
      "β##############β",
      "β##############β",
      "μ###βμββββμβ###μ",
      "μμββ        ββμμ"
    ]
  ],
  "refpalette": "biohazard:furnished_facades"
}
