{
  "xsize": 16,
  "zsize": 16,
  "slices": [
    [
      "  ############  ",
      " ############## ",
      "################",
      "################",
      "################",
      "#####  #########",
      "#####  #########",
      "#####  #########",
      "#####cc#########",
      "################",
      "################",
      "################",
      "################",
      "################",
      " ############## ",
      "  ############  "
    ],
    [
      "  γγγγγγγγγγγγ  ",
      " ν            ν ",
      "γ              γ",
      "γ νν νν        γ",
      "γ ννγγγγ       γ",
      "γ   γ :γ       γ",
      "γ   γ  γ       γ",
      "γ   γ  γ       γ",
      "γ      γ       γ",
      "γ   γγγγ       γ",
      "γ              γ",
      "γ              γ",
      "γ              γ",
      "γ              γ",
      " ν            ν ",
      "  γγγγγγγγγγγγ  "
    ],
    [
      "                ",
      " η            η ",
      "                ",
      "                ",
      "    γγγγ        ",
      "    γ ::        ",
      "    γ  γ        ",
      "    γ  γ        ",
      "       γ        ",
      "    γγγγ        ",
      "                ",
      "                ",
      "                ",
      "                ",
      " η            η ",
      "                "
    ],
    [
      "                ",
      " η            η ",
      "                ",
      "                ",
      "    γγγγ        ",
      "    γ ::        ",
      "    γ  γ        ",
      "    γ  γ        ",
      "       γ        ",
      "    γγγγ        ",
      "                ",
      "                ",
      "                ",
      "                ",
      " η            η ",
      "                "
    ],
    [
      "                ",
      " η            η ",
      "                ",
      "                ",
      "    νννν        ",
      "    νν:ν        ",
      "    νννν        ",
      "    νννν        ",
      "    νννν        ",
      "    νννν        ",
      "                ",
      "                ",
      "                ",
      "                ",
      " η            η ",
      "                "
    ],
    [
      "                ",
      " ν            ν ",
      "                ",
      "                ",
      "                ",
      "                ",
      "                ",
      "                ",
      "                ",
      "                ",
      "                ",
      "                ",
      "                ",
      "                ",
      " ν            ν ",
      "                "
    ]
  ],
  "refpalette": "biohazard:furnished_facades"
}
