{
  "xsize": 16,
  "zsize": 16,
  "slices": [
    [
      "  ############  ",
      " ############## ",
      "################",
      "################",
      "################",
      "################",
      "################",
      "################",
      "################",
      "################",
      "################",
      "################",
      "################",
      "################",
      " ############## ",
      "  ############  "
    ],
    [
      "  νγγνν  ννγγν  ",
      " νC②          ν ",
      "γ $$       $$$ γ",
      "γ $D$cc ③  $D$ γ",
      "γ $$:dd:①  $$$ γ",
      "ν   :  :       ν",
      "γL  :  :       γ",
      "γL  :  :       γ",
      "γLLL:  :       γ",
      "γ###     #     γ",
      "νⓕFF    ##  .  ν",
      "γⓔ             γ",
      "γ           .  γ",
      "γ              γ",
      " ν     ⑥⑦     ν ",
      "  νγγννγγγνγγν  "
    ],
    [
      "  νγγνν  ννγγν  ",
      " η            η ",
      "η              η",
      "γ  K        K  γ",
      "γ    cc        γ",
      "ν    dd        ν",
      "ηL             η",
      "γL             γ",
      "γLLLL          γ",
      "γ###     #     γ",
      "ν       ##  -  ν",
      "γ              γ",
      "γ           -  γ",
      "γ              γ",
      " η            η ",
      "  νγγννγγγνγγν  "
    ],
    [
      "  νγγνν  ννγγν  ",
      " η            η ",
      "η              η",
      "γ              γ",
      "γ              γ",
      "ν    cc        ν",
      "ηL   dd        η",
      "γL             γ",
      "γLLLL          γ",
      "γ###     #     γ",
      "ν       ##     ν",
      "γ              γ",
      "γ              γ",
      "γ              γ",
      " η            η ",
      "  νγγννγγγνγγν  "
    ],
    [
      "  νγγννννννγγν  ",
      " η            η ",
      "η              η",
      "γ  E        E  γ",
      "γ              γ",
      "ν              ν",
      "ηL   cc        η",
      "γL   dd        γ",
      "γLLLL          γ",
      "γ#####   #     γ",
      "νL⑮⑮L#####     ν",
      "γ              γ",
      "γ           E  γ",
      "γ              γ",
      " η            η ",
      "  νγγννγγγνγγν  "
    ],
    [
      "  νγγννγγγνγγν  ",
      " ν            ν ",
      "γ              γ",
      "γ  {        {  γ",
      "γ              γ",
      "ν              ν",
      "γ              γ",
      "γ    cc        γ",
      "γ    dd        γ",
      "γ#####   #     γ",
      "νLLLL#####     ν",
      "γ              γ",
      "γ           {  γ",
      "γ              γ",
      " ν            ν ",
      "  νγγννγγγνγγν  "
    ]
  ],
  "refpalette": "biohazard:furnished_facades"
}
