{
  "xsize": 16,
  "zsize": 16,
  "slices": [
    [
      " @#@#@####@#@#@ ",
      "@##############@",
      "################",
      "@##############@",
      "################",
      "@##############@",
      "################",
      "@##############@",
      "@##############@",
      "################",
      "@##############@",
      "################",
      "@##############@",
      "################",
      "@##############@",
      " @#@#@#@@#@#@#@ "
    ],
    [
      " ζ    ζ  ζζπππζ ",
      "ζ⑮πππζ⑭  ⑪     ζ",
      "π $$$      F$$ π",
      "π $          $ π",
      "π L .      . $ π",
      "ζ              ζ",
      "π              π",
      "π              π",
      "π         cc   π",
      "π        :dd:  π",
      "ζ     ④⑱⑤:  :  ζ",
      "π L .    :  :  π",
      "π $      :  :  π",
      "π $$$    :  :  π",
      "ζ ⓜⓛ           ζ",
      " ζπππζππππ    ζ "
    ],
    [
      " ζ    ζ  ζζθθθζ ",
      "ζ θθθζ         ζ",
      "θ * L        * θ",
      "θ            L θ",
      "θ L -      - L θ",
      "ζ              ζ",
      "θ              θ",
      "θ              θ",
      "θ              θ",
      "θ         cc   θ",
      "ζ         dd   ζ",
      "θ L -          θ",
      "θ              θ",
      "θ * C          θ",
      "ζ              ζ",
      " ζθθθζθθθθ    ζ "
    ],
    [
      " ζ    ζ  ζζθθθζ ",
      "ζ θθθζ         ζ",
      "θ              θ",
      "θ              θ",
      "θ              θ",
      "ζ              ζ",
      "θ              θ",
      "θ              θ",
      "θ              θ",
      "θ              θ",
      "ζ         cc   ζ",
      "θ         dd   θ",
      "θ              θ",
      "θ              θ",
      "ζ              ζ",
      " ζθθθζθθθθ    ζ "
    ],
    [
      " ζ    ζζζζζθθθζ ",
      "ζ θθθζ         ζ",
      "θ              θ",
      "θ  E        E  θ",
      "θ              θ",
      "ζ              ζ",
      "θ              θ",
      "θ              θ",
      "θ              θ",
      "θ              θ",
      "ζ              ζ",
      "θ         cc   θ",
      "θ  E      dd   θ",
      "θ              θ",
      "ζ         ζθθθ ζ",
      " ζθθθζθθθθ    ζ "
    ],
    [
      " ζ    ππππζπππζ ",
      "ζ πππζ         ζ",
      "π              π",
      "π  {        {  π",
      "π              π",
      "ζ              ζ",
      "π              π",
      "π              π",
      "π              π",
      "π              π",
      "ζ              ζ",
      "π              π",
      "π  {      cc   π",
      "π         dd   π",
      "ζ         ζπππ ζ",
      " ζπππζππππ    ζ "
    ]
  ],
  "refpalette": "biohazard:furnished_facades"
}
