{
  "xsize": 16,
  "zsize": 16,
  "slices": [
    [
      "#@#@#@#@@#@#@#@#",
      "@##############@",
      "################",
      "@##############@",
      "################",
      "@##############@",
      "################",
      "@##############@",
      "@##############@",
      "################",
      "@##############@",
      "################",
      "@##############@",
      "################",
      "@##############@",
      "#@#@#@#@@#@#@#@#"
    ],
    [
      "#`#`#`#``#`#`#`#",
      "`⑮⑪⑭           `",
      "# $$$      F$$ #",
      "` $          $ `",
      "# L .      . $ #",
      "`              `",
      "#              #",
      "`              `",
      "`         cc   `",
      "#        :dd:  #",
      "`     ④⑱⑤:  :  `",
      "# L .    :  :  #",
      "` $      :  :  `",
      "# $$$    :  :  #",
      "` ⓜⓛ           `",
      "#`#`#`#``#`#`#`#"
    ],
    [
      "#`#`#`#``#`#`#`#",
      "`              `",
      "# * L        * #",
      "`            L `",
      "# L -      - L #",
      "`              `",
      "#              #",
      "`              `",
      "`              `",
      "#         cc   #",
      "`         dd   `",
      "# L -          #",
      "`              `",
      "# * C          #",
      "`              `",
      "#`#`#`#``#`#`#`#"
    ],
    [
      "#`#`#`#``#`#`#`#",
      "`              `",
      "#              #",
      "`              `",
      "#              #",
      "`              `",
      "#              #",
      "`              `",
      "`              `",
      "#              #",
      "`         cc   `",
      "#         dd   #",
      "`              `",
      "#              #",
      "`              `",
      "#`#`#`#``#`#`#`#"
    ],
    [
      "#`#`#`#``#`#`#`#",
      "`              `",
      "#              #",
      "`  E        E  `",
      "#              #",
      "`              `",
      "#              #",
      "`              `",
      "`              `",
      "#              #",
      "`              `",
      "#         cc   #",
      "`  E      dd   `",
      "#              #",
      "`              `",
      "#`#`#`#``#`#`#`#"
    ],
    [
      "#`#`#`#``#`#`#`#",
      "`              `",
      "#              #",
      "`  {        {  `",
      "#              #",
      "`              `",
      "#              #",
      "`              `",
      "`              `",
      "#              #",
      "`              `",
      "#              #",
      "`  {      cc   `",
      "#         dd   #",
      "`              `",
      "#`#`#`#``#`#`#`#"
    ]
  ],
  "refpalette": "biohazard:handcrafted_furnishings"
}
