{
  "xsize": 16,
  "zsize": 16,
  "slices": [
    [
      " ############## ",
      "################",
      "################",
      "################",
      "################",
      "################",
      "################",
      "################",
      "###########  ###",
      "###########  ###",
      "###########  ###",
      "###########cc###",
      "################",
      "################",
      "################",
      " ############## "
    ],
    [
      " γγγγγγγγγγγγγγ ",
      "γ              γ",
      "γ              γ",
      "γ αα αα        γ",
      "γ αα           γ",
      "γ     :        γ",
      "γ              γ",
      "γ         γγγγ γ",
      "γ         γ  γ γ",
      "γ         γ  γ γ",
      "γ         γ  γ γ",
      "γ            γ γ",
      "γ         γγγγ γ",
      "γ              γ",
      "γ              γ",
      " γγγγγγγγγγγγγγ "
    ],
    [
      "                ",
      "                ",
      "                ",
      "                ",
      "                ",
      "      :         ",
      "                ",
      "          γγγγ  ",
      "          γ  :  ",
      "          γ  γ  ",
      "          γ  γ  ",
      "             γ  ",
      "          γγγγ  ",
      "                ",
      "                ",
      "                "
    ],
    [
      "                ",
      "                ",
      "                ",
      "                ",
      "                ",
      "      :         ",
      "                ",
      "          γγγγ  ",
      "          γ  :  ",
      "          γ  γ  ",
      "          γ  γ  ",
      "             γ  ",
      "          γγγγ  ",
      "                ",
      "                ",
      "                "
    ],
    [
      "                ",
      "                ",
      "                ",
      "                ",
      "                ",
      "      :         ",
      "                ",
      "          αααα  ",
      "          αααα  ",
      "          αααα  ",
      "          αααα  ",
      "          αααα  ",
      "          αααα  ",
      "                ",
      "                ",
      "                "
    ],
    [
      "                ",
      "                ",
      "                ",
      "                ",
      "                ",
      "                ",
      "                ",
      "                ",
      "                ",
      "                ",
      "                ",
      "                ",
      "                ",
      "                ",
      "                ",
      "                "
    ]
  ],
  "refpalette": "biohazard:furnished_facades"
}
