{
  "xsize": 16,
  "zsize": 16,
  "slices": [
    [
      "################",
      "################",
      "################",
      "################",
      "################",
      "################",
      "################",
      "################",
      "################",
      "################",
      "##########  ####",
      "##########  ####",
      "##########  ####",
      "##########cc####",
      "################",
      "################"
    ],
    [
      "################",
      "#              #",
      "#              #",
      "# SS SS        #",
      "# SS           #",
      "#     :        #",
      "#              #",
      "#              #",
      "#              #",
      "#        ####  #",
      "#        #  #  #",
      "#        #  #  #",
      "#        #  #  #",
      "#           #  #",
      "#        ####  #",
      "################"
    ],
    [
      "                ",
      "                ",
      "                ",
      "                ",
      "                ",
      "      :         ",
      "                ",
      "                ",
      "                ",
      "         ####   ",
      "         #  :   ",
      "         #  #   ",
      "         #  #   ",
      "            #   ",
      "         ####   ",
      "                "
    ],
    [
      "                ",
      "                ",
      "                ",
      "                ",
      "                ",
      "      :         ",
      "                ",
      "                ",
      "                ",
      "         ####   ",
      "         #  :   ",
      "         #  #   ",
      "         #  #   ",
      "            #   ",
      "         ####   ",
      "                "
    ],
    [
      "                ",
      "                ",
      "                ",
      "                ",
      "                ",
      "      :         ",
      "                ",
      "                ",
      "                ",
      "         SSSS   ",
      "         SSSS   ",
      "         SSSS   ",
      "         SSSS   ",
      "         SSSS   ",
      "         SSSS   ",
      "                "
    ],
    [
      "                ",
      "                ",
      "                ",
      "                ",
      "                ",
      "                ",
      "                ",
      "                ",
      "                ",
      "                ",
      "                ",
      "                ",
      "                ",
      "                ",
      "                ",
      "                "
    ]
  ],
  "refpalette": "biohazard:handcrafted_furnishings"
}
