{
  "xsize": 16,
  "zsize": 16,
  "slices": [
    [
      "#$$#$$#$$#$$#$$#",
      "$##############$",
      "$##############$",
      "################",
      "$##############$",
      "$##############$",
      "################",
      "$##############$",
      "$##############$",
      "################",
      "$##############$",
      "$##############$",
      "################",
      "$##############$",
      "$##############$",
      "#$$#$$#$$#$$#$$#"
    ],
    [
      "################",
      "#  ⓕⓓ ⓐⓛ       #",
      "#  ⓔ           #",
      "#              #",
      "#              #",
      "#          cc  #",
      "#         :dd: #",
      "#         :  : #",
      "#         :  : #",
      "#         :  : #",
      "#     ### :  : #",
      "#              #",
      "#              #",
      "#              #",
      "#         ⓗⓖ   #",
      "################"
    ],
    [
      "#aa#aa#aa#aa#aa#",
      "a              a",
      "a              a",
      "#              #",
      "a              a",
      "a              a",
      "#          cc  #",
      "a          dd  a",
      "a              a",
      "#              #",
      "a     ###      a",
      "a              a",
      "#              #",
      "a              a",
      "a              a",
      "#aa#aa#aa#aa#aa#"
    ],
    [
      "#aa#aa#aa#aa#aa#",
      "a              a",
      "a              a",
      "#              #",
      "a              a",
      "a              a",
      "#              #",
      "a          cc  a",
      "a          dd  a",
      "#              #",
      "a     ###      a",
      "a      %       a",
      "#              #",
      "a              a",
      "a              a",
      "#aa#aa#aa#aa#aa#"
    ],
    [
      "################",
      "################",
      "################",
      "################",
      "################",
      "###########  ###",
      "###########  ###",
      "###########  ###",
      "###########cc###",
      "####### ###dd###",
      "###########  ###",
      "################",
      "################",
      "################",
      "################",
      "################"
    ],
    [
      "################",
      "################",
      "################",
      "################",
      "################",
      "###########  ###",
      "###########  ###",
      "###########  ###",
      "###########  ###",
      "####### ###cc###",
      "###########dd###",
      "################",
      "################",
      "################",
      "################",
      "################"
    ]
  ],
  "refpalette": "biohazard:handcrafted_furnishings"
}
