{
  "xsize": 16,
  "zsize": 16,
  "slices": [
    [
      "###    ##    ###",
      "################",
      "################",
      "################",
      "################",
      "################",
      "################",
      "################",
      "################",
      "################",
      "################",
      "################",
      "################",
      "################",
      "################",
      "################"
    ],
    [
      "ααδ   α  α   δαα",
      "α##   ⓛ  δαδδ##α",
      "δ#D    ⓐ⑫⑫  #D#δ",
      "δ#D#cc      #D#δ",
      "δ#D:dd:     #D#δ",
      "α##:  :     ###α",
      "δ  :  :        δ",
      "δF :  : ④⑱⑤   Lδ",
      "δF :  :       Lδ",
      "δ              δ",
      "α#     ##     #α",
      "δ#            #δ",
      "δ#    . .     #δ",
      "δ#            #δ",
      "α#####L⑥⑦L#####α",
      "ααδαδαδαδδααδδαα"
    ],
    [
      "ααη   α  α   δαα",
      "α#a      ηαηηa#α",
      "ηaK          Kaη",
      "δaK          Kaδ",
      "δaK cc       Kaδ",
      "α#  dd        #α",
      "η              η",
      "δ             Lδ",
      "δ             Lδ",
      "δ              δ",
      "α#     ##     #α",
      "δa            aδ",
      "δa    - -     aδ",
      "δa            aδ",
      "α#aaa#L  L#aaa#α",
      "ααηαδαηαδδααδδαα"
    ],
    [
      "ααη   α  α   δαα",
      "α#a      ηαηηa#α",
      "ηa            aη",
      "δa            aδ",
      "δa            aδ",
      "α#  cc        #α",
      "η   dd         η",
      "δ              δ",
      "δ              δ",
      "δ              δ",
      "α#     ##     #α",
      "δa            aδ",
      "δa            aδ",
      "δa            aδ",
      "α#aaa#LⓑⓑL#aaa#α",
      "ααηαδαηαδδααδδαα"
    ],
    [
      "ααη   αααα   δαα",
      "α#aηηαη  ηαηηa#α",
      "ηa            aη",
      "δa            aδ",
      "δa            aδ",
      "α#E          E#α",
      "η   cc         η",
      "δ   dd         δ",
      "δ              δ",
      "δ              δ",
      "α#E   ###    E#α",
      "δa            aδ",
      "δa            aδ",
      "δa            aδ",
      "α#aaa#    #aaa#α",
      "ααηαδαηαδδααδδαα"
    ],
    [
      "ααδ    δδ    δαα",
      "α##δδαδ##δαδδ##α",
      "δ##############δ",
      "δ###  #########δ",
      "δ###  #########δ",
      "α###  #########α",
      "δ###  #########δ",
      "δ###cc#########δ",
      "δ###dd#########δ",
      "δ###### #######δ",
      "α##############α",
      "δ##############δ",
      "δ##############δ",
      "δ##############δ",
      "α##############α",
      "ααδαδαδαδδααδδαα"
    ]
  ],
  "refpalette": "biohazard:furnished_facades"
}
