{
  "xsize": 16,
  "zsize": 16,
  "slices": [
    [
      "################",
      "################",
      "################",
      "################",
      "################",
      "#####  #########",
      "#####  #########",
      "#####  #########",
      "#####cc#########",
      "################",
      "################",
      "################",
      "################",
      "################",
      "################",
      "################"
    ],
    [
      "################",
      "#              #",
      "#              #",
      "# SS SS        #",
      "# SS####       #",
      "#   # :#       #",
      "#   #  #       #",
      "#   #  #       #",
      "#      #       #",
      "#   ####       #",
      "#              #",
      "#              #",
      "#              #",
      "#              #",
      "#              #",
      "################"
    ],
    [
      "                ",
      "                ",
      "                ",
      "                ",
      "    ####        ",
      "    # ::        ",
      "    #  #        ",
      "    #  #        ",
      "       #        ",
      "    ####        ",
      "                ",
      "                ",
      "                ",
      "                ",
      "                ",
      "                "
    ],
    [
      "                ",
      "                ",
      "                ",
      "                ",
      "    ####        ",
      "    # ::        ",
      "    #  #        ",
      "    #  #        ",
      "       #        ",
      "    ####        ",
      "                ",
      "                ",
      "                ",
      "                ",
      "                ",
      "                "
    ],
    [
      "                ",
      "                ",
      "                ",
      "                ",
      "    SSSS        ",
      "    SS:S        ",
      "    SSSS        ",
      "    SSSS        ",
      "    SSSS        ",
      "    SSSS        ",
      "                ",
      "                ",
      "                ",
      "                ",
      "                ",
      "                "
    ],
    [
      "                ",
      "                ",
      "                ",
      "                ",
      "                ",
      "                ",
      "                ",
      "                ",
      "                ",
      "                ",
      "                ",
      "                ",
      "                ",
      "                ",
      "                ",
      "                "
    ]
  ],
  "refpalette": "biohazard:handcrafted_furnishings"
}
