{
  "xsize": 16,
  "zsize": 16,
  "slices": [
    [
      " ############## ",
      "################",
      "################",
      "################",
      "################",
      "################",
      "################",
      "################",
      "################",
      "##########  ####",
      "##########  ####",
      "##########  ####",
      "##########cc####",
      "################",
      "################",
      " ############## "
    ],
    [
      " δδδδδδδδδδδδδδ ",
      "δ              δ",
      "δ              δ",
      "δ ιι ιι        δ",
      "δ ιι           δ",
      "δ     :        δ",
      "δ              δ",
      "δ              δ",
      "δ        δδδδ  δ",
      "δ        δ  δ  δ",
      "δ        δ  δ  δ",
      "δ        δ  δ  δ",
      "δ           δ  δ",
      "δ        δδδδ  δ",
      "δ              δ",
      " δδδδδδδδδδδδδδ "
    ],
    [
      "                ",
      "                ",
      "                ",
      "                ",
      "                ",
      "      :         ",
      "                ",
      "                ",
      "         δδδδ   ",
      "         δ  :   ",
      "         δ  δ   ",
      "         δ  δ   ",
      "            δ   ",
      "         δδδδ   ",
      "                ",
      "                "
    ],
    [
      "                ",
      "                ",
      "                ",
      "                ",
      "                ",
      "      :         ",
      "                ",
      "                ",
      "         δδδδ   ",
      "         δ  :   ",
      "         δ  δ   ",
      "         δ  δ   ",
      "            δ   ",
      "         δδδδ   ",
      "                ",
      "                "
    ],
    [
      "                ",
      "                ",
      "                ",
      "                ",
      "                ",
      "      :         ",
      "                ",
      "                ",
      "         ιιιι   ",
      "         ιιιι   ",
      "         ιιιι   ",
      "         ιιιι   ",
      "         ιιιι   ",
      "         ιιιι   ",
      "                ",
      "                "
    ],
    [
      "                ",
      "                ",
      "                ",
      "                ",
      "                ",
      "                ",
      "                ",
      "                ",
      "                ",
      "                ",
      "                ",
      "                ",
      "                ",
      "                ",
      "                ",
      "                "
    ]
  ],
  "refpalette": "biohazard:furnished_facades"
}
