{
  "xsize": 16,
  "zsize": 16,
  "slices": [
    [
      "  ############  ",
      " ############## ",
      "################",
      "################",
      "################",
      "################",
      "################",
      "################",
      "################",
      "############  ##",
      "############  ##",
      "############  ##",
      "############cc##",
      "################",
      " ############## ",
      "  ############  "
    ],
    [
      "  αααααααααααα  ",
      " ξ            ξ ",
      "α              α",
      "α ξξ ξξ        α",
      "α ξξ           α",
      "α     :        α",
      "α              α",
      "α              α",
      "α          ααααα",
      "α          α  αα",
      "α          α  αα",
      "α          α  αα",
      "α             αα",
      "α          ααααα",
      " ξ            ξ ",
      "  αααααααααααα  "
    ],
    [
      "                ",
      " η            η ",
      "                ",
      "                ",
      "                ",
      "      :         ",
      "                ",
      "                ",
      "           αααα ",
      "           α  : ",
      "           α  α ",
      "           α  α ",
      "              α ",
      "           αααα ",
      " η            η ",
      "                "
    ],
    [
      "                ",
      " η            η ",
      "                ",
      "                ",
      "                ",
      "      :         ",
      "                ",
      "                ",
      "           αααα ",
      "           α  : ",
      "           α  α ",
      "           α  α ",
      "              α ",
      "           αααα ",
      " η            η ",
      "                "
    ],
    [
      "                ",
      " η            η ",
      "                ",
      "                ",
      "                ",
      "      :         ",
      "                ",
      "                ",
      "           ξξξξ ",
      "           ξξξξ ",
      "           ξξξξ ",
      "           ξξξξ ",
      "           ξξξξ ",
      "           ξξξξ ",
      " η            η ",
      "                "
    ],
    [
      "                ",
      " ξ            ξ ",
      "                ",
      "                ",
      "                ",
      "                ",
      "                ",
      "                ",
      "                ",
      "                ",
      "                ",
      "                ",
      "                ",
      "                ",
      " ξ            ξ ",
      "                "
    ]
  ],
  "refpalette": "biohazard:furnished_facades"
}
