{
  "xsize": 16,
  "zsize": 16,
  "slices": [
    [
      "  SSSSS##SSSSS  ",
      " ############## ",
      "S##############S",
      "S##############S",
      "S##############S",
      "S############## ",
      "S#####1######## ",
      "S############## ",
      "S############## ",
      "S############## ",
      "S############## ",
      "S##############S",
      "S##############S",
      "S##############S",
      " ############## ",
      "  SSSSSSSSSSSS  "
    ],
    [
      "  οοοεε  εεοοο  ",
      " εLLLL#  ⑲    ε ",
      "οL    #②       ο",
      "οC     ③       ο",
      "ο     #①       ο",
      "ε     #       ε ",
      "ο######       ο ",
      "ο    S#       ο ",
      "ο    S#   cc  ο ",
      "ο    S#  :dd: ο ",
      "ε     #  :  : ε ",
      "ο        :  :  ο",
      "ο    F#  :  :  ο",
      "ο    F#  :  :  ο",
      " εF⑥⑦ #       ε ",
      "  οοοεοοοοεοοο  "
    ],
    [
      "  θθθεε  εεθθθ  ",
      " θLLLL#       θ ",
      "θL    #        θ",
      "θ              θ",
      "θ     #        θ",
      "ε     #       ε ",
      "θ#:::##       θ ",
      "θ     #       θ ",
      "θ    *#       θ ",
      "θ    *#   cc  θ ",
      "ε     #   dd  ε ",
      "θ              θ",
      "θ     #        θ",
      "θ     #        θ",
      " θ    #       θ ",
      "  θθθεθθθθεθθθ  "
    ],
    [
      "  θθθεε  εεθθθ  ",
      " θLLLL#       θ ",
      "θL    #        θ",
      "θ     #        θ",
      "θ     #        θ",
      "ε     #       ε ",
      "θ######E      θ ",
      "θ     #       θ ",
      "θ     #       θ ",
      "θ     #       θ ",
      "ε     #   cc  ε ",
      "θ     #   dd   θ",
      "θ     #        θ",
      "θ     #        θ",
      " θ ⑳⑲ #       θ ",
      "  θθθεθθθθεθθθ  "
    ],
    [
      "  θθθεεεεεεθθθ  ",
      " θ############θ ",
      "θ##############θ",
      "θ##############θ",
      "θ##############θ",
      "ε#############ε ",
      "θ#############θ ",
      "θ#############θ ",
      "θ#########  ##θ ",
      "θ#########  ##θ ",
      "ε#########  ##ε ",
      "θ#########cc###θ",
      "θ#########dd###θ",
      "θ#########  ###θ",
      " θ############θ ",
      "  θθθεθθθθεθθθ  "
    ],
    [
      "  οοοεοοοοεοοο  ",
      " ε############ε ",
      "ο##############ο",
      "ο##############ο",
      "ο##############ο",
      "ε#############ε ",
      "ο#############ο ",
      "ο#############ο ",
      "ο#########  ##ο ",
      "ο#########  ##ο ",
      "ε#########  ##ε ",
      "ο#########  ###ο",
      "ο#########cc###ο",
      "ο#########dd###ο",
      " ε############ε ",
      "  οοοεοοοοεοοο  "
    ]
  ],
  "refpalette": "biohazard:furnished_facades"
}
