{
  "xsize": 16,
  "zsize": 16,
  "slices": [
    [
      " #   ######   # ",
      "################",
      " ############## ",
      " ############## ",
      " ############## ",
      "################",
      "################",
      "################",
      "################",
      "################",
      "################",
      " ############## ",
      " ############## ",
      " ############## ",
      "################",
      " #   ######   # "
    ],
    [
      " ααγγαα  ααγγαα ",
      "α#aaa#L  ⓒ#aaa#α",
      "γa⑫      ①    aγ",
      "γa            aγ",
      "γa            aγ",
      "α#             α",
      "γL         cc Lγ",
      "γ⑪        :dd:⑬γ",
      "γ⑪        :  :⑬γ",
      "γL        :  :Lγ",
      "α#    ### :  :#α",
      "γa        :  :aγ",
      "γa             γ",
      "γa            aγ",
      "α#aaa#ⓜⓛⓗⓖ#aaa#α",
      " ααγγαγγγγαγγαα "
    ],
    [
      " ααηηαα  ααηηαα ",
      "α#aaa#L   #aaa#α",
      "ηa            aη",
      "ηa            aη",
      "ηa            aη",
      "α#             α",
      "ηL            Lη",
      "η⑪         cc ⑬η",
      "η⑪         dd ⑬η",
      "ηL            Lη",
      "α#    ###     #α",
      "ηa            aη",
      "ηa             η",
      "ηa            aη",
      "α#aaa#    #aaa#α",
      " ααηηαηηηηαηηαα "
    ],
    [
      " ααηηαα  ααηηαα ",
      "α#aaa#L   #aaa#α",
      "ηa            aη",
      "ηa            aη",
      "ηa            aη",
      "α#             α",
      "ηL            Lη",
      "ηL            Lη",
      "ηL         cc Lη",
      "ηL         dd Lη",
      "α#    ###     #α",
      "ηa     E      aη",
      "ηa             η",
      "ηa            aη",
      "α#aaa#    #aaa#α",
      " ααηηαηηηηαηηαα "
    ],
    [
      " ααηηααααααηηαα ",
      "α##############α",
      "η##############η",
      "η##############η",
      "η##############η",
      "α##############α",
      "η##########  ##η",
      "η##########  ##η",
      "η##########  ##η",
      "η###### ###cc##η",
      "α##########dd##α",
      "η##########  ##η",
      "η##############η",
      "η##############η",
      "α##############α",
      " ααηηαηηηηαηηαα "
    ],
    [
      " ααγγαγγγγαγγαα ",
      "α##############α",
      "γ##############γ",
      "γ##############γ",
      "γ##############γ",
      "α##############α",
      "γ##########  ##γ",
      "γ##########  ##γ",
      "γ##########  ##γ",
      "γ###### ###  ##γ",
      "α##########cc##α",
      "γ##########dd##γ",
      "γ##############γ",
      "γ##############γ",
      "α##############α",
      " ααγγαγγγγαγγαα "
    ]
  ],
  "refpalette": "biohazard:furnished_facades"
}
