{
  "xsize": 16,
  "zsize": 16,
  "slices": [
    [
      "  ############  ",
      " ############## ",
      "################",
      "################",
      "################",
      "################",
      "################",
      "################",
      "################",
      "################",
      "##########  ####",
      "##########  ####",
      "##########  ####",
      "##########cc####",
      " ############## ",
      "  ############  "
    ],
    [
      "  οοοοοοοοοοοο  ",
      " ε            ε ",
      "ο              ο",
      "ο εε εε        ο",
      "ο εε           ο",
      "ο     :        ο",
      "ο              ο",
      "ο              ο",
      "ο              ο",
      "ο        οοοο  ο",
      "ο        ο  ο  ο",
      "ο        ο  ο  ο",
      "ο        ο  ο  ο",
      "ο           ο  ο",
      " ε       οοοο ε ",
      "  οοοοοοοοοοοο  "
    ],
    [
      "                ",
      " θ            θ ",
      "                ",
      "                ",
      "                ",
      "      :         ",
      "                ",
      "                ",
      "                ",
      "         οοοο   ",
      "         ο  :   ",
      "         ο  ο   ",
      "         ο  ο   ",
      "            ο   ",
      " θ       οοοο θ ",
      "                "
    ],
    [
      "                ",
      " θ            θ ",
      "                ",
      "                ",
      "                ",
      "      :         ",
      "                ",
      "                ",
      "                ",
      "         οοοο   ",
      "         ο  :   ",
      "         ο  ο   ",
      "         ο  ο   ",
      "            ο   ",
      " θ       οοοο θ ",
      "                "
    ],
    [
      "                ",
      " θ            θ ",
      "                ",
      "                ",
      "                ",
      "      :         ",
      "                ",
      "                ",
      "                ",
      "         εεεε   ",
      "         εεεε   ",
      "         εεεε   ",
      "         εεεε   ",
      "         εεεε   ",
      " θ       εεεε θ ",
      "                "
    ],
    [
      "                ",
      " ε            ε ",
      "                ",
      "                ",
      "                ",
      "                ",
      "                ",
      "                ",
      "                ",
      "                ",
      "                ",
      "                ",
      "                ",
      "                ",
      " ε            ε ",
      "                "
    ]
  ],
  "refpalette": "rotwire:furnished_facades"
}
