{
  "xsize": 16,
  "zsize": 16,
  "slices": [
    [
      "####        ####",
      "################",
      "################",
      "################",
      "################",
      "####  ##########",
      "####  ##########",
      "####  ##########",
      "####cc##########",
      "################",
      "################",
      "################",
      "################",
      "################",
      "################",
      "################"
    ],
    [
      "δδδδ        δδδδ",
      "δ   αααααααα   δ",
      "δ              δ",
      "δ αα αα        δ",
      "δ ααδδδ        δ",
      "δ  δ  :        δ",
      "δ  δ  δ        δ",
      "δ  δ  δ        δ",
      "δ     δ        δ",
      "δ  δδδδ        δ",
      "δ              δ",
      "δ              δ",
      "δ              δ",
      "δ              δ",
      "δ              δ",
      "δδδδδδδδδδδδδδδδ"
    ],
    [
      "                ",
      "                ",
      "                ",
      "                ",
      "   δδδδ         ",
      "   δ  :         ",
      "   δ  δ         ",
      "   δ  δ         ",
      "      δ         ",
      "   δδδδ         ",
      "                ",
      "                ",
      "                ",
      "                ",
      "                ",
      "                "
    ],
    [
      "                ",
      "                ",
      "                ",
      "                ",
      "   δδδδ         ",
      "   δ  :         ",
      "   δ  δ         ",
      "   δ  δ         ",
      "      δ         ",
      "   δδδδ         ",
      "                ",
      "                ",
      "                ",
      "                ",
      "                ",
      "                "
    ],
    [
      "                ",
      "                ",
      "                ",
      "                ",
      "   αααα         ",
      "   ααα:         ",
      "   αααα         ",
      "   αααα         ",
      "   αααα         ",
      "   αααα         ",
      "                ",
      "                ",
      "                ",
      "                ",
      "                ",
      "                "
    ],
    [
      "                ",
      "                ",
      "                ",
      "                ",
      "                ",
      "                ",
      "                ",
      "                ",
      "                ",
      "                ",
      "                ",
      "                ",
      "                ",
      "                ",
      "                ",
      "                "
    ]
  ],
  "refpalette": "rotwire:furnished_facades"
}
