{
  "xsize": 16,
  "zsize": 16,
  "slices": [
    [
      "####        ####",
      "################",
      "################",
      "################",
      "################",
      "################",
      "################",
      "###########  ###",
      "###########  ###",
      "###########  ###",
      "###########cc###",
      "################",
      "################",
      "################",
      "################",
      "################"
    ],
    [
      "ββββ        ββββ",
      "β   μμμμμμμμ   β",
      "β              β",
      "β μμ μμ        β",
      "β μμ           β",
      "β     :        β",
      "β         ββββ β",
      "β         β  β β",
      "β         β  β β",
      "β         β  β β",
      "β            β β",
      "β         ββββ β",
      "β              β",
      "β              β",
      "β              β",
      "ββββββββββββββββ"
    ],
    [
      "                ",
      "                ",
      "                ",
      "                ",
      "                ",
      "      :         ",
      "          ββββ  ",
      "          β  :  ",
      "          β  β  ",
      "          β  β  ",
      "             β  ",
      "          ββββ  ",
      "                ",
      "                ",
      "                ",
      "                "
    ],
    [
      "                ",
      "                ",
      "                ",
      "                ",
      "                ",
      "      :         ",
      "          ββββ  ",
      "          β  :  ",
      "          β  β  ",
      "          β  β  ",
      "             β  ",
      "          ββββ  ",
      "                ",
      "                ",
      "                ",
      "                "
    ],
    [
      "                ",
      "                ",
      "                ",
      "                ",
      "                ",
      "      :         ",
      "          μμμμ  ",
      "          μμμμ  ",
      "          μμμμ  ",
      "          μμμμ  ",
      "          μμμμ  ",
      "          μμμμ  ",
      "                ",
      "                ",
      "                ",
      "                "
    ],
    [
      "                ",
      "                ",
      "                ",
      "                ",
      "                ",
      "                ",
      "                ",
      "                ",
      "                ",
      "                ",
      "                ",
      "                ",
      "                ",
      "                ",
      "                ",
      "                "
    ]
  ],
  "refpalette": "rotwire:furnished_facades"
}
