{
  "xsize": 16,
  "zsize": 16,
  "slices": [
    [
      " ############## ",
      "################",
      "################",
      "################",
      "################",
      "################",
      "################",
      "################",
      "################",
      "################",
      "##########  ####",
      "##########  ####",
      "##########  ####",
      "##########cc####",
      "################",
      " ############## "
    ],
    [
      " ππππππππππππππ ",
      "π              π",
      "π              π",
      "π ζζ ζζ        π",
      "π ζζ           π",
      "π     :        π",
      "π              π",
      "π              π",
      "π              π",
      "π        ππππ  π",
      "π        π  π  π",
      "π        π  π  π",
      "π        π  π  π",
      "π           π  π",
      "π        ππππ  π",
      " ππππππππππππππ "
    ],
    [
      "                ",
      "                ",
      "                ",
      "                ",
      "                ",
      "      :         ",
      "                ",
      "                ",
      "                ",
      "         ππππ   ",
      "         π  :   ",
      "         π  π   ",
      "         π  π   ",
      "            π   ",
      "         ππππ   ",
      "                "
    ],
    [
      "                ",
      "                ",
      "                ",
      "                ",
      "                ",
      "      :         ",
      "                ",
      "                ",
      "                ",
      "         ππππ   ",
      "         π  :   ",
      "         π  π   ",
      "         π  π   ",
      "            π   ",
      "         ππππ   ",
      "                "
    ],
    [
      "                ",
      "                ",
      "                ",
      "                ",
      "                ",
      "      :         ",
      "                ",
      "                ",
      "                ",
      "         ζζζζ   ",
      "         ζζζζ   ",
      "         ζζζζ   ",
      "         ζζζζ   ",
      "         ζζζζ   ",
      "         ζζζζ   ",
      "                "
    ],
    [
      "                ",
      "                ",
      "                ",
      "                ",
      "                ",
      "                ",
      "                ",
      "                ",
      "                ",
      "                ",
      "                ",
      "                ",
      "                ",
      "                ",
      "                ",
      "                "
    ]
  ],
  "refpalette": "rotwire:furnished_facades"
}
