{
  "xsize": 16,
  "zsize": 16,
  "slices": [
    [
      " ############## ",
      "################",
      "################",
      "################",
      "################",
      "################",
      "################",
      "################",
      "################",
      "################",
      "################",
      "################",
      "################",
      "################",
      "################",
      " ############## "
    ],
    [
      " ιδδδιι  ιιδδδι ",
      "ι  # ⑨ⓓ     #  ι",
      "δ  #F⑧      #  δ",
      "δ  #F      L#  δ",
      "δ  #D      L#  δ",
      "ι  #           ι",
      "δ              δ",
      "δ  #      cc#  δ",
      "δ  #     :dd:  δ",
      "δ  #     :  :  δ",
      "ι  ######:  :  ι",
      "δ        :  :  δ",
      "δ        :  :  δ",
      "δ              δ",
      "ι⑥⑦δδιδδ       ι",
      " ιδ     δδιδδδι "
    ],
    [
      " ιηηηιι  ιιηηηι ",
      "ι  #        #  ι",
      "η  #        #  η",
      "η  #       L#  η",
      "η  #*      L#  η",
      "ι  #           ι",
      "η              η",
      "η  #        #  η",
      "η  #      cc#  η",
      "η  #      dd#  η",
      "ι  #######  #  ι",
      "η              η",
      "η              η",
      "η              η",
      "ι  ηηιηη       ι",
      " ιη     ηηιηηηι "
    ],
    [
      " ιηηηιι  ιιηηηι ",
      "ι  #        #  ι",
      "η  #        #  η",
      "η  #        #  η",
      "η  #        #  η",
      "ι  #           ι",
      "η  #           η",
      "η  #        #  η",
      "η  #        #  η",
      "η  #      cc#  η",
      "ι  #######dd#  ι",
      "η       E      η",
      "η              η",
      "η              η",
      "ι  ηηιηη       ι",
      " ιη     ηηιηηηι "
    ],
    [
      " ιηηηιιιιιιηηηι ",
      "ι##############ι",
      "η##############η",
      "η##############η",
      "η##############η",
      "ι##############ι",
      "η##############η",
      "η#########  ###η",
      "η#########  ###η",
      "η###### ##  ###η",
      "ι#########cc###ι",
      "η#########dd###η",
      "η#########  ###η",
      "η##############η",
      "ι##ηηιηη#######ι",
      " ιη     ηηιηηηι "
    ],
    [
      " ιδδδιδδδδιδδδι ",
      "ι##############ι",
      "δ##############δ",
      "δ##############δ",
      "δ##############δ",
      "ι##############ι",
      "δ##############δ",
      "δ#########  ###δ",
      "δ#########  ###δ",
      "δ###### ##  ###δ",
      "ι#########  ###ι",
      "δ#########cc###δ",
      "δ#########dd###δ",
      "δ##############δ",
      "ι##δδιδδ#######ι",
      " ιδ     δδιδδδι "
    ]
  ],
  "refpalette": "rotwire:furnished_facades"
}
