{
  "xsize": 16,
  "zsize": 16,
  "slices": [
    [
      "  WWWWWWWWWWWW  ",
      " FFFFFFFFFFFFFF ",
      "WFFFFFFFFFFFFFFW",
      "WFFFFFFFFFFFFFFW",
      " FFFFFFFFFFFFFFW",
      " FFFFFFFFFFFFFFW",
      " FFFFFFFFFFFFFFW",
      " FFFFFFFFFFFFFFW",
      " FFFFFFFFFFFFFFW",
      " FFFFFFFFFFFFFFW",
      " FFFFFFFFF  FFFW",
      " FFFFFFFFF  FFFW",
      "WFFFFFFFFF  FFFW",
      "WFFFFFFFFFccFFFW",
      " FFFFFFFFFFFFFF ",
      "  WWWWWWWWWWWW  "
    ],
    [
      "  WWWWWWWWWWWW  ",
      " W   W        W ",
      "W    W         W",
      "W q  W q       W",
      " AQ    Q       W",
      " W             W",
      " W   W q       W",
      " W   W Q       W",
      " W   W    cc   W",
      " Wq  W   :dd:  W",
      " WQ  W   :  :  W",
      " A       :  :  W",
      "W    W   :  :  W",
      "W    W i :  :  W",
      " Wu uW        W ",
      "  WWWWWWWWWWWW  "
    ],
    [
      "  GGGAGGGGAGGG  ",
      " G   W        G ",
      "G    W         G",
      "G    W         G",
      " A             G",
      " G             A",
      " G   W         G",
      " G   W         G",
      " G   W         G",
      " G   W    cc   G",
      " G   W    dd   A",
      " A             G",
      "G    W         G",
      "G    W         G",
      " G   W        G ",
      "  GGGAGGGGAGGG  "
    ],
    [
      "  GGGAGGGGAGGG  ",
      " G   W        G ",
      "G    W         G",
      "G    W         G",
      " A             G",
      " G             A",
      " G   W         G",
      " G   W         G",
      " G   W         G",
      " G   W         G",
      " G   W    cc   A",
      " A        dd   G",
      "G    W         G",
      "G    W         G",
      " G   W        G ",
      "  GGGAGGGGAGGG  "
    ],
    [
      "  GGGWGGGGWGGG  ",
      " G   W        G ",
      "G    W         G",
      "G    W         G",
      " A             G",
      " G             W",
      " G   W         G",
      " G   W         G",
      " G   W         G",
      " G   W         G",
      " G   W         W",
      " A        cc   G",
      "G    W    dd   G",
      "G    W         G",
      " G   W        G ",
      "  GGGWGGGGWGGG  "
    ],
    [
      "  WWWWWWWWWWWW  ",
      " W            W ",
      "W              W",
      "W  L           W",
      " A      L      W",
      " W             W",
      " W             W",
      " W             W",
      " W             W",
      " W             W",
      " W L           W",
      " A      L      W",
      "W         cc   W",
      "W         dd   W",
      " W            W ",
      "  WWWWWWWWWWWW  "
    ]
  ],
  "refpalette": "biohazard:custom_buildings"
}
