{
  "xsize": 16,
  "zsize": 16,
  "slices": [
    [
      "FFFFFFFFFFFFFFFF",
      "FFFFFFFFFFFFFFFF",
      "FFFFFFFFFFFFFFFF",
      "FFFFFFFFFFFFFFFF",
      "FFFFFFFFFFFFFFFF",
      "FFFFFFFFFFFFFFFF",
      "FFFFFFFFFFFFFFFF",
      "FFFFFFFFFFFFFFFF",
      "FFFFFFFFFFFFFFFF",
      "FFFFFFFFFFFFFFFF",
      "FFFFFFFFFFFFFFFF",
      "FFFFFFFFFFFFFFFF",
      "FFFFFFFFFFFFFFFF",
      "FFFFFFFFFFFFFFFF",
      " FFFFFFFFFFFFFFF",
      "  FFFFFFFFFFFFFF"
    ],
    [
      "W               ",
      "W               ",
      "W               ",
      "W  XX XX        ",
      "W  XX           ",
      "W               ",
      "W               ",
      "W  AAAAA        ",
      "W               ",
      "W               ",
      "W               ",
      "W               ",
      "W               ",
      "W               ",
      " W              ",
      "  WWWWWWWWWWWWWW"
    ],
    [
      "                ",
      "                ",
      "                ",
      "                ",
      "                ",
      "                ",
      "                ",
      "                ",
      "                ",
      "                ",
      "                ",
      "                ",
      "                ",
      "                ",
      " G              ",
      "                "
    ],
    [
      "                ",
      "                ",
      "                ",
      "                ",
      "                ",
      "                ",
      "                ",
      "                ",
      "                ",
      "                ",
      "                ",
      "                ",
      "                ",
      "                ",
      " G              ",
      "                "
    ],
    [
      "                ",
      "                ",
      "                ",
      "                ",
      "                ",
      "                ",
      "                ",
      "                ",
      "                ",
      "                ",
      "                ",
      "                ",
      "                ",
      "                ",
      " G              ",
      "                "
    ],
    [
      "                ",
      "                ",
      "                ",
      "                ",
      "                ",
      "                ",
      "                ",
      "                ",
      "                ",
      "                ",
      "                ",
      "                ",
      "                ",
      "                ",
      " W              ",
      "                "
    ]
  ],
  "refpalette": "biohazard:custom_buildings"
}
