{
  "xsize": 16,
  "zsize": 16,
  "slices": [
    [
      "FFFFFFFFFFFFFFFF",
      "FFFFFFFFFFFFFFFF",
      "FFFFFFFFFFFFFFFF",
      "FFFFFFFFFFFFFFFF",
      "FFFFFFFFFFFFFFFF",
      "FFFFFFFFFFFFFFFF",
      "FFFFFFFFFFFFFFFF",
      "FFFFFFFFFFFFFFFF",
      "FFFFFFFFFFFFFFFF",
      "FFFFFFFFFFFFFFFF",
      "FFFFFFFFFF  FFFF",
      "FFFFFFFFFF  FFFF",
      "FFFFFFFFFF  FFFF",
      "FFFFFFFFFFccFFFF",
      "FFFFFFFFFFFFFFFF",
      "FFFFFFFFFFFFFFFF"
    ],
    [
      "               W",
      "               W",
      "               W",
      "   XX XX       W",
      "   XX          W",
      "               W",
      "               W",
      "   AAAAA       W",
      "               W",
      "         WWWW  W",
      "         W  W  W",
      "         W  W  W",
      "         W  W  W",
      "            W  W",
      "         WWWW  W",
      "WWWWWWWWWWWWWWWW"
    ],
    [
      "                ",
      "                ",
      "                ",
      "                ",
      "                ",
      "                ",
      "                ",
      "                ",
      "                ",
      "         WWWW   ",
      "         W  W   ",
      "         W  G   ",
      "         W  W   ",
      "            W   ",
      "         WWWW   ",
      "                "
    ],
    [
      "                ",
      "                ",
      "                ",
      "                ",
      "                ",
      "                ",
      "                ",
      "                ",
      "                ",
      "         WWWW   ",
      "         W  W   ",
      "         W  G   ",
      "         W  W   ",
      "            W   ",
      "         WWWW   ",
      "                "
    ],
    [
      "                ",
      "                ",
      "                ",
      "                ",
      "                ",
      "                ",
      "                ",
      "                ",
      "                ",
      "         FFFF   ",
      "         FFFF   ",
      "         FFFF   ",
      "         FFFF   ",
      "         FFFF   ",
      "         FFFF   ",
      "                "
    ],
    [
      "                ",
      "                ",
      "                ",
      "                ",
      "                ",
      "                ",
      "                ",
      "                ",
      "                ",
      "                ",
      "                ",
      "                ",
      "                ",
      "                ",
      "                ",
      "                "
    ]
  ],
  "refpalette": "biohazard:custom_buildings"
}
