{
  "xsize": 16,
  "zsize": 16,
  "slices": [
    [
      "WWWWWWWWWWWWWWWW",
      "WFFFFFFFFFFFFFFW",
      "WFFFFFFFFFFFFFFW",
      "WFFFFFFFFFFFFFFW",
      "WFFFFFFFFFFFFFFW",
      "WFFFFFFFFFFFFFFW",
      "WFFFFFFFFFFFFFFW",
      "WFFFFFFFFFFFFFFW",
      "WFFFFFFFFFFFFFFW",
      "WFFFFFFFFFFFFFFW",
      "WFFFFFFFFFFFFFFW",
      "WFFFFFFFFFFFFFFW",
      "WFFFFFFFFFFFFFFW",
      "WFFFFFFFFFFFFFFW",
      "WFFFFFFFFFFFFFFW",
      "WWWWWWWWWWWWWWWW"
    ],
    [
      "               W",
      "               W",
      "          W    W",
      "          W    W",
      "   TTTTT  W  u W",
      "          W    W",
      "               W",
      "               W",
      "          cc   W",
      "         :dd:  W",
      "         :W :  W",
      "        A:AA:i W",
      "         :W :  W",
      "         :W :  W",
      "               W",
      "WWWWWWWWWWWWWWWW"
    ],
    [
      "               A",
      "               W",
      "          W    G",
      "          W    G",
      "          W    G",
      "          W    A",
      "               G",
      "               G",
      "               G",
      "          cc   G",
      "          dd   A",
      "          W    G",
      "          W    G",
      "          W    G",
      "               W",
      "AWGGGAGGGGAGGGWA"
    ],
    [
      "               A",
      "               W",
      "          W    G",
      "          W    G",
      "          W    G",
      "          W    A",
      "               G",
      "               G",
      "               G",
      "          W    G",
      "          cc   A",
      "          dd   G",
      "          W    G",
      "          W    G",
      "               W",
      "AWGGGAGGGGAGGGWA"
    ],
    [
      "               W",
      "               W",
      "               G",
      "               G",
      "               G",
      "               W",
      "               G",
      "               G",
      "               G",
      "               G",
      "               W",
      "          cc   G",
      "          dd   G",
      "               G",
      "               W",
      "WWGGGWGGGGWGGGWW"
    ],
    [
      "               W",
      "               W",
      "               W",
      "               W",
      "               W",
      "   L    L      W",
      "               W",
      "               W",
      "               W",
      "               W",
      "               W",
      "               W",
      "   L    L cc   W",
      "          dd   W",
      "               W",
      "WWWWWWWWWWWWWWWW"
    ]
  ],
  "refpalette": "biohazard:custom_buildings"
}
