{
  "xsize": 16,
  "zsize": 16,
  "slices": [
    [
      "  FFFFFFFFFFFF  ",
      " FFFFFFFFFFFFFF ",
      "FFFFFFFFFFFFFFFF",
      "FFFFFFFFFFFFFFFF",
      "FFFFFFFFFFFFFFFF",
      "FFFFFFFFFFFFFFFF",
      "FFFFFFFFFFFFFFFF",
      "FFFFFFFFFFFFFFFF",
      "FFFFFFFFFFFFFFFF",
      "FFFFFFFFFFFFFFFF",
      "FFFFFFFFFF  FFFF",
      "FFFFFFFFFF  FFFF",
      "FFFFFFFFFF  FFFF",
      "FFFFFFFFFFccFFFF",
      " FFFFFFFFFFFFFF ",
      "  FFFFFFFFFFFF  "
    ],
    [
      "  WWWWWWWWWWWW  ",
      " W            W ",
      "W              W",
      "W  XX XX       W",
      "W  XX          W",
      "W              W",
      "W              W",
      "W  AAAAA       W",
      "W              W",
      "W        WWWW  W",
      "W        W  W  W",
      "W        W  W  W",
      "W        W  W  W",
      "W           W  W",
      " W       WWWW W ",
      "  WWWWWWWWWWWW  "
    ],
    [
      "                ",
      " G            G ",
      "                ",
      "                ",
      "                ",
      "                ",
      "                ",
      "                ",
      "                ",
      "         WWWW   ",
      "         W  W   ",
      "         W  G   ",
      "         W  W   ",
      "            W   ",
      " G       WWWW G ",
      "                "
    ],
    [
      "                ",
      " G            G ",
      "                ",
      "                ",
      "                ",
      "                ",
      "                ",
      "                ",
      "                ",
      "         WWWW   ",
      "         W  W   ",
      "         W  G   ",
      "         W  W   ",
      "            W   ",
      " G       WWWW G ",
      "                "
    ],
    [
      "                ",
      " G            G ",
      "                ",
      "                ",
      "                ",
      "                ",
      "                ",
      "                ",
      "                ",
      "         FFFF   ",
      "         FFFF   ",
      "         FFFF   ",
      "         FFFF   ",
      "         FFFF   ",
      " G       FFFF G ",
      "                "
    ],
    [
      "                ",
      " W            W ",
      "                ",
      "                ",
      "                ",
      "                ",
      "                ",
      "                ",
      "                ",
      "                ",
      "                ",
      "                ",
      "                ",
      "                ",
      " W            W ",
      "                "
    ]
  ],
  "refpalette": "biohazard:custom_buildings"
}
