{
  "xsize": 16,
  "zsize": 16,
  "slices": [
    [
      "WWWWWWWWWWWWWWWW",
      "WFFFFFFFFFFFFFFW",
      "WFFFFFFFFFFFFFFW",
      "WFFFFFFFFFFFFFFW",
      "WFFFFFFFFFFFFFFW",
      "WFFFFFFFFFFFFFFW",
      "WFFFFFFFFFFFFFFW",
      "WFFFFFFFFFFFFFFW",
      "WFFFFFFFFFFFFFFW",
      "WFFFFFFFFFFFFFFW",
      "WFFFFFFFFFFFFFFW",
      "WFFFFFFFFFFFFFFW",
      "WFFFFFFFFFFFFFFW",
      "WFFFFFFFFFFFFFFW",
      "WFFFFFFFFFFFFFFW",
      "WWWWWWWWWWWWWWWW"
    ],
    [
      "WWWWWWWWWWWWWWWW",
      "               W",
      "          W    W",
      "  q    q  W    W",
      "  Q    Q  W  u W",
      "          W    W",
      "          W    W",
      "               W",
      "               W",
      "          W    W",
      "  q    q  W    W",
      "  Q    Q  W  i W",
      "          W    W",
      "          W    W",
      "               W",
      "               W"
    ],
    [
      "AWGGGAGGGGAGGGWA",
      "               W",
      "          W    G",
      "          W    G",
      "          W    G",
      "          W    A",
      "          W    G",
      "               G",
      "               G",
      "          W    G",
      "          W    A",
      "          W    G",
      "          W    G",
      "          W    G",
      "               W",
      "               A"
    ],
    [
      "AWGGGAGGGGAGGGWA",
      "               W",
      "          W    G",
      "          W    G",
      "          W    G",
      "          W    A",
      "          W    G",
      "               G",
      "               G",
      "          W    G",
      "          W    A",
      "          W    G",
      "          W    G",
      "          W    G",
      "               W",
      "               A"
    ],
    [
      "WWGGGWGGGGWGGGWW",
      "               W",
      "               G",
      "               G",
      "               G",
      "               W",
      "               G",
      "               G",
      "               G",
      "               G",
      "               W",
      "               G",
      "               G",
      "               G",
      "               W",
      "               W"
    ],
    [
      "WWWWWWWWWWWWWWWW",
      "               W",
      "               W",
      "               W",
      "               W",
      "   L    L      W",
      "               W",
      "               W",
      "               W",
      "               W",
      "               W",
      "               W",
      "   L    L      W",
      "               W",
      "               W",
      "               W"
    ]
  ],
  "refpalette": "biohazard:custom_buildings"
}
