{
  "xsize": 16,
  "zsize": 16,
  "slices": [
    [
      "WWWWWWWWWWWWWW  ",
      "WFFFFFFFFFFFFFF ",
      "WFFFFFFFFFFFFFFW",
      "WFFFFFFFFFFFFFFW",
      "WFFFFFFFFFFFFFFW",
      "WFFFFFFFFFFFFFFW",
      "WFFFFFFFFFFFFFFW",
      "WFFFFFFFFFFFFFFW",
      "WFFFFFFFFFFFFFFW",
      "WFFFFFFFFFFFFFFW",
      "WFFFFFFFFFFFFFFW",
      "WFFFFFFFFFFFFFFW",
      "WFFFFFFFFFFFFFFW",
      "WFFFFFFFFFFFFFFW",
      "WFFFFFFFFFFFFFFW",
      "WWWWWWWWWWWWWWWW"
    ],
    [
      "WWWWAWWWWWWAWW  ",
      "              W ",
      "          W    W",
      "  q    q  W    W",
      "  Q    Q  W  u A",
      "          W    W",
      "          W    W",
      "               W",
      "               W",
      "          W    W",
      "  q    q  W    W",
      "  Q    Q  W  i A",
      "          W    W",
      "          W    W",
      "               W",
      "               W"
    ],
    [
      "AWGGAAGGGGAAGG  ",
      "              G ",
      "          W    G",
      "          W    G",
      "          W    A",
      "          W    A",
      "          W    G",
      "               G",
      "               G",
      "          W    G",
      "          W    A",
      "          W    A",
      "          W    G",
      "          W    G",
      "               W",
      "               A"
    ],
    [
      "AWGGAAGGGGAAGG  ",
      "              G ",
      "          W    G",
      "          W    G",
      "          W    A",
      "          W    A",
      "          W    G",
      "               G",
      "               G",
      "          W    G",
      "          W    A",
      "          W    A",
      "          W    G",
      "          W    G",
      "               W",
      "               A"
    ],
    [
      "WWGGAWGGGGWAGG  ",
      "              G ",
      "               G",
      "               G",
      "               A",
      "               W",
      "               G",
      "               G",
      "               G",
      "               G",
      "               W",
      "               A",
      "               G",
      "               G",
      "               W",
      "               W"
    ],
    [
      "WWWWAWWWWWWAWW  ",
      "              W ",
      "               W",
      "               W",
      "               A",
      "   L    L      W",
      "               W",
      "               W",
      "               W",
      "               W",
      "               W",
      "               A",
      "   L    L      W",
      "               W",
      "               W",
      "               W"
    ]
  ],
  "refpalette": "biohazard:custom_buildings"
}
