{
  "xsize": 16,
  "zsize": 16,
  "slices": [
    [
      "WWWWWWWWWWWWWWWW",
      "WFFFFFFFFFFFFFFW",
      "WFFFFFFFFFFFFFFW",
      "WFFFFFFFFFFFFFFW",
      "WFFFFFFFFFFFFFFW",
      "WFFFFFFFFFFFFFFW",
      "WFFFFFFFFFFFFFFW",
      "WFFFFFFFFFFFFFFW",
      "WFFFFFFFFFFFFFFW",
      "WFFFFFFFFFFFFFFW",
      "WFFFFFFFFFFFFFFW",
      "WFFFFFFFFFFFFFFW",
      "WFFFFFFFFFFFFFFW",
      "WFFFFFFFFFFFFFFW",
      "WFFFFFFFFFFFFFFW",
      "WWWWWWWWWWWWWWWW"
    ],
    [
      "WWWWWWA  AWWWWWW",
      "W    W         W",
      "W    W         W",
      "W TTTW         W",
      "W              W",
      "W              W",
      "W  uiW  A      W",
      "W    W         W",
      "W    W    cc   W",
      "W    W   :dd:  W",
      "W    W   :  :  W",
      "W        :  :  W",
      "W    W   :  :  W",
      "W    W   :  :  W",
      "W    W         W",
      "WWWWWWWWWWWWWWWW"
    ],
    [
      "AWGGGAA  AAGGGWA",
      "W    W         W",
      "G    W         G",
      "G    W         G",
      "G              G",
      "A              A",
      "G    W         G",
      "G    W         G",
      "G    W         G",
      "G    W    cc   G",
      "A    W    dd   A",
      "G              G",
      "G    W         G",
      "G    W         G",
      "W    W         W",
      "AWGGGAGGGGAGGGWA"
    ],
    [
      "AWGGGAA  AAGGGWA",
      "W    W         W",
      "G    W         G",
      "G    W         G",
      "G              G",
      "A              A",
      "G    W         G",
      "G    W         G",
      "G    W         G",
      "G    W         G",
      "A    W    cc   A",
      "G         dd   G",
      "G    W         G",
      "G    W         G",
      "W    W         W",
      "AWGGGAGGGGAGGGWA"
    ],
    [
      "WWGGGWGGGGWGGGWW",
      "W    W         W",
      "G    W         G",
      "G    W         G",
      "G              G",
      "W              W",
      "G    W         G",
      "G    W         G",
      "G    W         G",
      "G    W         G",
      "W    W         W",
      "G         cc   G",
      "G    W    dd   G",
      "G    W         G",
      "W    W         W",
      "WWGGGWGGGGWGGGWW"
    ],
    [
      "WWWWWWWWWWWWWWWW",
      "W              W",
      "W              W",
      "W  L           W",
      "W       L      W",
      "W              W",
      "W              W",
      "W              W",
      "W              W",
      "W              W",
      "W  L           W",
      "W       L      W",
      "W         cc   W",
      "W         dd   W",
      "W              W",
      "WWWWWWWWWWWWWWWW"
    ]
  ],
  "refpalette": "biohazard:custom_buildings"
}
