{
  "xsize": 16,
  "zsize": 16,
  "slices": [
    [
      "WWWWWWWWWWWWWWWW",
      "WFFFFFFFFFFFFFFW",
      "WFFFFFFFFFFFFFFW",
      "WFFFFFFFFFFFFFFW",
      "WFFFFFFFFFFFFFFW",
      "WFFFFFFFFFFFFFFW",
      "WFFFFFFFFFFFFFFW",
      "WFFFFFFFFFFFFFFW",
      "WFFFFFFFFFFFFFFW",
      "WFFFFFFFFFFFFFFW",
      "WFFFFFFFFFFFFFFW",
      "WFFFFFFFFFFFFFFW",
      "WFFFFFFFFFFFFFFW",
      "WFFFFFFFFFFFFFFW",
      "WFFFFFFFFFFFFFFW",
      "WWWWWWWWWWWWWWWW"
    ],
    [
      "W               ",
      "W               ",
      "W    W          ",
      "W q  W q        ",
      "W Q  W Q     u  ",
      "W    W          ",
      "W    W          ",
      "W               ",
      "W               ",
      "W    W          ",
      "W q  W q        ",
      "W Q  W Q     i  ",
      "W    W          ",
      "W    W          ",
      "W               ",
      "WWWWWWWWWWWWWWWW"
    ],
    [
      "A               ",
      "W               ",
      "G    W          ",
      "G    W          ",
      "G    W          ",
      "A    W          ",
      "G    W          ",
      "G               ",
      "G               ",
      "G    W          ",
      "A    W          ",
      "G    W          ",
      "G    W          ",
      "G    W          ",
      "W               ",
      "AWGGGAGGGGAGGGWA"
    ],
    [
      "A               ",
      "W               ",
      "G    W          ",
      "G    W          ",
      "G    W          ",
      "A    W          ",
      "G    W          ",
      "G               ",
      "G               ",
      "G    W          ",
      "A    W          ",
      "G    W          ",
      "G    W          ",
      "G    W          ",
      "W               ",
      "AWGGGAGGGGAGGGWA"
    ],
    [
      "W               ",
      "W               ",
      "G               ",
      "G               ",
      "G               ",
      "W               ",
      "G               ",
      "G               ",
      "G               ",
      "G               ",
      "W               ",
      "G               ",
      "G               ",
      "G               ",
      "W               ",
      "WWGGGWGGGGWGGGWW"
    ],
    [
      "W               ",
      "W               ",
      "W               ",
      "W               ",
      "W               ",
      "W  L    L       ",
      "W               ",
      "W               ",
      "W               ",
      "W               ",
      "W               ",
      "W               ",
      "W  L    L       ",
      "W               ",
      "W               ",
      "WWWWWWWWWWWWWWWW"
    ]
  ],
  "refpalette": "biohazard:custom_buildings"
}
