{
  "xsize": 16,
  "zsize": 16,
  "slices": [
    [
      "WWWWWWWWWWWWWWWW",
      "WFFFFFFFFFFFFFFW",
      "WFFFFFFFFFFFFFFW",
      "WFFFFFFFFFFFFFFW",
      "WFFFFFFFFFFFFFFW",
      "WFFFFFFFFFFFFFFW",
      "WFFFFFFFFFFFFFFW",
      "WFFFFFFFFFFFFFFW",
      "WFFFFFFFFFFFFFFW",
      "WFFFFFFFFFFFFFFW",
      "WFFFFFFFFFFFFFFW",
      "WFFFFFFFFFFFFFFW",
      "WFFFFFFFFFFFFFFW",
      "WFFFFFFFFFFFFFFW",
      "WFFFFFFFFFFFFFFW",
      "WWWWWWWWWWWWWWWW"
    ],
    [
      "W               ",
      "W               ",
      "W    W          ",
      "W    W          ",
      "A  TTTTT     u  ",
      "W    W          ",
      "W    W          ",
      "W               ",
      "W               ",
      "W    W          ",
      "W    W          ",
      "A    W  AAAAAi  ",
      "W    W          ",
      "W    W          ",
      " W              ",
      "  WWAWWWWWWAWWWW"
    ],
    [
      "A               ",
      "W               ",
      "G    W          ",
      "G    W          ",
      "A    W          ",
      "A    W          ",
      "G    W          ",
      "G               ",
      "G               ",
      "G    W          ",
      "A    W          ",
      "A    W          ",
      "G    W          ",
      "G    W          ",
      " G              ",
      "  GGAAGGGGAAGGWA"
    ],
    [
      "A               ",
      "W               ",
      "G    W          ",
      "G    W          ",
      "A    W          ",
      "A    W          ",
      "G    W          ",
      "G               ",
      "G               ",
      "G    W          ",
      "A    W          ",
      "A    W          ",
      "G    W          ",
      "G    W          ",
      " G              ",
      "  GGAAGGGGAAGGWA"
    ],
    [
      "W               ",
      "W               ",
      "G               ",
      "G               ",
      "A               ",
      "W               ",
      "G               ",
      "G               ",
      "G               ",
      "G               ",
      "W               ",
      "A               ",
      "G               ",
      "G               ",
      " G              ",
      "  GGAWGGGGWAGGWW"
    ],
    [
      "W               ",
      "W               ",
      "W               ",
      "W               ",
      "A               ",
      "W  L    L       ",
      "W               ",
      "W               ",
      "W               ",
      "W               ",
      "W               ",
      "A               ",
      "W  L    L       ",
      "W               ",
      " W              ",
      "  WWAWWWWWWAWWWW"
    ]
  ],
  "refpalette": "biohazard:custom_buildings"
}
