{
  "xsize": 16,
  "zsize": 16,
  "slices": [
    [
      "FFFFFFFFFFFFFFFF",
      "FFFFFFFFFFFFFFFF",
      "FFFFFFFFFFFFFFFF",
      "FFFFFFFFFFFFFFFF",
      "FFFFFFFFFFFFFFFF",
      "FFFFFFFFFFFFFFFF",
      "FFFFFFFFFFFFFFFF",
      "FFFFFFFFFFFFFFFF",
      "FFFFFFFFFFFFFFFF",
      "FFFFFFFFFFFFFFFF",
      "FFFFFFFFFF  FFFF",
      "FFFFFFFFFF  FFFF",
      "FFFFFFFFFF  FFFF",
      "FFFFFFFFFFccFFFF",
      "FFFFFFFFFFFFFFF ",
      "FFFFFFFFFFFFFF  "
    ],
    [
      "               W",
      "               W",
      "               W",
      "   XX XX       W",
      "   XX          W",
      "               W",
      "               W",
      "   AAAAA       W",
      "               W",
      "         WWWW  W",
      "         W  W  W",
      "         W  W  W",
      "         W  W  W",
      "            W  W",
      "         WWWW W ",
      "WWWWWWWWWWWWWW  "
    ],
    [
      "                ",
      "                ",
      "                ",
      "                ",
      "                ",
      "                ",
      "                ",
      "                ",
      "                ",
      "         WWWW   ",
      "         W  W   ",
      "         W  G   ",
      "         W  W   ",
      "            W   ",
      "         WWWW G ",
      "                "
    ],
    [
      "                ",
      "                ",
      "                ",
      "                ",
      "                ",
      "                ",
      "                ",
      "                ",
      "                ",
      "         WWWW   ",
      "         W  W   ",
      "         W  G   ",
      "         W  W   ",
      "            W   ",
      "         WWWW G ",
      "                "
    ],
    [
      "                ",
      "                ",
      "                ",
      "                ",
      "                ",
      "                ",
      "                ",
      "                ",
      "                ",
      "         FFFF   ",
      "         FFFF   ",
      "         FFFF   ",
      "         FFFF   ",
      "         FFFF   ",
      "         FFFF G ",
      "                "
    ],
    [
      "                ",
      "                ",
      "                ",
      "                ",
      "                ",
      "                ",
      "                ",
      "                ",
      "                ",
      "                ",
      "                ",
      "                ",
      "                ",
      "                ",
      "              W ",
      "                "
    ]
  ],
  "refpalette": "biohazard:custom_buildings"
}
