{
  "xsize": 16,
  "zsize": 16,
  "slices": [
    [
      "WWWWWWWFFWWWWWWW",
      "WFFFFFFFFFFFFFFW",
      "WFFFFFFFFFFFFFFW",
      "WFFFFFFFFFFFFFFW",
      "WFFFFFFFFFFFFFFW",
      "WFFFFFFFFFFFFFFW",
      "WFFFFFFFFFFFFFFW",
      "WFFFFFFFFFFFFFFW",
      "WFFFFFFFFFFFFFFW",
      "WFFFFFFFFFFFFFFW",
      "WFFFFFFFFFFFFFFW",
      "WFFFFFFFFFFFFFFW",
      "WFFFFFFFFFFFFFFW",
      "WFFFFFFFFFFFFFFW",
      "WFFFFFFFFFFFFFFW",
      "WWWWWWWWWWWWWWWW"
    ],
    [
      "  WWWWA  AWWWW  ",
      " W   W        W ",
      "W    W         W",
      "W TTTW         W",
      " A             W",
      " W             W",
      " W uiW  A      W",
      " W   W         W",
      " W   W    cc   W",
      " W   W   :dd:  W",
      " W   W   :  :  W",
      " A       :  :  W",
      "W    W   :  :  W",
      "W    W   :  :  W",
      " W   W        W ",
      "  WWWWWWWWWWWW  "
    ],
    [
      "  GGGAA  AAGGG  ",
      " G   W        G ",
      "G    W         G",
      "G    W         G",
      " A             G",
      " G             A",
      " G   W         G",
      " G   W         G",
      " G   W         G",
      " G   W    cc   G",
      " G   W    dd   A",
      " A             G",
      "G    W         G",
      "G    W         G",
      " G   W        G ",
      "  GGGAGGGGAGGG  "
    ],
    [
      "  GGGAA  AAGGG  ",
      " G   W        G ",
      "G    W         G",
      "G    W         G",
      " A             G",
      " G             A",
      " G   W         G",
      " G   W         G",
      " G   W         G",
      " G   W         G",
      " G   W    cc   A",
      " A        dd   G",
      "G    W         G",
      "G    W         G",
      " G   W        G ",
      "  GGGAGGGGAGGG  "
    ],
    [
      "  GGGWAAAAWGGG  ",
      " G   W        G ",
      "G    W         G",
      "G    W         G",
      " A             G",
      " G             W",
      " G   W         G",
      " G   W         G",
      " G   W         G",
      " G   W         G",
      " G   W         W",
      " A        cc   G",
      "G    W    dd   G",
      "G    W         G",
      " G   W        G ",
      "  GGGWGGGGWGGG  "
    ],
    [
      "  WWWWWWWWWWWW  ",
      " W            W ",
      "W              W",
      "W  L           W",
      " A      L      W",
      " W             W",
      " W             W",
      " W             W",
      " W             W",
      " W             W",
      " W L           W",
      " A      L      W",
      "W         cc   W",
      "W         dd   W",
      " W            W ",
      "  WWWWWWWWWWWW  "
    ]
  ],
  "refpalette": "biohazard:custom_buildings"
}
