{
  "xsize": 16,
  "zsize": 16,
  "slices": [
    [
      "WWWWWWWWWWWWWWWW",
      "WFFFFFFFFFFFFFFW",
      "WFFFFFFFFFFFFFFW",
      "WFFFFFFFFFFFFFFW",
      "WFFFFFFFFFFFFFFW",
      "WFFFFFFFFFFFFFFW",
      "WFFFFFFFFFFFFFFW",
      "WFFFFFFFFFFFFFFW",
      "WFFFFFFFFFFFFFFW",
      "WFFFFFFFFFFFFFFW",
      "WFFFFFFFFF  FFFW",
      "WFFFFFFFFF  FFFW",
      "WFFFFFFFFF  FFFW",
      "WFFFFFFFFFccFFFW",
      "WFFFFFFFFFFFFFFW",
      "WWWWWWWWWWWWWWWW"
    ],
    [
      "WWWWWWWWWWWWWWWW",
      "W               ",
      "W    W          ",
      "W q  W q        ",
      "W Q  W Q     u  ",
      "W    W          ",
      "W    W          ",
      "W               ",
      "W         cc    ",
      "W    W   :dd:   ",
      "W q  W q :  :   ",
      "W Q  W Q :  :i  ",
      "W    W   :  :   ",
      "W    W   :  :   ",
      "W               ",
      "W               "
    ],
    [
      "AWGGGAGGGGAGGGWA",
      "W               ",
      "G    W          ",
      "G    W          ",
      "G    W          ",
      "A    W          ",
      "G    W          ",
      "G               ",
      "G               ",
      "G    W    cc    ",
      "A    W    dd    ",
      "G    W          ",
      "G    W          ",
      "G    W          ",
      "W               ",
      "A               "
    ],
    [
      "AWGGGAGGGGAGGGWA",
      "W               ",
      "G    W          ",
      "G    W          ",
      "G    W          ",
      "A    W          ",
      "G    W          ",
      "G               ",
      "G               ",
      "G    W          ",
      "A    W    cc    ",
      "G    W    dd    ",
      "G    W          ",
      "G    W          ",
      "W               ",
      "A               "
    ],
    [
      "WWGGGWGGGGWGGGWW",
      "W               ",
      "G               ",
      "G               ",
      "G               ",
      "W               ",
      "G               ",
      "G               ",
      "G               ",
      "G               ",
      "W               ",
      "G         cc    ",
      "G         dd    ",
      "G               ",
      "W               ",
      "W               "
    ],
    [
      "WWWWWWWWWWWWWWWW",
      "W               ",
      "W               ",
      "W               ",
      "W               ",
      "W  L    L       ",
      "W               ",
      "W               ",
      "W               ",
      "W               ",
      "W               ",
      "W               ",
      "W  L    L cc    ",
      "W         dd    ",
      "W               ",
      "W               "
    ]
  ],
  "refpalette": "biohazard:custom_buildings"
}
