{
  "xsize": 16,
  "zsize": 16,
  "slices": [
    [
      "  WWWWWWWWWWWWWW",
      " FFFFFFFFFFFFFFW",
      "WFFFFFFFFFFFFFFW",
      "WFFFFFFFFFFFFFFW",
      "WFFFFFFFFFFFFFFW",
      "WFFFFFFFFFFFFFFW",
      "WFFFFFFFFFFFFFFW",
      "WFFFFFFFFFFFFFFW",
      "WFFFFFFFFFFFFFFW",
      "WFFFFFFFFFFFFFFW",
      "WFFFFFFFFF  FFFW",
      "WFFFFFFFFF  FFFW",
      "WFFFFFFFFF  FFFW",
      "WFFFFFFFFFccFFFW",
      "WFFFFFFFFFFFFFFW",
      "WWWWWWWWWWWWWWWW"
    ],
    [
      "  WWAWWWWWWAWWWW",
      " W              ",
      "W    W          ",
      "W q  W q        ",
      "A Q  W Q     u  ",
      "W    W          ",
      "W    W          ",
      "W               ",
      "W         cc    ",
      "W    W   :dd:   ",
      "W q  W q :  :   ",
      "A Q  W Q :  :i  ",
      "W    W   :  :   ",
      "W    W   :  :   ",
      "W               ",
      "W               "
    ],
    [
      "  GGAAGGGGAAGGWA",
      " G              ",
      "G    W          ",
      "G    W          ",
      "A    W          ",
      "A    W          ",
      "G    W          ",
      "G               ",
      "G               ",
      "G    W    cc    ",
      "A    W    dd    ",
      "A    W          ",
      "G    W          ",
      "G    W          ",
      "W               ",
      "A               "
    ],
    [
      "  GGAAGGGGAAGGWA",
      " G              ",
      "G    W          ",
      "G    W          ",
      "A    W          ",
      "A    W          ",
      "G    W          ",
      "G               ",
      "G               ",
      "G    W          ",
      "A    W    cc    ",
      "A    W    dd    ",
      "G    W          ",
      "G    W          ",
      "W               ",
      "A               "
    ],
    [
      "  GGAWGGGGWAGGWW",
      " G              ",
      "G               ",
      "G               ",
      "A               ",
      "W               ",
      "G               ",
      "G               ",
      "G               ",
      "G               ",
      "W               ",
      "A         cc    ",
      "G         dd    ",
      "G               ",
      "W               ",
      "W               "
    ],
    [
      "  WWAWWWWWWAWWWW",
      " W              ",
      "W               ",
      "W               ",
      "A               ",
      "W  L    L       ",
      "W               ",
      "W               ",
      "W               ",
      "W               ",
      "W               ",
      "A               ",
      "W  L    L cc    ",
      "W         dd    ",
      "W               ",
      "W               "
    ]
  ],
  "refpalette": "biohazard:custom_buildings"
}
