{
  "xsize": 16,
  "zsize": 16,
  "slices": [
    [
      "WWWWWWWWWWWWWWWW",
      "WFFFFFFFFFFFFFFW",
      "WFFFFFFFFFFFFFFW",
      "WFFFFFFFFFFFFFFW",
      "WFFFFFFFFFFFFFFW",
      "WFFFFFFFFFFFFFFW",
      "WFFFFFFFFFFFFFFW",
      "WFFFFFFFFFFFFFFW",
      "WFFFFFFFFFFFFFFW",
      "WFFFFFFFFFFFFFFW",
      "WFFFFFFFFF  FFFW",
      "WFFFFFFFFF  FFFW",
      "WFFFFFFFFF  FFFW",
      "WFFFFFFFFFccFFFW",
      "WFFFFFFFFFFFFFFW",
      "WWWWWWWWWWWWWWWW"
    ],
    [
      "WWWWWWWWWWWWWWWW",
      "W    W         W",
      "W    W         W",
      "W q  W q       W",
      "W Q    Q       W",
      "W              W",
      "W    W q       W",
      "W    W Q       W",
      "W    W    cc   W",
      "W q  W   :dd:  W",
      "W Q  W   :  :  W",
      "W        :  :  W",
      "W    W   :  :  W",
      "W  u W i :  :  W",
      "W    W         W",
      "WWWWWWWWWWWWWWWW"
    ],
    [
      "AWGGGAGGGGAGGGWA",
      "W    W         W",
      "G    W         G",
      "G    W         G",
      "G              G",
      "A              A",
      "G    W         G",
      "G    W         G",
      "G    W         G",
      "G    W    cc   G",
      "A    W    dd   A",
      "G              G",
      "G    W         G",
      "G    W         G",
      "W    W         W",
      "AWGGGAGGGGAGGGWA"
    ],
    [
      "AWGGGAGGGGAGGGWA",
      "W    W         W",
      "G    W         G",
      "G    W         G",
      "G              G",
      "A              A",
      "G    W         G",
      "G    W         G",
      "G    W         G",
      "G    W         G",
      "A    W    cc   A",
      "G         dd   G",
      "G    W         G",
      "G    W         G",
      "W    W         W",
      "AWGGGAGGGGAGGGWA"
    ],
    [
      "WWGGGWGGGGWGGGWW",
      "W    W         W",
      "G    W         G",
      "G    W         G",
      "G              G",
      "W              W",
      "G    W         G",
      "G    W         G",
      "G    W         G",
      "G    W         G",
      "W    W         W",
      "G         cc   G",
      "G    W    dd   G",
      "G    W         G",
      "W    W         W",
      "WWGGGWGGGGWGGGWW"
    ],
    [
      "WWWWWWWWWWWWWWWW",
      "W              W",
      "W              W",
      "W  L           W",
      "W       L      W",
      "W              W",
      "W              W",
      "W              W",
      "W              W",
      "W              W",
      "W  L           W",
      "W       L      W",
      "W         cc   W",
      "W         dd   W",
      "W              W",
      "WWWWWWWWWWWWWWWW"
    ]
  ],
  "refpalette": "biohazard:custom_buildings"
}
