{
  "xsize": 16,
  "zsize": 16,
  "slices": [
    [
      "NNNNNNNNNNNNNNNN",
      "NFFFFFFFFFFFFFFN",
      "NFFFFFFFFFFFFFFN",
      "NFFFFFFFFFFFFFFN",
      "NFFFFFFFFFFFFFFN",
      "NFFFFFFFFFFFFFFN",
      "NFFFFFFFFFFFFFFN",
      "NFFFFFFFFFFFFFFN",
      "NFFFFFFFFFFFFFFN",
      "NFFFFFFFFFFFFFFN",
      "NFFFFFFFFFFFFFFN",
      "NFFFFFFFFFFFFFFN",
      "NFFFFFFFFFFFFFFN",
      "NFFFFFFFFFFFFFFN",
      "NFFFFFFFFFFFFFFN",
      "NNNNNNNNNNNNNNNN"
    ],
    [
      "NNNNNNR  RNNNNNN",
      "N              N",
      "N     TTTT     N",
      "N  TT  TT    e N",
      "N              N",
      "N            f N",
      "NNNN  NNN      N",
      "N              N",
      "N         cc   N",
      "N        :dd:  N",
      "N  TT  TT:  :  N",
      "N        :  :  N",
      "N        :  :  N",
      "N  e     :  :  N",
      "N              N",
      "NNNNNNNNNNNNNNNN"
    ],
    [
      "RNVVVRR  RRVVVNR",
      "N              N",
      "V              V",
      "V  K   K       V",
      "V              V",
      "R              R",
      "VNNN  NNN      V",
      "V              V",
      "V              V",
      "V         cc   V",
      "R  K   K  dd   R",
      "V              V",
      "V              V",
      "V              V",
      "N              N",
      "RNVVVRVVVVRVVVNR"
    ],
    [
      "RNVVVRR  RRVVVNR",
      "N              N",
      "V              V",
      "V              V",
      "V              V",
      "R              R",
      "VNNN  NNN      V",
      "V              V",
      "V              V",
      "V              V",
      "R         cc   R",
      "V         dd   V",
      "V              V",
      "V              V",
      "N              N",
      "RNVVVRVVVVRVVVNR"
    ],
    [
      "NNVVVNVVVVNVVVNN",
      "N              N",
      "V              V",
      "V              V",
      "V              V",
      "N              N",
      "V              V",
      "V              V",
      "V              V",
      "V              V",
      "N              N",
      "V         cc   V",
      "V         dd   V",
      "V              V",
      "N              N",
      "NNVVVNVVVVNVVVNN"
    ],
    [
      "NNNNNNNNNNNNNNNN",
      "N              N",
      "N              N",
      "N              N",
      "N   L   L      N",
      "N              N",
      "N              N",
      "N              N",
      "N              N",
      "N              N",
      "N              N",
      "N   L   L      N",
      "N         cc   N",
      "N         dd   N",
      "N              N",
      "NNNNNNNNNNNNNNNN"
    ]
  ],
  "refpalette": "biohazard:custom_buildings"
}
