{
  "xsize": 16,
  "zsize": 16,
  "slices": [
    [
      "FFFFFFFFFFFFFFFF",
      "FFFFFFFFFFFFFFFF",
      "FFFFFFFFFFFFFFFF",
      "FFFFFFFFFFFFFFFF",
      "FFFFFFFFFFFFFFFF",
      "FFFFFFFFFFFFFFFF",
      "FFFFFFFFFFFFFFFF",
      "FFFFFFFFFFFFFFFF",
      "FFFFFFFFFFFFFFFF",
      "FFFFFFFFFFFFFFFF",
      "FFFFFFFFFF  FFFF",
      "FFFFFFFFFF  FFFF",
      "FFFFFFFFFF  FFFF",
      "FFFFFFFFFFccFFFF",
      "FFFFFFFFFFFFFFFF",
      "FFFFFFFFFFFFFFFF"
    ],
    [
      "NNNNNNNNNNNNNNNN",
      "N              N",
      "N              N",
      "N  XX XX       N",
      "N  XX          N",
      "N              N",
      "N              N",
      "N  RRRRR       N",
      "N              N",
      "N        NNNN  N",
      "N        N  N  N",
      "N        N  N  N",
      "N        N  N  N",
      "N           N  N",
      "N        NNNN  N",
      "NNNNNNNNNNNNNNNN"
    ],
    [
      "                ",
      "                ",
      "                ",
      "                ",
      "                ",
      "                ",
      "                ",
      "                ",
      "                ",
      "         NNNN   ",
      "         N  N   ",
      "         N  G   ",
      "         N  N   ",
      "            N   ",
      "         NNNN   ",
      "                "
    ],
    [
      "                ",
      "                ",
      "                ",
      "                ",
      "                ",
      "                ",
      "                ",
      "                ",
      "                ",
      "         NNNN   ",
      "         N  N   ",
      "         N  G   ",
      "         N  N   ",
      "            N   ",
      "         NNNN   ",
      "                "
    ],
    [
      "                ",
      "                ",
      "                ",
      "                ",
      "                ",
      "                ",
      "                ",
      "                ",
      "                ",
      "         FFFF   ",
      "         FFFF   ",
      "         FFFF   ",
      "         FFFF   ",
      "         FFFF   ",
      "         FFFF   ",
      "                "
    ],
    [
      "                ",
      "                ",
      "                ",
      "                ",
      "                ",
      "                ",
      "                ",
      "                ",
      "                ",
      "                ",
      "                ",
      "                ",
      "                ",
      "                ",
      "                ",
      "                "
    ]
  ],
  "refpalette": "biohazard:custom_buildings"
}
