{
  "xsize": 16,
  "zsize": 16,
  "slices": [
    [
      "FFFFFFFFFFFFFFFF",
      "FFFFFFFFFFFFFFFF",
      "FFFFFFFFFFFFFFFF",
      "FFFFFFFFFFFFFFFF",
      "FFFFFFFFFFFFFFFF",
      "FFFFFFFFFFFFFFFF",
      "FFFFFFFFFFFFFFFF",
      "FFFFFFFFFFFFFFFF",
      "FFFFFFFFFFFFFFFF",
      "FFFFFFFFFFFFFFFF",
      "FFFFFFFFFF  FFFF",
      "FFFFFFFFFF  FFFF",
      "FFFFFFFFFF  FFFF",
      "FFFFFFFFFFccFFFF",
      "FFFFFFFFFFFFFFFF",
      "FFFFFFFFFFFFFFFF"
    ],
    [
      "PPPPPPPPPPPPPPPP",
      "P              P",
      "P              P",
      "P  XX XX       P",
      "P  XX          P",
      "P              P",
      "P              P",
      "P  HHHHH       P",
      "P              P",
      "P        PPPP  P",
      "P        P  P  P",
      "P        P  P  P",
      "P        P  P  P",
      "P           P  P",
      "P        PPPP  P",
      "PPPPPPPPPPPPPPPP"
    ],
    [
      "                ",
      "                ",
      "                ",
      "                ",
      "                ",
      "                ",
      "                ",
      "                ",
      "                ",
      "         PPPP   ",
      "         P  P   ",
      "         P  G   ",
      "         P  P   ",
      "            P   ",
      "         PPPP   ",
      "                "
    ],
    [
      "                ",
      "                ",
      "                ",
      "                ",
      "                ",
      "                ",
      "                ",
      "                ",
      "                ",
      "         PPPP   ",
      "         P  P   ",
      "         P  G   ",
      "         P  P   ",
      "            P   ",
      "         PPPP   ",
      "                "
    ],
    [
      "                ",
      "                ",
      "                ",
      "                ",
      "                ",
      "                ",
      "                ",
      "                ",
      "                ",
      "         FFFF   ",
      "         FFFF   ",
      "         FFFF   ",
      "         FFFF   ",
      "         FFFF   ",
      "         FFFF   ",
      "                "
    ],
    [
      "                ",
      "                ",
      "                ",
      "                ",
      "                ",
      "                ",
      "                ",
      "                ",
      "                ",
      "                ",
      "                ",
      "                ",
      "                ",
      "                ",
      "                ",
      "                "
    ]
  ],
  "refpalette": "biohazard:custom_buildings"
}
