{
  "xsize": 16,
  "zsize": 16,
  "slices": [
    [
      "PPPPPPPPPPPPPPPP",
      "PFFFFFFFFFFFFFFP",
      "PFFFFFFFFFFFFFFP",
      "PFFFFFFFFFFFFFFP",
      "PFFFFFFFFFFFFFFP",
      "PFFFFFFFFFFFFFFP",
      "PFFFFFFFFFFFFFFP",
      "PFFFFFFFFFFFFFFP",
      "PFFFFFFFFFFFFFFP",
      "PFFFFFFFFFFFFFFP",
      "PFFFFFFFFFFFFFFP",
      "PFFFFFFFFFFFFFFP",
      "PFFFFFFFFFFFFFFP",
      "PFFFFFFFFFFFFFFP",
      "PFFFFFFFFFFFFFFP",
      "PPPPPPPPPPPPPPPP"
    ],
    [
      "PPPPPPH  HPPPPPP",
      "P      P       P",
      "P q  u P  q  i P",
      "P Q    P  Q    P",
      "P              P",
      "P      P       P",
      "P      P       P",
      "PPP  PPPP    PPP",
      "P      P  cc   P",
      "P      P :dd:  P",
      "P q    Pq:  :  P",
      "P Q     Q:  :  P",
      "P    j P :  :m P",
      "P      P :  :  P",
      "P      P       P",
      "PPPPPPPPPPPPPPPP"
    ],
    [
      "HPGGGHH  HHGGGPH",
      "P      P       P",
      "G      P       G",
      "G      P       G",
      "G              G",
      "H      P       H",
      "G      P       G",
      "GPP  PPPP    PPG",
      "G      P       G",
      "G      P  cc   G",
      "H      P  dd   H",
      "G              G",
      "G      P       G",
      "G      P       G",
      "P      P       P",
      "HPGGGHGGGGHGGGPH"
    ],
    [
      "HPGGGHH  HHGGGPH",
      "P      P       P",
      "G      P       G",
      "G      P       G",
      "G              G",
      "H      P       H",
      "G      P       G",
      "GPP  PPPP    PPG",
      "G      P       G",
      "G      P       G",
      "H      P  cc   H",
      "G         dd   G",
      "G      P       G",
      "G      P       G",
      "P      P       P",
      "HPGGGHGGGGHGGGPH"
    ],
    [
      "PPGGGPGGGGPGGGPP",
      "P      P       P",
      "G      P       G",
      "G      P       G",
      "G              G",
      "P      P       P",
      "G      P       G",
      "GPP  PPPPPPPPPPG",
      "G      P       G",
      "G      P       G",
      "P      P       P",
      "G         cc   G",
      "G      P  dd   G",
      "G      P       G",
      "P      P       P",
      "PPGGGPGGGGPGGGPP"
    ],
    [
      "PPPPPPPPPPPPPPPP",
      "P              P",
      "P              P",
      "P              P",
      "P   L      L   P",
      "P              P",
      "P              P",
      "P              P",
      "P              P",
      "P              P",
      "P              P",
      "P   L      L   P",
      "P         cc   P",
      "P         dd   P",
      "P              P",
      "PPPPPPPPPPPPPPPP"
    ]
  ],
  "refpalette": "biohazard:custom_buildings"
}
