{
    "xsize":  16,
    "zsize":  16,
    "slices":  [
                   [
                       "#SSSSSSSSSSSSSS#",
                       "S##############S",
                       "S##############S",
                       "S##############S",
                       "S##############S",
                       "S##############S",
                       "S##############S",
                       "S##############S",
                       "S##############S",
                       "S##############S",
                       "S#########  ###S",
                       "S#########  ###S",
                       "S#########  ###S",
                       "S#########cc###S",
                       "S##############S",
                       "#SSSSSSSSSSSSSS#"
                   ],
                   [
                       "#aa#aa#aa#aa#aa#",
                       "a     #D F     a",
                       "a     Q C   wz a",
                       "#F    Q     B  #",
                       "a     Q     A  a",
                       "a     Q        a",
                       "#F    #        #",
                       "a              a",
                       "a         cc   a",
                       "#F    #  :dd:  #",
                       "a     Q  :  :  a",
                       "a     Q  :  :  a",
                       "#     Q  :  :  #",
                       "a     Q        a",
                       "a     #        a",
                       "#aa#aa#aa#aa#aa#"
                   ],
                   [
                       "#aa#aa#aa#aa#aa#",
                       "a     #        a",
                       "a     Q        a",
                       "#     Q        #",
                       "a     Q        a",
                       "a     Q        a",
                       "#     #        #",
                       "a              a",
                       "a              a",
                       "#     #   cc   #",
                       "a     Q   dd   a",
                       "a     Q        a",
                       "#     Q        #",
                       "a     Q        a",
                       "a     #        a",
                       "#aa#aa#aa#aa#aa#"
                   ],
                   [
                       "#aa#aa#aa#aa#aa#",
                       "a     #        a",
                       "a     Q        a",
                       "#    EQ        #",
                       "a     Q        a",
                       "a     Q        a",
                       "#     #        #",
                       "a     #        a",
                       "a     #        a",
                       "#     #        #",
                       "a     Q   cc   a",
                       "a     Q   dd   a",
                       "#     Q        #",
                       "a     Q        a",
                       "a     #        a",
                       "#aa#aa#aa#aa#aa#"
                   ],
                   [
                       "#SSSSSSSSSSSSSS#",
                       "S##############S",
                       "S##############S",
                       "S##############S",
                       "S##############S",
                       "S##############S",
                       "S##############S",
                       "S##############S",
                       "S#########  ###S",
                       "S#########  ###S",
                       "S#########  ###S",
                       "S#########cc###S",
                       "S##############S",
                       "S##############S",
                       "S##############S",
                       "#SSSSSSSSSSSSSS#"
                   ],
                   [
                       "################",
                       "################",
                       "################",
                       "################",
                       "################",
                       "################",
                       "################",
                       "################",
                       "################",
                       "##########  ####",
                       "##########  ####",
                       "##########  ####",
                       "##########cc####",
                       "################",
                       "################",
                       "################"
                   ]
               ],
    "refpalette":  "biohazard:handcrafted_furnishings"
}
