{
  "xsize": 16,
  "zsize": 16,
  "slices": [
    [
      "#SSSSSSSSSSSSSS#",
      "S##############S",
      "S##############S",
      "S##############S",
      "S##############S",
      "S##############S",
      "S##############S",
      "S##############S",
      "S##############S",
      "S##############S",
      "S#########  ###S",
      "S#########  ###S",
      "S#########  ###S",
      "S#########cc###S",
      "S##############S",
      "#SSSSSSSSSSSSSS#"
    ],
    [
      "#aa#aa#aa#aa#aa#",
      "a  Fⓓ⑨:  ⑫⑫ⓐ   a",
      "a    ⑧:        a",
      "#F    #        #",
      "a     :        a",
      "a     :        a",
      "#::#  #        #",
      "a              a",
      "a         cc   a",
      "#     #  :dd:  #",
      "a     :  :  :  a",
      "a     :  :  :  a",
      "#     #  :  :  #",
      "a     :        a",
      "a⑥⑦   :        a",
      "#aa#aa#aa#aa#aa#"
    ],
    [
      "#aa#aa#aa#aa#aa#",
      "a     :        a",
      "a     :        a",
      "#     #        #",
      "a     :        a",
      "a     :        a",
      "#::#  #        #",
      "a              a",
      "a              a",
      "#     #   cc   #",
      "a     :   dd   a",
      "a     :        a",
      "#     #        #",
      "a     :        a",
      "a     :        a",
      "#aa#aa#aa#aa#aa#"
    ],
    [
      "#aa#aa#aa#aa#aa#",
      "a     :L       a",
      "a     :⑪       a",
      "#  E  #        #",
      "a     :        a",
      "a     :        a",
      "#::#  #        #",
      "a              a",
      "a              a",
      "#     #        #",
      "a     :   cc   a",
      "a     :   dd   a",
      "#     #        #",
      "a     :        a",
      "a     :        a",
      "#aa#aa#aa#aa#aa#"
    ],
    [
      "#SSSSSSSSSSSSSS#",
      "S##############S",
      "S##############S",
      "S##############S",
      "S##############S",
      "S##############S",
      "S##############S",
      "S##############S",
      "S#########  ###S",
      "S#########  ###S",
      "S#########  ###S",
      "S#########cc###S",
      "S##############S",
      "S##############S",
      "S##############S",
      "#SSSSSSSSSSSSSS#"
    ],
    [
      "################",
      "################",
      "################",
      "################",
      "################",
      "################",
      "################",
      "################",
      "################",
      "##########  ####",
      "##########  ####",
      "##########  ####",
      "##########cc####",
      "################",
      "################",
      "################"
    ]
  ],
  "refpalette": "biohazard:handcrafted_furnishings"
}
