{
  "xsize": 16,
  "zsize": 16,
  "slices": [
    [
      "#SSSSSSSSSSSSSS#",
      "S##############S",
      "S##############S",
      "S##############S",
      "S##############S",
      "S##############S",
      "S###1##########S",
      "S##############S",
      "S##############S",
      "S##############S",
      "S#########  ###S",
      "S#########  ###S",
      "S#########  ###S",
      "S#########cc###S",
      "S##############S",
      "#SSSSSSSSSSSSSS#"
    ],
    [
      "#aa#aa#aa#aa#aa#",
      "aⓛ       ⓒⓑ    a",
      "a        ①     a",
      "#   L         F#",
      "a   L          a",
      "a  CLF         a",
      "##########  ####",
      "a              a",
      "a         cc   a",
      "#        :dd:  #",
      "a        :  :  a",
      "a        :  :  a",
      "#        :  :  #",
      "a        :  :  a",
      "a  F ⓗⓖ ⓜ      a",
      "#aa#aa#aa#aa#aa#"
    ],
    [
      "#aa#aa#aa#aa#aa#",
      "a              a",
      "a              a",
      "#   L          #",
      "a   L          a",
      "a   L          a",
      "#######aa#  #aa#",
      "a              a",
      "a              a",
      "#         cc   #",
      "a         dd   a",
      "a              a",
      "#              #",
      "a              a",
      "a              a",
      "#aa#aa#aa#aa#aa#"
    ],
    [
      "#aa#aa#aa#aa#aa#",
      "a              a",
      "a              a",
      "#   L          #",
      "a   L          a",
      "a   LE         a",
      "#######aa#  #aa#",
      "a    E         a",
      "a              a",
      "#              #",
      "a         cc   a",
      "a         dd   a",
      "#              #",
      "a              a",
      "a              a",
      "#aa#aa#aa#aa#aa#"
    ],
    [
      "#SSSSSSSSSSSSSS#",
      "S##############S",
      "S##############S",
      "S##############S",
      "S##############S",
      "S##############S",
      "S##############S",
      "S##############S",
      "S#########  ###S",
      "S#########  ###S",
      "S#########  ###S",
      "S#########cc###S",
      "S#########dd###S",
      "S#########  ###S",
      "S##############S",
      "#SSSSSSSSSSSSSS#"
    ],
    [
      "################",
      "################",
      "################",
      "################",
      "################",
      "################",
      "################",
      "################",
      "##########  ####",
      "##########  ####",
      "##########  ####",
      "##########  ####",
      "##########cc####",
      "##########dd####",
      "################",
      "################"
    ]
  ],
  "refpalette": "biohazard:handcrafted_furnishings"
}
