{
  "xsize": 16,
  "zsize": 16,
  "slices": [
    [
      "#SSSSSSSSSSSSSS#",
      "S##############S",
      "S##############S",
      "S##############S",
      "S##############S",
      "S##############S",
      "S#####1########S",
      "S##############S",
      "S##############S",
      "S##############S",
      "S#########  ###S",
      "S#########  ###S",
      "S#########  ###S",
      "S#########cc###S",
      "S##############S",
      "#SSSSSSSSSSSSSS#"
    ],
    [
      "#aa#aa#aa#aa#aa#",
      "aLLLLL#        a",
      "aL    #②       a",
      "#C     ③       #",
      "a     #①       a",
      "a     #        a",
      "#######        #",
      "a    S#        a",
      "a    S#   cc   a",
      "#    S#  :dd:  #",
      "a     #  :  :  a",
      "a        :  :  a",
      "#    F#  :  :  #",
      "a    F#        a",
      "a⑲F⑥⑦ #        a",
      "#aa#aa#aa#aa#aa#"
    ],
    [
      "#aa#aa#aa#aa#aa#",
      "aLLLLL#        a",
      "aL    #        a",
      "#              #",
      "a     #        a",
      "a     #        a",
      "##:::##        #",
      "a     #        a",
      "a    *#        a",
      "#    *#   cc   #",
      "a     #   dd   a",
      "a              a",
      "#     #        #",
      "a     #        a",
      "a     #        a",
      "#aa#aa#aa#aa#aa#"
    ],
    [
      "#aa#aa#aa#aa#aa#",
      "aLLLLL#        a",
      "aL    #        a",
      "#     #        #",
      "a     #        a",
      "a     #        a",
      "#######E       #",
      "a     #        a",
      "a     #        a",
      "#     #        #",
      "a     #   cc   a",
      "a     #   dd   a",
      "#     #        #",
      "a     #        a",
      "a  ⑳⑲ #        a",
      "#aa#aa#aa#aa#aa#"
    ],
    [
      "#SSSSSSSSSSSSSS#",
      "S##############S",
      "S##############S",
      "S##############S",
      "S##############S",
      "S##############S",
      "S##############S",
      "S##############S",
      "S#########  ###S",
      "S#########  ###S",
      "S#########  ###S",
      "S#########cc###S",
      "S##############S",
      "S##############S",
      "S##############S",
      "#SSSSSSSSSSSSSS#"
    ],
    [
      "################",
      "################",
      "################",
      "################",
      "################",
      "################",
      "################",
      "################",
      "################",
      "##########  ####",
      "##########  ####",
      "##########  ####",
      "##########cc####",
      "################",
      "################",
      "################"
    ]
  ],
  "refpalette": "biohazard:handcrafted_furnishings"
}
