{
    "xsize":  16,
    "zsize":  16,
    "slices":  [
                   [
                       "#SSSSSSSSSSSSSS#",
                       "S##############S",
                       "S##############S",
                       "S##############S",
                       "S##############S",
                       "S##############S",
                       "S###1##########S",
                       "S##############S",
                       "S##############S",
                       "S##############S",
                       "S#########  ###S",
                       "S#########  ###S",
                       "S#########  ###S",
                       "S#########cc###S",
                       "S##############S",
                       "#SSSSSSSSSSSSSS#"
                   ],
                   [
                       "#aa#aa#aa#aa#aa#",
                       "a      D       a",
                       "a       C   wz a",
                       "#           B F#",
                       "a           A  a",
                       "a  CFF         a",
                       "##########  ####",
                       "a              a",
                       "a         cc   a",
                       "#        :dd:  #",
                       "a        :  :  a",
                       "a        :  :  a",
                       "#        :  :  #",
                       "a              a",
                       "a  F           a",
                       "#aa#aa#aa#aa#aa#"
                   ],
                   [
                       "#aa#aa#aa#aa#aa#",
                       "a              a",
                       "a              a",
                       "#              #",
                       "a              a",
                       "a              a",
                       "#######aa#  #aa#",
                       "a              a",
                       "a              a",
                       "#         cc   #",
                       "a         dd   a",
                       "a              a",
                       "#              #",
                       "a              a",
                       "a              a",
                       "#aa#aa#aa#aa#aa#"
                   ],
                   [
                       "#aa#aa#aa#aa#aa#",
                       "a              a",
                       "a              a",
                       "#              #",
                       "a              a",
                       "a    E         a",
                       "#######aa#  #aa#",
                       "a    E         a",
                       "a              a",
                       "#              #",
                       "a         cc   a",
                       "a         dd   a",
                       "#              #",
                       "a              a",
                       "a              a",
                       "#aa#aa#aa#aa#aa#"
                   ],
                   [
                       "#SSSSSSSSSSSSSS#",
                       "S##############S",
                       "S##############S",
                       "S##############S",
                       "S##############S",
                       "S##############S",
                       "S##############S",
                       "S##############S",
                       "S#########  ###S",
                       "S#########  ###S",
                       "S#########  ###S",
                       "S#########cc###S",
                       "S##############S",
                       "S##############S",
                       "S##############S",
                       "#SSSSSSSSSSSSSS#"
                   ],
                   [
                       "################",
                       "################",
                       "################",
                       "################",
                       "################",
                       "################",
                       "################",
                       "################",
                       "################",
                       "##########  ####",
                       "##########  ####",
                       "##########  ####",
                       "##########cc####",
                       "################",
                       "################",
                       "################"
                   ]
               ],
    "refpalette":  "biohazard:handcrafted_furnishings"
}
