{
  "xsize": 16,
  "zsize": 16,
  "slices": [
    [
      "  SSSSSSSSSSSS  ",
      " ############## ",
      "S##############S",
      "S##############S",
      "S##############S",
      "S############## ",
      "S############## ",
      "S############## ",
      "S############## ",
      "S############## ",
      "S#########  ### ",
      "S#########  ###S",
      "S#########  ###S",
      "S#########cc###S",
      " ############## ",
      "  SSSSSSSSSSSS  "
    ],
    [
      "  οοοεοοοοεοοο  ",
      " ε⑥Fⓓ⑨:⑱ ⑫⑫ⓐ  ε ",
      "ο    ⑧:⑱       ο",
      "οF    #        ο",
      "ο     :        ο",
      "ε     :       ε ",
      "ο::#  #       ο ",
      "ο             ο ",
      "ο         cc  ο ",
      "ο     #  :dd: ο ",
      "ε     :  :  : ε ",
      "ο     :  :  :  ο",
      "ο     #  :  :  ο",
      "ο     :  :  :  ο",
      " ε⑦   :       ε ",
      "  οοοεοοοοεοοο  "
    ],
    [
      "  θθθεθθθθεθθθ  ",
      " θ    :       θ ",
      "θ     :        θ",
      "θ     #        θ",
      "θ     :        θ",
      "ε     :       ε ",
      "θ::#  #       θ ",
      "θ             θ ",
      "θ             θ ",
      "θ     #   cc  θ ",
      "ε     :   dd  ε ",
      "θ     :        θ",
      "θ     #        θ",
      "θ     :        θ",
      " θ    :       θ ",
      "  θθθεθθθθεθθθ  "
    ],
    [
      "  θθθεθθθθεθθθ  ",
      " θ    :L      θ ",
      "θ     :⑪       θ",
      "θ  E  #        θ",
      "θ     :        θ",
      "ε     :       ε ",
      "θ::#  #       θ ",
      "θ             θ ",
      "θ             θ ",
      "θ     #       θ ",
      "ε     :   cc  ε ",
      "θ     :   dd   θ",
      "θ     #        θ",
      "θ     :        θ",
      " θ    :       θ ",
      "  θθθεθθθθεθθθ  "
    ],
    [
      "  θθθεθθθθεθθθ  ",
      " θ############θ ",
      "θ##############θ",
      "θ##############θ",
      "θ##############θ",
      "ε#############ε ",
      "θ#############θ ",
      "θ#############θ ",
      "θ#########  ##θ ",
      "θ#########  ##θ ",
      "ε#########  ##ε ",
      "θ#########cc###θ",
      "θ#########dd###θ",
      "θ#########  ###θ",
      " θ############θ ",
      "  θθθεθθθθεθθθ  "
    ],
    [
      "  οοοεοοοοεοοο  ",
      " ε############ε ",
      "ο##############ο",
      "ο##############ο",
      "ο##############ο",
      "ε#############ε ",
      "ο#############ο ",
      "ο#############ο ",
      "ο#########  ##ο ",
      "ο#########  ##ο ",
      "ε#########  ##ε ",
      "ο#########  ###ο",
      "ο#########cc###ο",
      "ο#########dd###ο",
      " ε############ε ",
      "  οοοεοοοοεοοο  "
    ]
  ],
  "refpalette": "biohazard:furnished_facades"
}
