{
  "xsize": 16,
  "zsize": 16,
  "slices": [
    [
      "  SSSSSSSSSSSS  ",
      " ############## ",
      "S##############S",
      "S##############S",
      "S##############S",
      "S############## ",
      "S###1########## ",
      "S############## ",
      "S############## ",
      "S############## ",
      "S#########  ### ",
      "S#########  ###S",
      "S#########  ###S",
      "S#########cc###S",
      " ############## ",
      "  SSSSSSSSSSSS  "
    ],
    [
      "  οοοεοοοοεοοο  ",
      " εⓛ      ⓒⓑ   ε ",
      "ο        ①     ο",
      "ο   L         Fο",
      "ο   L          ο",
      "ε  CLF        ε ",
      "ο########    #ο ",
      "ο             ο ",
      "ο         cc  ο ",
      "ο        :dd: ο ",
      "ε        :  : ε ",
      "ο        :  :  ο",
      "ο        :  :  ο",
      "ο              ο",
      " ε Fⓗⓖ ⓜ      ε ",
      "  οοοεοοοοεοοο  "
    ],
    [
      "  θθθεθθθθεθθθ  ",
      " θ            θ ",
      "θ              θ",
      "θ   L          θ",
      "θ   L          θ",
      "ε   L         ε ",
      "θ######aa    aθ ",
      "θ             θ ",
      "θ             θ ",
      "θ         cc  θ ",
      "ε         dd  ε ",
      "θ              θ",
      "θ              θ",
      "θ              θ",
      " θ            θ ",
      "  θθθεθθθθεθθθ  "
    ],
    [
      "  θθθεθθθθεθθθ  ",
      " θ            θ ",
      "θ              θ",
      "θ   L          θ",
      "θ   L          θ",
      "ε   LE        ε ",
      "θ######aa    aθ ",
      "θ    E        θ ",
      "θ             θ ",
      "θ             θ ",
      "ε         cc  ε ",
      "θ         dd   θ",
      "θ              θ",
      "θ              θ",
      " θ            θ ",
      "  θθθεθθθθεθθθ  "
    ],
    [
      "  θθθεθθθθεθθθ  ",
      " θ############θ ",
      "θ##############θ",
      "θ##############θ",
      "θ##############θ",
      "ε#############ε ",
      "θ#############θ ",
      "θ#############θ ",
      "θ#########  ##θ ",
      "θ#########  ##θ ",
      "ε#########  ##ε ",
      "θ#########cc###θ",
      "θ#########dd###θ",
      "θ#########  ###θ",
      " θ############θ ",
      "  θθθεθθθθεθθθ  "
    ],
    [
      "  οοοεοοοοεοοο  ",
      " ε############ε ",
      "ο##############ο",
      "ο##############ο",
      "ο##############ο",
      "ε#############ε ",
      "ο#############ο ",
      "ο#############ο ",
      "ο#########  ##ο ",
      "ο#########  ##ο ",
      "ε#########  ##ε ",
      "ο#########  ###ο",
      "ο#########cc###ο",
      "ο#########dd###ο",
      " ε############ε ",
      "  οοοεοοοοεοοο  "
    ]
  ],
  "refpalette": "biohazard:furnished_facades"
}
