{
  "xsize": 16,
  "zsize": 16,
  "slices": [
    [
      "################",
      "################",
      "################",
      "################",
      "################",
      "################",
      "################",
      "################",
      "################",
      "#######l########",
      "################",
      "################",
      "################",
      "################",
      "################",
      "################"
    ],
    [
      "#aa@aaaaaaaa@aa#",
      "a              a",
      "a              a",
      "@              @",
      "a      ②       a",
      "a      ③       a",
      "a    ##①##     a",
      "a    #   ######a",
      "a              a",
      "a    # l #     a",
      "a    #####     a",
      "a      F#      a",
      "@       #      @",
      "a              a",
      "a       #⑥⑦    a",
      "#aa@aaaaaaaa@aa#"
    ],
    [
      "#aa@aaaaaaaa@aa#",
      "a              a",
      "a              a",
      "@              @",
      "a              a",
      "a              a",
      "a    ## ##     a",
      "a    #   ###:##a",
      "a              a",
      "a    # l #     a",
      "a    #####     a",
      "a       #      a",
      "@       #      @",
      "a              a",
      "a       #      a",
      "#aa@aaaaaaaa@aa#"
    ],
    [
      "#aa@aaaaaaaa@aa#",
      "a              a",
      "a              a",
      "@              @",
      "a              a",
      "a              a",
      "a    #####     a",
      "a    #   ######a",
      "a    #   # E E a",
      "a    # l #     a",
      "a    #####     a",
      "a       #      a",
      "@       #      @",
      "a       #      a",
      "a       #      a",
      "#aa@aaaaaaaa@aa#"
    ],
    [
      "################",
      "################",
      "################",
      "################",
      "################",
      "################",
      "################",
      "################",
      "################",
      "#######l########",
      "################",
      "################",
      "################",
      "################",
      "################",
      "################"
    ],
    [
      "################",
      "################",
      "################",
      "################",
      "################",
      "################",
      "################",
      "################",
      "################",
      "#######l########",
      "################",
      "################",
      "################",
      "################",
      "################",
      "################"
    ]
  ],
  "refpalette": "biohazard:handcrafted_furnishings"
}
