{
  "xsize": 16,
  "zsize": 16,
  "slices": [
    [
      " ############## ",
      "################",
      "################",
      "################",
      "################",
      "################",
      "################",
      "################",
      "################",
      "####X1X#X1  ####",
      "##########  ####",
      "##########  ####",
      "##########cc####",
      "################",
      "################",
      " ############## "
    ],
    [
      " ιδδδιδδδδιδδδι ",
      "ι⑮⑫⑮LL         ι",
      "δ              δ",
      "δ              δ",
      "δ              δ",
      "ι              ι",
      "δ    ## #      δ",
      "δ   ②#   #cc   δ",
      "δ   ③#   :dd:  δ",
      "δ   ①X   :  :  δ",
      "ι  QQ####:  :  ι",
      "δ      CF:  :  δ",
      "δ        :  :  δ",
      "δ              δ",
      "ιLLδδ  δ       ι",
      " ιδρρρρρδδιδδδι "
    ],
    [
      " ιηηηιηηηηιηηηι ",
      "ι   e          ι",
      "η              η",
      "η              η",
      "η              η",
      "ι              ι",
      "η    ## #      η",
      "η    #   #     η",
      "η    #   #cc   η",
      "η    #   #dd   η",
      "ι  QQ#####     ι",
      "η              η",
      "η              η",
      "η              η",
      "ι  ηη  η       ι",
      " ιη     ηηιηηηι "
    ],
    [
      " ιηηηιηηηηιηηηι ",
      "ι              ι",
      "η              η",
      "η              η",
      "η              η",
      "ι              ι",
      "η    ####      η",
      "η    #  E#     η",
      "η    #   #     η",
      "η    #   #cc   η",
      "ι  QQ#####dd   ι",
      "η              η",
      "η              η",
      "η              η",
      "ι  ηηιηη       ι",
      " ιη     ηηιηηηι "
    ],
    [
      " ιηηηιηηηηιηηηι ",
      "ι##############ι",
      "η##############η",
      "η##############η",
      "η##############η",
      "ι##############ι",
      "η##############η",
      "η#########  ###η",
      "η#########  ###η",
      "η###### ##  ###η",
      "ι#########cc###ι",
      "η#########dd###η",
      "η#########  ###η",
      "η##############η",
      "ι##ηηιηη#######ι",
      " ιη     ηηιηηηι "
    ],
    [
      " ιδδδιδδδδιδδδι ",
      "ι##############ι",
      "δ##############δ",
      "δ##############δ",
      "δ##############δ",
      "ι##############ι",
      "δ##############δ",
      "δ#########  ###δ",
      "δ#########  ###δ",
      "δ###### ##  ###δ",
      "ι#########  ###ι",
      "δ#########cc###δ",
      "δ#########dd###δ",
      "δ##############δ",
      "ι##δδιδδ#######ι",
      " ιδ     δδιδδδι "
    ]
  ],
  "refpalette": "biohazard:furnished_facades"
}
