{
  "xsize": 16,
  "zsize": 16,
  "slices": [
    [
      "################",
      "################",
      "################",
      "################",
      "################",
      "################",
      "################",
      "################",
      "################",
      "##########  ####",
      "##########  ####",
      "##########  ####",
      "##########cc####",
      "################",
      "################",
      "################"
    ],
    [
      "#aa@aaaaaaaa@aa#",
      "a  # ⑨ⓓ     #  a",
      "a  #F⑧      #  a",
      "@  #F      L#  @",
      "a  #D      L#  a",
      "a  #           a",
      "a              a",
      "a  #      cc#  a",
      "a  #     :dd:  a",
      "a  #     :  :  a",
      "a  ######:  :  a",
      "a        :  :  a",
      "@        :  :  @",
      "a              a",
      "a⑥⑦   F        a",
      "#aa@aaaaaaaa@aa#"
    ],
    [
      "#aa@aaaaaaaa@aa#",
      "a  #        #  a",
      "a  #        #  a",
      "@  #       L#  @",
      "a  #*      L#  a",
      "a  #           a",
      "a              a",
      "a  #        #  a",
      "a  #      cc#  a",
      "a  #      dd#  a",
      "a  #######  #  a",
      "a              a",
      "@              @",
      "a              a",
      "a              a",
      "#aa@aaaaaaaa@aa#"
    ],
    [
      "#aa@aaaaaaaa@aa#",
      "a  #        #  a",
      "a  #        #  a",
      "@  #        #  @",
      "a  #        #  a",
      "a  #           a",
      "a  #           a",
      "a  #        #  a",
      "a  #        #  a",
      "a  #      cc#  a",
      "a  #######dd#  a",
      "a       E      a",
      "@              @",
      "a              a",
      "a              a",
      "#aa@aaaaaaaa@aa#"
    ],
    [
      "################",
      "################",
      "################",
      "################",
      "################",
      "################",
      "################",
      "##########  ####",
      "##########  ####",
      "####### ##  ####",
      "##########cc####",
      "##########dd####",
      "##########  ####",
      "################",
      "################",
      "################"
    ],
    [
      "################",
      "################",
      "################",
      "################",
      "################",
      "################",
      "################",
      "##########  ####",
      "##########  ####",
      "####### ##  ####",
      "##########  ####",
      "##########cc####",
      "##########dd####",
      "################",
      "################",
      "################"
    ]
  ],
  "refpalette": "biohazard:handcrafted_furnishings"
}
