{
    "xsize":  16,
    "zsize":  16,
    "slices":  [
                   [
                       "################",
                       "################",
                       "################",
                       "################",
                       "################",
                       "################",
                       "################",
                       "################",
                       "################",
                       "#######l########",
                       "####X1X#X1X#####",
                       "#####X###X######",
                       "################",
                       "################",
                       "################",
                       "################"
                   ],
                   [
                       "#aa@aaaaaaaa@aa#",
                       "a      #       a",
                       "a      #F      a",
                       "@              @",
                       "a      #       a",
                       "a     L#       a",
                       "au   #####    Da",
                       "ars  #   #     a",
                       "a t j#   #F    a",
                       "a      l #     a",
                       "a########X     a",
                       "a       :     Ca",
                       "@       :     z@",
                       "a   C       CCAa",
                       "a              a",
                       "#aa@aaaaaaaa@aa#"
                   ],
                   [
                       "#aa@aaaaaaaa@aa#",
                       "a      #       a",
                       "a      #       a",
                       "@              @",
                       "a      #       a",
                       "a     L#       a",
                       "a    #####     a",
                       "a    #   #     a",
                       "a    #   #     a",
                       "a      l #     a",
                       "a#########     a",
                       "a       :      a",
                       "@       :      @",
                       "a              a",
                       "a              a",
                       "#aa@aaaaaaaa@aa#"
                   ],
                   [
                       "#aa@aaaaaaaa@aa#",
                       "a      #       a",
                       "a      #       a",
                       "@      #       @",
                       "a      #       a",
                       "a     L#       a",
                       "a    #####     a",
                       "a    #   #     a",
                       "a    #   #E    a",
                       "a    # l #     a",
                       "a#########     a",
                       "a    E  :      a",
                       "@       :      @",
                       "a              a",
                       "a              a",
                       "#aa@aaaaaaaa@aa#"
                   ],
                   [
                       "################",
                       "################",
                       "################",
                       "################",
                       "################",
                       "################",
                       "################",
                       "################",
                       "################",
                       "#######l########",
                       "################",
                       "################",
                       "################",
                       "################",
                       "################",
                       "################"
                   ],
                   [
                       "################",
                       "################",
                       "################",
                       "################",
                       "################",
                       "################",
                       "################",
                       "################",
                       "################",
                       "#######l########",
                       "################",
                       "################",
                       "################",
                       "################",
                       "################",
                       "################"
                   ]
               ],
    "refpalette":  "biohazard:handcrafted_furnishings"
}
