{
  "xsize": 16,
  "zsize": 16,
  "slices": [
    [
      " ############## ",
      "################",
      "################",
      "################",
      "################",
      "################",
      "################",
      "################",
      "################",
      "##########  ####",
      "####X1X#X1  ####",
      "#####X###X  ####",
      "##########cc####",
      "################",
      "################",
      " ############## "
    ],
    [
      " ιδδδιδδδδιδδδι ",
      "ι⑥     #   ⑨ⓓ  ι",
      "δ      #F  ⑧   δ",
      "δ              δ",
      "δ      #       δ",
      "ιL    L#       ι",
      "δL   ####      δ",
      "δLL  #FFF#cc   δ",
      "δ    #   :dd:  δ",
      "δⓜⓓⓜ     :  :  δ",
      "ι########:  :  ι",
      "δ       ::  :  δ",
      "δ       ::  :  δ",
      "δ   C          δ",
      "ι  δδ  δ⑦      ι",
      " ιδρρρρρδδιδδδι "
    ],
    [
      " ιηηηιηηηηιηηηι ",
      "ι      #       ι",
      "η      #       η",
      "η              η",
      "η      #       η",
      "ι     L#       ι",
      "ηe   ####      η",
      "η    #   #     η",
      "η    #   #cc   η",
      "η        #dd   η",
      "ι#########     ι",
      "η       :      η",
      "η       :      η",
      "η              η",
      "ι  ηη  η       ι",
      " ιη     ηηιηηηι "
    ],
    [
      " ιηηηιηηηηιηηηι ",
      "ι      #       ι",
      "η      #       η",
      "η      #       η",
      "η      #       η",
      "ι     L#       ι",
      "η    ####      η",
      "η    # E #     η",
      "η    #   #     η",
      "η    #   #cc   η",
      "ι#########dd   ι",
      "η    E  :      η",
      "η       :      η",
      "η              η",
      "ι  ηηιηη       ι",
      " ιη     ηηιηηηι "
    ],
    [
      " ιηηηιηηηηιηηηι ",
      "ι##############ι",
      "η##############η",
      "η##############η",
      "η##############η",
      "ι##############ι",
      "η##############η",
      "η#########  ###η",
      "η#########  ###η",
      "η###### ##  ###η",
      "ι#########cc###ι",
      "η#########dd###η",
      "η#########  ###η",
      "η##############η",
      "ι##ηηιηη#######ι",
      " ιη     ηηιηηηι "
    ],
    [
      " ιδδδιδδδδιδδδι ",
      "ι##############ι",
      "δ##############δ",
      "δ##############δ",
      "δ##############δ",
      "ι##############ι",
      "δ##############δ",
      "δ#########  ###δ",
      "δ#########  ###δ",
      "δ###### ##  ###δ",
      "ι#########  ###ι",
      "δ#########cc###δ",
      "δ#########dd###δ",
      "δ##############δ",
      "ι##δδιδδ#######ι",
      " ιδ     δδιδδδι "
    ]
  ],
  "refpalette": "biohazard:furnished_facades"
}
