{
  "xsize": 16,
  "zsize": 16,
  "slices": [
    [
      "################",
      "################",
      "################",
      "################",
      "################",
      "################",
      "################",
      "################",
      "################",
      "##########  ####",
      "####X1X#X1  ####",
      "#####X###X  ####",
      "##########cc####",
      "################",
      "################",
      "################"
    ],
    [
      "#aa@aaaaaaaa@aa#",
      "a      #   ⑨ⓓ  a",
      "a      #F  ⑧   a",
      "@              @",
      "a      #       a",
      "a     L#       a",
      "a    ####      a",
      "a    #   #cc   a",
      "a    #   :dd:  a",
      "a        :  :  a",
      "a########:  :  a",
      "a       ::  :  a",
      "@       ::  :  @",
      "a   C          a",
      "a      ⑥⑦      a",
      "#aa@aaaaaaaa@aa#"
    ],
    [
      "#aa@aaaaaaaa@aa#",
      "a      #       a",
      "a      #       a",
      "@              @",
      "a      #       a",
      "a     L#       a",
      "a    ####      a",
      "a    #   #     a",
      "a    #   #cc   a",
      "a        #dd   a",
      "a#########     a",
      "a       :      a",
      "@       :      @",
      "a              a",
      "a              a",
      "#aa@aaaaaaaa@aa#"
    ],
    [
      "#aa@aaaaaaaa@aa#",
      "a      #       a",
      "a      #       a",
      "@      #       @",
      "a      #       a",
      "a     L#       a",
      "a    ####      a",
      "a    #   #     a",
      "a    #   #     a",
      "a    #   #cc   a",
      "a#########dd   a",
      "a    E  :      a",
      "@       :      @",
      "a              a",
      "a              a",
      "#aa@aaaaaaaa@aa#"
    ],
    [
      "################",
      "################",
      "################",
      "################",
      "################",
      "################",
      "################",
      "##########  ####",
      "##########  ####",
      "####### ##  ####",
      "##########cc####",
      "##########dd####",
      "##########  ####",
      "################",
      "################",
      "################"
    ],
    [
      "################",
      "################",
      "################",
      "################",
      "################",
      "################",
      "################",
      "##########  ####",
      "##########  ####",
      "####### ##  ####",
      "##########  ####",
      "##########cc####",
      "##########dd####",
      "################",
      "################",
      "################"
    ]
  ],
  "refpalette": "biohazard:handcrafted_furnishings"
}
