{
    "xsize":  16,
    "zsize":  16,
    "slices":  [
                   [
                       "################",
                       "################",
                       "################",
                       "################",
                       "################",
                       "################",
                       "################",
                       "################",
                       "################",
                       "#######l########",
                       "################",
                       "################",
                       "################",
                       "################",
                       "################",
                       "################"
                   ],
                   [
                       "#aa@aaaaaaaa@aa#",
                       "a              a",
                       "a              a",
                       "@              @",
                       "a              a",
                       "a              a",
                       "au   ## ##    Da",
                       "ars  #   #     a",
                       "a t j#   #     a",
                       "a    # l #     a",
                       "a# ############a",
                       "a     FFF     Ca",
                       "@             z@",
                       "a           CCAa",
                       "a              a",
                       "#aa@aaaaaaaa@aa#"
                   ],
                   [
                       "#aa@aaaaaaaa@aa#",
                       "a              a",
                       "a              a",
                       "@              @",
                       "a              a",
                       "a              a",
                       "a    ## ##     a",
                       "a    #   #     a",
                       "a    #   #     a",
                       "a    # l #     a",
                       "a# ########aaa#a",
                       "a              a",
                       "@              @",
                       "a              a",
                       "a              a",
                       "#aa@aaaaaaaa@aa#"
                   ],
                   [
                       "#aa@aaaaaaaa@aa#",
                       "a              a",
                       "a              a",
                       "@              @",
                       "a              a",
                       "a              a",
                       "a    #####     a",
                       "a    #  E#     a",
                       "a    #   #     a",
                       "a    # l #     a",
                       "a##############a",
                       "a              a",
                       "@              @",
                       "a              a",
                       "a              a",
                       "#aa@aaaaaaaa@aa#"
                   ],
                   [
                       "################",
                       "################",
                       "###1############",
                       "################",
                       "############1###",
                       "################",
                       "################",
                       "################",
                       "################",
                       "#######l########",
                       "################",
                       "################",
                       "################",
                       "################",
                       "################",
                       "################"
                   ],
                   [
                       "################",
                       "################",
                       "################",
                       "################",
                       "################",
                       "################",
                       "################",
                       "################",
                       "################",
                       "#######l########",
                       "################",
                       "################",
                       "################",
                       "################",
                       "################",
                       "################"
                   ]
               ],
    "refpalette":  "biohazard:handcrafted_furnishings"
}
