{
  "xsize": 16,
  "zsize": 16,
  "slices": [
    [
      "################",
      "################",
      "################",
      "################",
      "################",
      "################",
      "################",
      "################",
      "################",
      "##########  ####",
      "##########  ####",
      "##########  ####",
      "##########cc####",
      "################",
      "################",
      "################"
    ],
    [
      "#aa@aaaaaaaa@aa#",
      "a      ②     ⓓⓕa",
      "a      ③      ⓔa",
      "@      ①       @",
      "a              a",
      "a              a",
      "a    ## #      a",
      "a    #   #cc   a",
      "a    #   :dd:  a",
      "a    #   :  :  a",
      "a# ######:  :##a",
      "a    ⓓ   :  :  a",
      "@        :  :  @",
      "a              a",
      "a ⑥⑦⑦⑥FFFⓑⓑ    a",
      "#aa@aaaaaaaa@aa#"
    ],
    [
      "#aa@aaaaaaaa@aa#",
      "a              a",
      "a              a",
      "@              @",
      "a              a",
      "a              a",
      "a    ## #      a",
      "a    #   #     a",
      "a    #   #cc   a",
      "a    #   #dd   a",
      "a# #######  aa#a",
      "a              a",
      "@              @",
      "a              a",
      "a   ⓑⓑ         a",
      "#aa@aaaaaaaa@aa#"
    ],
    [
      "#aa@aaaaaaaa@aa#",
      "a              a",
      "a              a",
      "@              @",
      "a              a",
      "a              a",
      "a    ####      a",
      "a    #  E#     a",
      "a    #   #     a",
      "a    #   #cc   a",
      "a#########dd###a",
      "a       ⓓ      a",
      "@              @",
      "a              a",
      "a     ⓓⓑ       a",
      "#aa@aaaaaaaa@aa#"
    ],
    [
      "################",
      "################",
      "###1############",
      "################",
      "############1###",
      "################",
      "################",
      "##########  ####",
      "##########  ####",
      "####### ##  ####",
      "##########cc####",
      "##########dd####",
      "##########  ####",
      "################",
      "################",
      "################"
    ],
    [
      "################",
      "################",
      "################",
      "################",
      "################",
      "################",
      "################",
      "##########  ####",
      "##########  ####",
      "####### ##  ####",
      "##########  ####",
      "##########cc####",
      "##########dd####",
      "################",
      "################",
      "################"
    ]
  ],
  "refpalette": "biohazard:handcrafted_furnishings"
}
