{
  "xsize": 16,
  "zsize": 16,
  "slices": [
    [
      " ############## ",
      "################",
      "################",
      "################",
      "################",
      "################",
      "################",
      "################",
      "################",
      "##########  ####",
      "##########  ####",
      "##########  ####",
      "##########cc####",
      "################",
      "################",
      " ############## "
    ],
    [
      " ιδδδιδδδδιδδδι ",
      "ι⑮⑫⑮  ⑥⑦  ②    ι",
      "δ         ③    δ",
      "δ         ①    δ",
      "δ              δ",
      "ι              ι",
      "δ    ## #      δ",
      "δ    #  L#cc###δ",
      "δ       L:dd:  δ",
      "δ    #LLL:  :  δ",
      "ι    ####:  :  ι",
      "δ      F#:  :  δ",
      "δ       #:  :  δ",
      "δ              δ",
      "ι  δδ  δ#      ι",
      " ιδρρρρρδδιδδδι "
    ],
    [
      " ιηηηιηηηηιηηηι ",
      "ι              ι",
      "η              η",
      "η              η",
      "η              η",
      "ι              ι",
      "η    ## #      η",
      "η    #  e#  :##η",
      "η       L cc   η",
      "η    #L⑥L#dd   η",
      "ι    #####     ι",
      "η       #      η",
      "η       #      η",
      "η              η",
      "ι  ηη  η#      ι",
      " ιη     ηηιηηηι "
    ],
    [
      " ιηηηιηηηηιηηηι ",
      "ι              ι",
      "η              η",
      "η              η",
      "η              η",
      "ι              ι",
      "η    ####      η",
      "η    #   #  ###η",
      "η    #  L#   E η",
      "η    #LLL#cc   η",
      "ι    #####dd   ι",
      "η       #      η",
      "η       #      η",
      "η       #      η",
      "ι  ηηιηη#      ι",
      " ιη     ηηιηηηι "
    ],
    [
      " ιηηηιηηηηιηηηι ",
      "ι##############ι",
      "η##############η",
      "η##############η",
      "η##############η",
      "ι##############ι",
      "η##############η",
      "η#########  ###η",
      "η#########  ###η",
      "η###### ##  ###η",
      "ι#########cc###ι",
      "η#########dd###η",
      "η#########  ###η",
      "η##############η",
      "ι##ηηιηη#######ι",
      " ιη     ηηιηηηι "
    ],
    [
      " ιδδδιδδδδιδδδι ",
      "ι##############ι",
      "δ##############δ",
      "δ##############δ",
      "δ##############δ",
      "ι##############ι",
      "δ##############δ",
      "δ#########  ###δ",
      "δ#########  ###δ",
      "δ###### ##  ###δ",
      "ι#########  ###ι",
      "δ#########cc###δ",
      "δ#########dd###δ",
      "δ##############δ",
      "ι##δδιδδ#######ι",
      " ιδ     δδιδδδι "
    ]
  ],
  "refpalette": "biohazard:furnished_facades"
}
