{
  "xsize": 16,
  "zsize": 16,
  "slices": [
    [
      "################",
      "################",
      "################",
      "################",
      "################",
      "################",
      "################",
      "################",
      "################",
      "##########  ####",
      "####1#####  ####",
      "##########  ####",
      "##########cc####",
      "################",
      "################",
      "################"
    ],
    [
      "#aa@aaaaaaaa@aa#",
      "aⓓ⑨F      QQQⓑⓒa",
      "a ⑧          ① a",
      "@              @",
      "a              a",
      "a             Fa",
      "a              a",
      "a         cc   a",
      "a        :dd:  a",
      "a    ⓑL  :  :  a",
      "a########:  : #a",
      "a        :  :  a",
      "@        :  :  @",
      "a              a",
      "a              a",
      "#aa@aaaaaaaa@aa#"
    ],
    [
      "#aa@aaaaaaaa@aa#",
      "a         **   a",
      "a              a",
      "@              @",
      "a              a",
      "a              a",
      "a              a",
      "a              a",
      "a         cc   a",
      "a     ⓑ ⓑ dd   a",
      "a#::######    #a",
      "a              a",
      "@              @",
      "a              a",
      "a              a",
      "#aa@aaaaaaaa@aa#"
    ],
    [
      "#aa@aaaaaaaa@aa#",
      "a              a",
      "a              a",
      "@              @",
      "a              a",
      "a              a",
      "a              a",
      "a              a",
      "a              a",
      "a    E  ⓑ cc   a",
      "a#########dd###a",
      "a    E         a",
      "@              @",
      "a              a",
      "a              a",
      "#aa@aaaaaaaa@aa#"
    ],
    [
      "################",
      "################",
      "################",
      "################",
      "################",
      "################",
      "################",
      "##########  ####",
      "##########  ####",
      "####### ##  ####",
      "##########cc####",
      "##########dd####",
      "##########  ####",
      "################",
      "################",
      "################"
    ],
    [
      "################",
      "################",
      "################",
      "################",
      "################",
      "################",
      "################",
      "##########  ####",
      "##########  ####",
      "####### ##  ####",
      "##########  ####",
      "##########cc####",
      "##########dd####",
      "################",
      "################",
      "################"
    ]
  ],
  "refpalette": "biohazard:handcrafted_furnishings"
}
