{
    "xsize":  16,
    "zsize":  16,
    "slices":  [
                   [
                       "################",
                       "################",
                       "################",
                       "################",
                       "################",
                       "################",
                       "################",
                       "################",
                       "################",
                       "#######l########",
                       "################",
                       "################",
                       "################",
                       "################",
                       "################",
                       "################"
                   ],
                   [
                       "#aa@aaaaaaaa@aa#",
                       "a≈WWWW≈W≈WWW≈WWa",
                       "aW≈W≈WW≈WWW≈W≈Wa",
                       "@WW≈W≈WW≈W≈W≈WW@",
                       "aW≈W≈W≈WW≈WWW≈Wa",
                       "aaaaaaaaaaaaaaaa",
                       "au            Da",
                       "ars            a",
                       "aLt j          a",
                       "aF     l       a",
                       "aF    ###::::::a",
                       "a      :      Ca",
                       "@      :      z@",
                       "a      :    CCAa",
                       "a      :       a",
                       "#aa@aaaaaaaa@aa#"
                   ],
                   [
                       "#aa@aaaaaaaa@aa#",
                       "aWWWWWWWWWWWWWWa",
                       "aWWWWWWWWWWWWWWa",
                       "@WWWWWWWWWWWWWW@",
                       "aWWWWWWWWWWWWWWa",
                       "aaaaaaaaaaaaaaaa",
                       "a              a",
                       "a              a",
                       "aL             a",
                       "a      l       a",
                       "a     ###::::::a",
                       "a      :       a",
                       "@      :       @",
                       "a      :       a",
                       "a      :       a",
                       "#aa@aaaaaaaa@aa#"
                   ],
                   [
                       "#aa@aaaaaaaa@aa#",
                       "aWWWWWWWWWWWWWWa",
                       "aWWWWWWWWWWWWWWa",
                       "@WWWWWWWWWWWWWW@",
                       "aWWWWWWWWWWWWWWa",
                       "aaaaaaaaaaaaaaaa",
                       "a              a",
                       "a              a",
                       "aL             a",
                       "a      l       a",
                       "a     ###::::::a",
                       "a      :       a",
                       "@      :   E   @",
                       "a      :       a",
                       "a      :       a",
                       "#aa@aaaaaaaa@aa#"
                   ],
                   [
                       "################",
                       "################",
                       "################",
                       "################",
                       "################",
                       "################",
                       "################",
                       "################",
                       "################",
                       "#######l########",
                       "################",
                       "################",
                       "##1#1###########",
                       "################",
                       "################",
                       "################"
                   ],
                   [
                       "################",
                       "################",
                       "################",
                       "################",
                       "################",
                       "################",
                       "################",
                       "################",
                       "################",
                       "#######l########",
                       "################",
                       "################",
                       "################",
                       "################",
                       "################",
                       "################"
                   ]
               ],
    "refpalette":  "biohazard:handcrafted_furnishings"
}
