{
  "xsize": 16,
  "zsize": 16,
  "slices": [
    [
      "################",
      "################",
      "################",
      "################",
      "################",
      "################",
      "################",
      "################",
      "################",
      "##########  ####",
      "##########  ####",
      "##########  ####",
      "##########cc####",
      "################",
      "################",
      "################"
    ],
    [
      "#aa@aaaaaaaa@aa#",
      "a⑮⑫⑮      ②    a",
      "a         ③    a",
      "@         ①    @",
      "a              a",
      "a              a",
      "a    ## #      a",
      "a    #   #cc###a",
      "a        :dd:  a",
      "a    #   :  :  a",
      "a    ####:  :  a",
      "a      F#:  :  a",
      "@       #:  :  @",
      "a              a",
      "a       #⑥⑦    a",
      "#aa@aaaaaaaa@aa#"
    ],
    [
      "#aa@aaaaaaaa@aa#",
      "a              a",
      "a              a",
      "@              @",
      "a              a",
      "a              a",
      "a    ## #      a",
      "a    #   #  :##a",
      "a         cc   a",
      "a    #   #dd   a",
      "a    #####     a",
      "a       #      a",
      "@       #      @",
      "a              a",
      "a       #      a",
      "#aa@aaaaaaaa@aa#"
    ],
    [
      "#aa@aaaaaaaa@aa#",
      "a              a",
      "a              a",
      "@              @",
      "a              a",
      "a              a",
      "a    ####      a",
      "a    #   #  ###a",
      "a    #   #   E a",
      "a    #   #cc   a",
      "a    #####dd   a",
      "a       #      a",
      "@       #      @",
      "a       #      a",
      "a       #      a",
      "#aa@aaaaaaaa@aa#"
    ],
    [
      "################",
      "################",
      "################",
      "################",
      "################",
      "################",
      "################",
      "##########  ####",
      "##########  ####",
      "####### ##  ####",
      "##########cc####",
      "##########dd####",
      "##########  ####",
      "################",
      "################",
      "################"
    ],
    [
      "################",
      "################",
      "################",
      "################",
      "################",
      "################",
      "################",
      "##########  ####",
      "##########  ####",
      "####### ##  ####",
      "##########  ####",
      "##########cc####",
      "##########dd####",
      "################",
      "################",
      "################"
    ]
  ],
  "refpalette": "biohazard:handcrafted_furnishings"
}
