{
    "xsize":  16,
    "zsize":  16,
    "slices":  [
                   [
                       "################",
                       "################",
                       "################",
                       "################",
                       "################",
                       "################",
                       "################",
                       "################",
                       "################",
                       "####X1XlX1X#####",
                       "################",
                       "################",
                       "################",
                       "################",
                       "################",
                       "################"
                   ],
                   [
                       "#aa@aaaaaaaa@aa#",
                       "a   LL         a",
                       "a              a",
                       "@              @",
                       "a              a",
                       "a              a",
                       "au   ## ##    Da",
                       "ars  #   #     a",
                       "a t j#   #     a",
                       "a    X l X     a",
                       "a  QQ#####QQ   a",
                       "a      CF     Ca",
                       "@             z@",
                       "a           CCAa",
                       "a              a",
                       "#aa@aaaaaaaa@aa#"
                   ],
                   [
                       "#aa@aaaaaaaa@aa#",
                       "a   LL         a",
                       "a              a",
                       "@              @",
                       "a              a",
                       "a              a",
                       "a    ## ##     a",
                       "a    #   #     a",
                       "a    #   #     a",
                       "a    # l #     a",
                       "a  QQ#####QQ   a",
                       "a              a",
                       "@              @",
                       "a              a",
                       "a              a",
                       "#aa@aaaaaaaa@aa#"
                   ],
                   [
                       "#aa@aaaaaaaa@aa#",
                       "a              a",
                       "a              a",
                       "@              @",
                       "a              a",
                       "a              a",
                       "a    #####     a",
                       "a    #  E#     a",
                       "a    #   #     a",
                       "a    # l #     a",
                       "a  QQ#####QQ   a",
                       "a              a",
                       "@              @",
                       "a              a",
                       "a              a",
                       "#aa@aaaaaaaa@aa#"
                   ],
                   [
                       "################",
                       "################",
                       "################",
                       "################",
                       "################",
                       "################",
                       "################",
                       "################",
                       "################",
                       "#######l########",
                       "################",
                       "################",
                       "################",
                       "################",
                       "################",
                       "################"
                   ],
                   [
                       "################",
                       "################",
                       "################",
                       "################",
                       "################",
                       "################",
                       "################",
                       "################",
                       "################",
                       "#######l########",
                       "################",
                       "################",
                       "################",
                       "################",
                       "################",
                       "################"
                   ]
               ],
    "refpalette":  "biohazard:handcrafted_furnishings"
}
