{
    "xsize":  16,
    "zsize":  16,
    "slices":  [
                   [
                       "################",
                       "################",
                       "################",
                       "################",
                       "################",
                       "################",
                       "################",
                       "################",
                       "################",
                       "#######l########",
                       "################",
                       "################",
                       "################",
                       "################",
                       "################",
                       "################"
                   ],
                   [
                       "#aa@aaaaaaaa@aa#",
                       "a      #       a",
                       "a      #       a",
                       "@              @",
                       "a      #       a",
                       "a      #       a",
                       "au   #####    Da",
                       "ars  #   #     a",
                       "a t j#   #L    a",
                       "a      l #L    a",
                       "a#########     a",
                       "a    F        Ca",
                       "@             z@",
                       "a           CCAa",
                       "a              a",
                       "#aa@aaaaaaaa@aa#"
                   ],
                   [
                       "#aa@aaaaaaaa@aa#",
                       "a      #       a",
                       "a      #       a",
                       "@              @",
                       "a      #       a",
                       "a      #       a",
                       "a    #####     a",
                       "a    #   #     a",
                       "a    #   #L    a",
                       "a      l #L    a",
                       "a#########     a",
                       "a              a",
                       "@              @",
                       "a              a",
                       "a              a",
                       "#aa@aaaaaaaa@aa#"
                   ],
                   [
                       "#aa@aaaaaaaa@aa#",
                       "a      #       a",
                       "a      #       a",
                       "@      #       @",
                       "a      #       a",
                       "a      #       a",
                       "a    #####     a",
                       "a    # E #     a",
                       "a    #   #     a",
                       "a    # l #     a",
                       "a#########     a",
                       "a              a",
                       "@              @",
                       "a              a",
                       "a              a",
                       "#aa@aaaaaaaa@aa#"
                   ],
                   [
                       "################",
                       "################",
                       "################",
                       "################",
                       "################",
                       "################",
                       "################",
                       "################",
                       "################",
                       "#######l########",
                       "################",
                       "################",
                       "################",
                       "################",
                       "################",
                       "################"
                   ],
                   [
                       "################",
                       "################",
                       "################",
                       "################",
                       "################",
                       "################",
                       "################",
                       "################",
                       "################",
                       "#######l########",
                       "################",
                       "################",
                       "################",
                       "################",
                       "################",
                       "################"
                   ]
               ],
    "refpalette":  "biohazard:handcrafted_furnishings"
}
