{
    "xsize":  16,
    "zsize":  16,
    "slices":  [
                   [
                       "################",
                       "################",
                       "################",
                       "################",
                       "################",
                       "################",
                       "################",
                       "################",
                       "################",
                       "#######l########",
                       "##########1#####",
                       "################",
                       "################",
                       "################",
                       "################",
                       "################"
                   ],
                   [
                       "#aa@aaaaaaaa@aa#",
                       "a  #        #  a",
                       "a  #F       #  a",
                       "@  #F      L#  @",
                       "a  #D      L#  a",
                       "a  #        #  a",
                       "au            Da",
                       "ars#        #  a",
                       "a t#j       #  a",
                       "a  #   l    #  a",
                       "a  ##########  a",
                       "a             Ca",
                       "@             z@",
                       "a           CCAa",
                       "a     F        a",
                       "#aa@aaaaaaaa@aa#"
                   ],
                   [
                       "#aa@aaaaaaaa@aa#",
                       "a  #        #  a",
                       "a  #        #  a",
                       "@  #       L#  @",
                       "a  #*      L#  a",
                       "a  #        #  a",
                       "a              a",
                       "a  #        #  a",
                       "a  #        #  a",
                       "a  #   l    #  a",
                       "a  ##########  a",
                       "a              a",
                       "@              @",
                       "a              a",
                       "a              a",
                       "#aa@aaaaaaaa@aa#"
                   ],
                   [
                       "#aa@aaaaaaaa@aa#",
                       "a  #        #  a",
                       "a  #        #  a",
                       "@  #        #  @",
                       "a  #        #  a",
                       "a  #        #  a",
                       "a  #        #  a",
                       "a  #        #  a",
                       "a  #        #  a",
                       "a  #   l    #  a",
                       "a  ##########  a",
                       "a       E      a",
                       "@              @",
                       "a              a",
                       "a              a",
                       "#aa@aaaaaaaa@aa#"
                   ],
                   [
                       "################",
                       "################",
                       "################",
                       "################",
                       "################",
                       "################",
                       "################",
                       "################",
                       "################",
                       "#######l########",
                       "################",
                       "################",
                       "################",
                       "################",
                       "################",
                       "################"
                   ],
                   [
                       "################",
                       "################",
                       "################",
                       "################",
                       "################",
                       "################",
                       "################",
                       "################",
                       "################",
                       "#######l########",
                       "################",
                       "################",
                       "################",
                       "################",
                       "################",
                       "################"
                   ]
               ],
    "refpalette":  "biohazard:handcrafted_furnishings"
}
