{
  "xsize": 16,
  "zsize": 16,
  "slices": [
    [
      "################",
      "################",
      "################",
      "################",
      "################",
      "################",
      "################",
      "################",
      "################",
      "##########  ####",
      "##########  ####",
      "##########  ####",
      "##########cc####",
      "################",
      "################",
      "################"
    ],
    [
      "#aa@aaaaaaaa@aa#",
      "a        ⓐⓛ    a",
      "a              a",
      "@              @",
      "a              a",
      "a      F       a",
      "a    QQQQ    ::a",
      "a    Q   Qcc ⓓⓕa",
      "a    Q   :dd: ⓔa",
      "a        :  :  a",
      "a    QQQQ:  :  a",
      "a        :  :  a",
      "@        :  :  @",
      "a              a",
      "a    ⓗⓖ        a",
      "#aa@aaaaaaaa@aa#"
    ],
    [
      "#aa@aaaaaaaa@aa#",
      "a              a",
      "a              a",
      "@              @",
      "a              a",
      "a              a",
      "a    QQQQ    ::a",
      "a    Q   Q     a",
      "a    Q   Qcc   a",
      "a         dd   a",
      "a    QQQQQ     a",
      "a              a",
      "@              @",
      "a              a",
      "a              a",
      "#aa@aaaaaaaa@aa#"
    ],
    [
      "#aa@aaaaaaaa@aa#",
      "a              a",
      "a              a",
      "@              @",
      "a              a",
      "a              a",
      "a    QQQQ    ::a",
      "a    Q   Q     a",
      "a    Q   Q     a",
      "a    Q   Qcc   a",
      "a    QQQQQdd   a",
      "a              a",
      "@              @",
      "a              a",
      "a              a",
      "#aa@aaaaaaaa@aa#"
    ],
    [
      "################",
      "################",
      "################",
      "################",
      "################",
      "################",
      "################",
      "##########  ####",
      "##########  ####",
      "####### ##  ####",
      "##########cc####",
      "##########dd####",
      "##########  ####",
      "################",
      "################",
      "################"
    ],
    [
      "################",
      "################",
      "################",
      "################",
      "################",
      "################",
      "################",
      "##########  ####",
      "##########  ####",
      "####### ##  ####",
      "##########  ####",
      "##########cc####",
      "##########dd####",
      "################",
      "################",
      "################"
    ]
  ],
  "refpalette": "biohazard:handcrafted_furnishings"
}
