{
  "xsize": 16,
  "zsize": 16,
  "slices": [
    [
      " ############## ",
      "################",
      "################",
      "################",
      "################",
      "################",
      "################",
      "################",
      "################",
      "##########  ####",
      "##########  ####",
      "##########  ####",
      "##########cc####",
      "################",
      "################",
      " ############## "
    ],
    [
      " ιδδδιδδδδιδδδι ",
      "ιLLL     ⓐⓛ    ι",
      "δ              δ",
      "δ              δ",
      "δ              δ",
      "ι      F       ι",
      "δ    QQQQ     :δ",
      "δ    QⓕⓓLQcc  ⓓδ",
      "δ    Qⓔ  :dd: Fδ",
      "δ        :  :  δ",
      "ι    QQQQ:  :  ι",
      "δ        :  :  δ",
      "δ        :  :  δ",
      "δ              δ",
      "ιⓗⓖδδ  δ       ι",
      " ιδρρρρρδδιδδδι "
    ],
    [
      " ιηηηιηηηηιηηηι ",
      "ιLeL           ι",
      "η              η",
      "η              η",
      "η              η",
      "ι              ι",
      "η    QQQQ     :η",
      "η    Q   Q     η",
      "η    Q   Qcc   η",
      "η         dd   η",
      "ι    QQQQQ     ι",
      "η              η",
      "η              η",
      "η              η",
      "ι  ηη  η       ι",
      " ιη     ηηιηηηι "
    ],
    [
      " ιηηηιηηηηιηηηι ",
      "ι              ι",
      "η              η",
      "η              η",
      "η              η",
      "ι              ι",
      "η    QQQQ     :η",
      "η    Q E Q     η",
      "η    Q   Q     η",
      "η    Q   Qcc   η",
      "ι    QQQQQdd   ι",
      "η              η",
      "η              η",
      "η              η",
      "ι  ηηιηη       ι",
      " ιη     ηηιηηηι "
    ],
    [
      " ιηηηιηηηηιηηηι ",
      "ι##############ι",
      "η##############η",
      "η##############η",
      "η##############η",
      "ι##############ι",
      "η##############η",
      "η#########  ###η",
      "η#########  ###η",
      "η###### ##  ###η",
      "ι#########cc###ι",
      "η#########dd###η",
      "η#########  ###η",
      "η##############η",
      "ι##ηηιηη#######ι",
      " ιη     ηηιηηηι "
    ],
    [
      " ιδδδιδδδδιδδδι ",
      "ι##############ι",
      "δ##############δ",
      "δ##############δ",
      "δ##############δ",
      "ι##############ι",
      "δ##############δ",
      "δ#########  ###δ",
      "δ#########  ###δ",
      "δ###### ##  ###δ",
      "ι#########  ###ι",
      "δ#########cc###δ",
      "δ#########dd###δ",
      "δ##############δ",
      "ι##δδιδδ#######ι",
      " ιδ     δδιδδδι "
    ]
  ],
  "refpalette": "biohazard:furnished_facades"
}
