{
  "xsize": 16,
  "zsize": 16,
  "slices": [
    [
      " ############## ",
      "################",
      "################",
      "################",
      "################",
      "################",
      "################",
      "################",
      "################",
      "##########  ####",
      "##########  ####",
      "##########  ####",
      "##########cc####",
      "################",
      "################",
      " ############## "
    ],
    [
      " ιδδδιδδδδιδδδι ",
      "ιⓓ⑥L⑮  ②⑫⑫⑫⑫⑫ⓓⓕι",
      "δ      ③      ⓔδ",
      "δ      ①       δ",
      "δ              δ",
      "ι              ι",
      "δ    ## #      δ",
      "δ    #L  #cc   δ",
      "δ    #L  :dd:  δ",
      "δ    #L  :  :  δ",
      "ι# ######:  :##ι",
      "δ    ⓓF  :  :  δ",
      "δ        :  :  δ",
      "δ              δ",
      "ι ⑥δδ  δF      ι",
      " ιδρρρρρδδιδδδι "
    ],
    [
      " ιηηηιηηηηιηηηι ",
      "ι              ι",
      "η              η",
      "η              η",
      "η              η",
      "ι              ι",
      "η    ## #      η",
      "η    #L  #     η",
      "η    #   #cc   η",
      "η    #L  #dd   η",
      "ι# #######  aa#ι",
      "η              η",
      "η              η",
      "η              η",
      "ι  ηη  η       ι",
      " ιη     ηηιηηηι "
    ],
    [
      " ιηηηιηηηηιηηηι ",
      "ι              ι",
      "η              η",
      "η              η",
      "η              η",
      "ι              ι",
      "η    ####      η",
      "η    #L E#     η",
      "η    #L  #     η",
      "η    #L  #cc   η",
      "ι#########dd###ι",
      "η              η",
      "η              η",
      "η              η",
      "ι  ηηιηη       ι",
      " ιη     ηηιηηηι "
    ],
    [
      " ιηηηιηηηηιηηηι ",
      "ι##############ι",
      "η##1###########η",
      "η##############η",
      "η###########1##η",
      "ι##############ι",
      "η##############η",
      "η#########  ###η",
      "η#########  ###η",
      "η###### ##  ###η",
      "ι#########cc###ι",
      "η#########dd###η",
      "η#########  ###η",
      "η##############η",
      "ι##ηηιηη#######ι",
      " ιη     ηηιηηηι "
    ],
    [
      " ιδδδιδδδδιδδδι ",
      "ι##############ι",
      "δ##############δ",
      "δ##############δ",
      "δ##############δ",
      "ι##############ι",
      "δ##############δ",
      "δ#########  ###δ",
      "δ#########  ###δ",
      "δ###### ##  ###δ",
      "ι#########  ###ι",
      "δ#########cc###δ",
      "δ#########dd###δ",
      "δ##############δ",
      "ι##δδιδδ#######ι",
      " ιδ     δδιδδδι "
    ]
  ],
  "refpalette": "biohazard:furnished_facades"
}
