{
  "xsize": 16,
  "zsize": 16,
  "slices": [
    [
      "################",
      "################",
      "################",
      "################",
      "################",
      "################",
      "################",
      "################",
      "################",
      "##########  ####",
      "##########  ####",
      "##########  ####",
      "##########cc####",
      "################",
      "################",
      "################"
    ],
    [
      "#aa@aaaaaaaa@aa#",
      "a≈WWWW≈W≈WWW≈WWa",
      "aW≈W≈WW≈WWW≈W≈Wa",
      "@WW≈W≈WW≈W≈W≈WW@",
      "aW≈W≈W≈WW≈WWW≈Wa",
      "aaaaaaaaa    aaa",
      "a              a",
      "a         cc   a",
      "aL       :dd:  a",
      "aF       :  :  a",
      "aF    ###:  :::a",
      "a ④⑱⑤  : :  :  a",
      "@      : :  :  @",
      "a      :       a",
      "a      :ⓜⓛ     a",
      "#aa@aaaaaaaa@aa#"
    ],
    [
      "#aa@aaaaaaaa@aa#",
      "aWWWWWWWWWWWWWWa",
      "aWWWWWWWWWWWWWWa",
      "@WWWWWWWWWWWWWW@",
      "aWWWWWWWWWWWWWWa",
      "aaaaaaaaa    aaa",
      "a              a",
      "a              a",
      "aL        cc   a",
      "a       ⓑⓑdd   a",
      "a     ###:  :::a",
      "a      :       a",
      "@      :       @",
      "a      :       a",
      "a      :       a",
      "#aa@aaaaaaaa@aa#"
    ],
    [
      "#aa@aaaaaaaa@aa#",
      "aWWWWWWWWWWWWWWa",
      "aWWWWWWWWWWWWWWa",
      "@WWWWWWWWWWWWWW@",
      "aWWWWWWWWWWWWWWa",
      "aaaaaaaaa    aaa",
      "a              a",
      "a              a",
      "aL             a",
      "a       ⓑⓑcc   a",
      "a     ###:dd:::a",
      "a      :       a",
      "@      :       @",
      "a      :       a",
      "a      :       a",
      "#aa@aaaaaaaa@aa#"
    ],
    [
      "################",
      "################",
      "################",
      "################",
      "################",
      "################",
      "################",
      "##########  ####",
      "##########  ####",
      "####### ##  ####",
      "##########cc####",
      "##########dd####",
      "##1#1#####  ####",
      "################",
      "################",
      "################"
    ],
    [
      "################",
      "################",
      "################",
      "################",
      "################",
      "################",
      "################",
      "##########  ####",
      "##########  ####",
      "####### ##  ####",
      "##########  ####",
      "##########cc####",
      "##########dd####",
      "################",
      "################",
      "################"
    ]
  ],
  "refpalette": "biohazard:handcrafted_furnishings"
}
