{
  "xsize": 16,
  "zsize": 16,
  "slices": [
    [
      "################",
      "################",
      "################",
      "################",
      "################",
      "####  ##########",
      "####  ##########",
      "####  ##########",
      "####cc##########",
      "################",
      "################",
      "################",
      "################",
      "################",
      "################",
      "################"
    ],
    [
      "##___######___##",
      "###   ⓐⓛⓐL######",
      "_#             #",
      "_#  cc         #",
      "_# :dd:        #",
      "## :  :        #",
      "#  :  :      ⓓⓕ#",
      "#  :  :       ⓔ#",
      "#  :  :        #",
      "#             ⓑ#",
      "##     ##      #",
      "_#    FF       #",
      "_#             #",
      "_#             #",
      "######  ⓗⓖ######",
      "##___######___##"
    ],
    [
      "##   ######   ##",
      "##a       #aaa##",
      " a            a ",
      " a            a ",
      " a  cc        a ",
      "##  dd        ##",
      "#              #",
      "#              #",
      "#              #",
      "#              #",
      "##     ##     ##",
      " a            a ",
      " a            a ",
      " a            a ",
      "##aaa#    #aaa##",
      "##   ######   ##"
    ],
    [
      "##   ######   ##",
      "##a      L#aaa##",
      " a            a ",
      " a            a ",
      " a            a ",
      "##  cc        ##",
      "#   dd         #",
      "#              #",
      "#              #",
      "#              #",
      "##     ##     ##",
      " a            a ",
      " a            a ",
      " a            a ",
      "##aaa#    #aaa##",
      "##   ######   ##"
    ],
    [
      "##   ######   ##",
      "##aaa#LLLL#aaa##",
      " a            a ",
      " a            a ",
      " a            a ",
      "##E          E##",
      "#   cc         #",
      "#   dd         #",
      "#              #",
      "#             L#",
      "##E   ###    E##",
      " a            a ",
      " a            a ",
      " a            a ",
      "##aaa#    #aaa##",
      "##   ######   ##"
    ],
    [
      "##===######===##",
      "################",
      "=##############=",
      "=###  #########=",
      "=###  #########=",
      "####  ##########",
      "####  ##########",
      "####cc##########",
      "####dd##########",
      "####### ########",
      "################",
      "=##############=",
      "=##############=",
      "=##############=",
      "################",
      "##===######===##"
    ]
  ],
  "refpalette": "biohazard:handcrafted_furnishings"
}
