{
  "xsize": 16,
  "zsize": 16,
  "slices": [
    [
      "################",
      "################",
      "################",
      "################",
      "################",
      "####  ##########",
      "####  ##########",
      "####  ##########",
      "####cc##########",
      "################",
      "################",
      "################",
      "################",
      "################",
      "################",
      "################"
    ],
    [
      "##___######___##",
      "###     ⓐⓛ######",
      "_#D         #D#_",
      "_#D#cc      #D#_",
      "_#D:dd:     #D#_",
      "###:  :     ####",
      "#  :  :        #",
      "#F :  : ④⑱⑤   L#",
      "#F :  :       L#",
      "#              #",
      "##     ##     ##",
      "_#            #_",
      "_#    . .     #_",
      "_#            #_",
      "######L⑥⑦L######",
      "##___######___##"
    ],
    [
      "##   ######   ##",
      "##a       #aaa##",
      " aK          Ka ",
      " aK          Ka ",
      " aK cc       Ka ",
      "##  dd        ##",
      "#              #",
      "#             L#",
      "#             L#",
      "#              #",
      "##     ##     ##",
      " a            a ",
      " a    - -     a ",
      " a            a ",
      "##aaa#L  L#aaa##",
      "##   ######   ##"
    ],
    [
      "##   ######   ##",
      "##a    ⑫⑫L#aaa##",
      " a            a ",
      " a            a ",
      " a            a ",
      "##  cc        ##",
      "#   dd         #",
      "#              #",
      "#              #",
      "#              #",
      "##     ##     ##",
      " a            a ",
      " a            a ",
      " a            a ",
      "##aaa#LⓑⓑL#aaa##",
      "##   ######   ##"
    ],
    [
      "##   ######   ##",
      "##aaa#    #aaa##",
      " a            a ",
      " a            a ",
      " a            a ",
      "##E          E##",
      "#   cc         #",
      "#   dd         #",
      "#              #",
      "#              #",
      "##E   ###    E##",
      " a            a ",
      " a            a ",
      " a            a ",
      "##aaa#    #aaa##",
      "##   ######   ##"
    ],
    [
      "##===######===##",
      "################",
      "=##############=",
      "=###  #########=",
      "=###  #########=",
      "####  ##########",
      "####  ##########",
      "####cc##########",
      "####dd##########",
      "####### ########",
      "################",
      "=##############=",
      "=##############=",
      "=##############=",
      "################",
      "##===######===##"
    ]
  ],
  "refpalette": "biohazard:handcrafted_furnishings"
}
