{
  "xsize": 16,
  "zsize": 16,
  "slices": [
    [
      "################",
      "################",
      "################",
      "################",
      "################",
      "################",
      "################",
      "################",
      "################",
      "#######l########",
      "################",
      "################",
      "################",
      "################",
      "################",
      "################"
    ],
    [
      "##___######___##",
      "######  ⓐⓛ######",
      "_#D#        #D#_",
      "_#D#        #D#_",
      "_#D#        #D#_",
      "####        ####",
      "#              #",
      "#F      ④⑱⑤   L#",
      "#F            L#",
      "#      l       #",
      "##    ###     ##",
      "_#            #_",
      "_#    . .     #_",
      "_#            #_",
      "######L⑥⑦L######",
      "##___######___##"
    ],
    [
      "##   ######   ##",
      "##aaa#    #aaa##",
      " aK          Ka ",
      " aK          Ka ",
      " aK          Ka ",
      "##            ##",
      "#              #",
      "#             L#",
      "#             L#",
      "#      l       #",
      "##    ###     ##",
      " a            a ",
      " a    - -     a ",
      " a            a ",
      "##aaa#L  L#aaa##",
      "##   ######   ##"
    ],
    [
      "##   ######   ##",
      "##aaa#L⑫⑫L#aaa##",
      " a            a ",
      " a            a ",
      " a            a ",
      "##            ##",
      "#              #",
      "#              #",
      "#              #",
      "#      l       #",
      "##    ###     ##",
      " a            a ",
      " a            a ",
      " a            a ",
      "##aaa#LⓑⓑL#aaa##",
      "##   ######   ##"
    ],
    [
      "##   ######   ##",
      "##aaa#    #aaa##",
      " a            a ",
      " a            a ",
      " a            a ",
      "##E          E##",
      "#              #",
      "#              #",
      "#              #",
      "#      l       #",
      "##E   ###    E##",
      " a            a ",
      " a            a ",
      " a            a ",
      "##aaa#    #aaa##",
      "##   ######   ##"
    ],
    [
      "##===######===##",
      "################",
      "=##############=",
      "=##############=",
      "=##############=",
      "################",
      "################",
      "################",
      "################",
      "#######l########",
      "################",
      "=##############=",
      "=##############=",
      "=##############=",
      "################",
      "##===######===##"
    ]
  ],
  "refpalette": "biohazard:handcrafted_furnishings"
}
