{
  "xsize": 16,
  "zsize": 16,
  "slices": [
    [
      "################",
      "################",
      "################",
      "################",
      "################",
      "####  ##########",
      "####  ##########",
      "####  ##########",
      "####cc##########",
      "################",
      "################",
      "################",
      "################",
      "################",
      "################",
      "################"
    ],
    [
      "##___######___##",
      "###      L######",
      "_#            #_",
      "_#  cc  ②     #_",
      "_# :dd: ③     #_",
      "## :  : ①     ##",
      "#  :  :        #",
      "#  :  :        #",
      "#  :  :        #",
      "#              #",
      "###    #### ####",
      "_#   FFFF     #_",
      "_#            #_",
      "_#            #_",
      "######⑥⑦ ⑩######",
      "##___######___##"
    ],
    [
      "##   ######   ##",
      "##a      L#aaa##",
      " a            a ",
      " a            a ",
      " a  cc        a ",
      "##  dd        ##",
      "#              #",
      "#              #",
      "#              #",
      "#              #",
      "###    #### ####",
      " a            a ",
      " a            a ",
      " a            a ",
      "##aaa#    #aaa##",
      "##   ######   ##"
    ],
    [
      "##   ######   ##",
      "##a    ⑮⑮L#aaa##",
      " a            a ",
      " a            a ",
      " a            a ",
      "##  cc        ##",
      "#   dd         #",
      "#              #",
      "#              #",
      "#              #",
      "###    #########",
      " a            a ",
      " a            a ",
      " a            a ",
      "##aaa#    #aaa##",
      "##   ######   ##"
    ],
    [
      "##   ######   ##",
      "##aaa#L⑮⑮L#aaa##",
      " a            a ",
      " a            a ",
      " a            a ",
      "##E          E##",
      "#   cc         #",
      "#   dd         #",
      "#              #",
      "#              #",
      "################",
      " a     E      a ",
      " a            a ",
      " a            a ",
      "##aaa#⑲⑳⑳⑲#aaa##",
      "##   ######   ##"
    ],
    [
      "##===######===##",
      "################",
      "=##############=",
      "=###  #########=",
      "=###  #########=",
      "####  ##########",
      "####  ##########",
      "####cc##########",
      "####dd##########",
      "####### ########",
      "################",
      "=##############=",
      "=##############=",
      "=##############=",
      "################",
      "##===######===##"
    ]
  ],
  "refpalette": "biohazard:handcrafted_furnishings"
}
