{
    "xsize":  16,
    "zsize":  16,
    "slices":  [
                   [
                       "################",
                       "################",
                       "################",
                       "################",
                       "################",
                       "################",
                       "################",
                       "################",
                       "################",
                       "#######l########",
                       "################",
                       "################",
                       "################",
                       "################",
                       "################",
                       "################"
                   ],
                   [
                       "##___######___##",
                       "######uv  ######",
                       "_#       w    #_",
                       "_#            #_",
                       "_#     rts    #_",
                       "##            ##",
                       "#              #",
                       "#              #",
                       "#              #",
                       "#      l       #",
                       "########### ####",
                       "_#   FFFF     #_",
                       "_#       Bz C #_",
                       "_#       A    #_",
                       "######    ######",
                       "##___######___##"
                   ],
                   [
                       "##   ######   ##",
                       "##aaa#    #aaa##",
                       " a            a ",
                       " a            a ",
                       " a            a ",
                       "##            ##",
                       "#              #",
                       "#              #",
                       "#              #",
                       "#      l       #",
                       "########### ####",
                       " a            a ",
                       " a            a ",
                       " a            a ",
                       "##aaa#    #aaa##",
                       "##   ######   ##"
                   ],
                   [
                       "##   ######   ##",
                       "##aaa#    #aaa##",
                       " a            a ",
                       " a            a ",
                       " a            a ",
                       "##            ##",
                       "#              #",
                       "#              #",
                       "#              #",
                       "#      l       #",
                       "################",
                       " a            a ",
                       " a            a ",
                       " a            a ",
                       "##aaa#    #aaa##",
                       "##   ######   ##"
                   ],
                   [
                       "##   ######   ##",
                       "##aaa#    #aaa##",
                       " a            a ",
                       " a            a ",
                       " a            a ",
                       "##E          E##",
                       "#              #",
                       "#              #",
                       "#              #",
                       "#      l       #",
                       "################",
                       " a     E      a ",
                       " a            a ",
                       " a            a ",
                       "##aaa#    #aaa##",
                       "##   ######   ##"
                   ],
                   [
                       "##===######===##",
                       "################",
                       "=##############=",
                       "=##############=",
                       "=##############=",
                       "################",
                       "################",
                       "################",
                       "################",
                       "#######l########",
                       "################",
                       "=##############=",
                       "=##############=",
                       "=##############=",
                       "################",
                       "##===######===##"
                   ]
               ],
    "refpalette":  "biohazard:handcrafted_furnishings"
}
