{
  "xsize": 16,
  "zsize": 16,
  "slices": [
    [
      "################",
      "################",
      "################",
      "################",
      "################",
      "################",
      "################",
      "################",
      "################",
      "#######l########",
      "################",
      "################",
      "################",
      "################",
      "################",
      "################"
    ],
    [
      "##___######___##",
      "######L ⓑⓒ######",
      "_#F      ①   F#_",
      "_#            #_",
      "_#F          F#_",
      "#######  #######",
      "#              #",
      "# .          . #",
      "# .          . #",
      "#      l       #",
      "##    ###     ##",
      "_#            #_",
      "_#            #_",
      "_#            #_",
      "######ⓜⓛⓗⓖ######",
      "##___######___##"
    ],
    [
      "##   ######   ##",
      "##aaa#L   #aaa##",
      " a            a ",
      " a            a ",
      " a            a ",
      "##aaaa#  #aaaa##",
      "#              #",
      "# -          - #",
      "# -          - #",
      "#      l       #",
      "##    ###     ##",
      " a            a ",
      " a            a ",
      " a            a ",
      "##aaa#    #aaa##",
      "##   ######   ##"
    ],
    [
      "##   ######   ##",
      "##aaa#L   #aaa##",
      " a            a ",
      " a            a ",
      " a            a ",
      "##aaaa####aaaa##",
      "#              #",
      "#              #",
      "#              #",
      "#      l       #",
      "##    ###     ##",
      " a            a ",
      " a            a ",
      " a            a ",
      "##aaa#    #aaa##",
      "##   ######   ##"
    ],
    [
      "##   ######   ##",
      "##aaa#LLLL#aaa##",
      " a            a ",
      " a            a ",
      " a    E  E    a ",
      "################",
      "#⑪            ⑬#",
      "#⑭            ⑯#",
      "#⑭            ⑯#",
      "#⑪     l      ⑬#",
      "##E   ###    E##",
      " a            a ",
      " a            a ",
      " a            a ",
      "##aaa#    #aaa##",
      "##   ######   ##"
    ],
    [
      "##===######===##",
      "################",
      "=##############=",
      "=##############=",
      "=##############=",
      "################",
      "################",
      "################",
      "################",
      "#######l########",
      "################",
      "=##############=",
      "=##############=",
      "=##############=",
      "################",
      "##===######===##"
    ]
  ],
  "refpalette": "biohazard:handcrafted_furnishings"
}
