{
    "xsize":  16,
    "zsize":  16,
    "slices":  [
                   [
                       "################",
                       "################",
                       "################",
                       "################",
                       "################",
                       "################",
                       "################",
                       "################",
                       "################",
                       "#######l########",
                       "################",
                       "################",
                       "################",
                       "################",
                       "################",
                       "################"
                   ],
                   [
                       "##___######___##",
                       "######uv  ######",
                       "_#F      w   F#_",
                       "_#            #_",
                       "_#F    rts   F#_",
                       "#######  #######",
                       "#              #",
                       "# .          . #",
                       "# .          . #",
                       "#      l       #",
                       "##    ###     ##",
                       "_#            #_",
                       "_#       Bz C #_",
                       "_#       A    #_",
                       "######    ######",
                       "##___######___##"
                   ],
                   [
                       "##   ######   ##",
                       "##aaa#    #aaa##",
                       " a            a ",
                       " a            a ",
                       " a            a ",
                       "##aaaa#  #aaaa##",
                       "#              #",
                       "# -          - #",
                       "# -          - #",
                       "#      l       #",
                       "##    ###     ##",
                       " a            a ",
                       " a            a ",
                       " a            a ",
                       "##aaa#    #aaa##",
                       "##   ######   ##"
                   ],
                   [
                       "##   ######   ##",
                       "##aaa#    #aaa##",
                       " a            a ",
                       " a            a ",
                       " a            a ",
                       "##aaaa####aaaa##",
                       "#              #",
                       "#              #",
                       "#              #",
                       "#      l       #",
                       "##    ###     ##",
                       " a            a ",
                       " a            a ",
                       " a            a ",
                       "##aaa#    #aaa##",
                       "##   ######   ##"
                   ],
                   [
                       "##   ######   ##",
                       "##aaa#    #aaa##",
                       " a            a ",
                       " a            a ",
                       " a    E  E    a ",
                       "################",
                       "#              #",
                       "#              #",
                       "#              #",
                       "#      l       #",
                       "##E   ###    E##",
                       " a            a ",
                       " a            a ",
                       " a            a ",
                       "##aaa#    #aaa##",
                       "##   ######   ##"
                   ],
                   [
                       "##===######===##",
                       "################",
                       "=##############=",
                       "=##############=",
                       "=##############=",
                       "################",
                       "################",
                       "################",
                       "################",
                       "#######l########",
                       "################",
                       "=##############=",
                       "=##############=",
                       "=##############=",
                       "################",
                       "##===######===##"
                   ]
               ],
    "refpalette":  "biohazard:handcrafted_furnishings"
}
