{
  "xsize": 16,
  "zsize": 16,
  "slices": [
    [
      "################",
      "################",
      "################",
      "################",
      "################",
      "####  ##########",
      "####  ##########",
      "####  ##########",
      "####cc##########",
      "################",
      "################",
      "################",
      "################",
      "################",
      "################",
      "################"
    ],
    [
      "##___######___##",
      "###     ⓑⓒ######",
      "_#F      ①   F#_",
      "_#  cc        #_",
      "_#F:dd:      F#_",
      "###:  :  #######",
      "#  :  :        #",
      "# .:  :      . #",
      "# .:  :      . #",
      "#              #",
      "##     ##     ##",
      "_#            #_",
      "_#            #_",
      "_#            #_",
      "######ⓜⓛⓗⓖ######",
      "##___######___##"
    ],
    [
      "##   ######   ##",
      "##a       #aaa##",
      " a            a ",
      " a            a ",
      " a  cc        a ",
      "##aadd#  #aaaa##",
      "#              #",
      "# -          - #",
      "# -          - #",
      "#              #",
      "##     ##     ##",
      " a            a ",
      " a            a ",
      " a            a ",
      "##aaa#    #aaa##",
      "##   ######   ##"
    ],
    [
      "##   ######   ##",
      "##a       #aaa##",
      " a            a ",
      " a            a ",
      " a            a ",
      "##aacc####aaaa##",
      "#   dd         #",
      "#              #",
      "#              #",
      "#              #",
      "##     ##     ##",
      " a            a ",
      " a            a ",
      " a            a ",
      "##aaa#    #aaa##",
      "##   ######   ##"
    ],
    [
      "##   ######   ##",
      "##aaa#LLLL#aaa##",
      " a            a ",
      " a            a ",
      " a    E  E    a ",
      "####  ##########",
      "#⑪  cc        ⑬#",
      "#⑭  dd        ⑯#",
      "#⑭            ⑯#",
      "#⑪            ⑬#",
      "##E   ###    E##",
      " a            a ",
      " a            a ",
      " a            a ",
      "##aaa#    #aaa##",
      "##   ######   ##"
    ],
    [
      "##===######===##",
      "################",
      "=##############=",
      "=###  #########=",
      "=###  #########=",
      "####  ##########",
      "####  ##########",
      "####cc##########",
      "####dd##########",
      "####### ########",
      "################",
      "=##############=",
      "=##############=",
      "=##############=",
      "################",
      "##===######===##"
    ]
  ],
  "refpalette": "biohazard:handcrafted_furnishings"
}
