{
    "xsize":  16,
    "zsize":  16,
    "slices":  [
                   [
                       "################",
                       "################",
                       "################",
                       "################",
                       "################",
                       "################",
                       "################",
                       "################",
                       "################",
                       "#######l########",
                       "################",
                       "################",
                       "################",
                       "################",
                       "################",
                       "################"
                   ],
                   [
                       "##___######___##",
                       "######uv  ######",
                       "_#D#     w  #D#_",
                       "_#D#        #D#_",
                       "_#D#   rts  #D#_",
                       "####        ####",
                       "#              #",
                       "#F            L#",
                       "#F            L#",
                       "#      l       #",
                       "##    ###     ##",
                       "_#            #_",
                       "_#    . .Bz C #_",
                       "_#       A    #_",
                       "######    ######",
                       "##___######___##"
                   ],
                   [
                       "##   ######   ##",
                       "##aaa#    #aaa##",
                       " aK          Ka ",
                       " aK          Ka ",
                       " aK          Ka ",
                       "##            ##",
                       "#              #",
                       "#             L#",
                       "#             L#",
                       "#      l       #",
                       "##    ###     ##",
                       " a            a ",
                       " a    - -     a ",
                       " a            a ",
                       "##aaa#    #aaa##",
                       "##   ######   ##"
                   ],
                   [
                       "##   ######   ##",
                       "##aaa#    #aaa##",
                       " a            a ",
                       " a            a ",
                       " a            a ",
                       "##            ##",
                       "#              #",
                       "#              #",
                       "#              #",
                       "#      l       #",
                       "##    ###     ##",
                       " a            a ",
                       " a            a ",
                       " a            a ",
                       "##aaa#    #aaa##",
                       "##   ######   ##"
                   ],
                   [
                       "##   ######   ##",
                       "##aaa#    #aaa##",
                       " a            a ",
                       " a            a ",
                       " a            a ",
                       "##E          E##",
                       "#              #",
                       "#              #",
                       "#              #",
                       "#      l       #",
                       "##E   ###    E##",
                       " a            a ",
                       " a            a ",
                       " a            a ",
                       "##aaa#    #aaa##",
                       "##   ######   ##"
                   ],
                   [
                       "##===######===##",
                       "################",
                       "=##############=",
                       "=##############=",
                       "=##############=",
                       "################",
                       "################",
                       "################",
                       "################",
                       "#######l########",
                       "################",
                       "=##############=",
                       "=##############=",
                       "=##############=",
                       "################",
                       "##===######===##"
                   ]
               ],
    "refpalette":  "biohazard:handcrafted_furnishings"
}
