{
    "xsize":  16,
    "zsize":  16,
    "slices":  [
                   [
                       "#@#@#@#@@#@#@#@#",
                       "@##############@",
                       "################",
                       "@##############@",
                       "################",
                       "@##############@",
                       "################",
                       "@##############@",
                       "@##############@",
                       "################",
                       "@#########  ###@",
                       "##########  ####",
                       "@#########  ###@",
                       "##########cc####",
                       "@##############@",
                       "#@#@#@#@@#@#@#@#"
                   ],
                   [
                       "#`#`#`#``#`#`#`#",
                       "`              `",
                       "# $$$      F$$ #",
                       "` $       w  $ `",
                       "# L .      . $ #",
                       "`              `",
                       "#              #",
                       "`       D  FEG `",
                       "`         ccC  `",
                       "#        :dd:  #",
                       "`        :  :  `",
                       "# L .    :  :  #",
                       "` $      :  :  `",
                       "# $$$          #",
                       "`              `",
                       "#`#`#`#``#`#`#`#"
                   ],
                   [
                       "#`#`#`#``#`#`#`#",
                       "`              `",
                       "# * L        * #",
                       "`            L `",
                       "# L -      - L #",
                       "`              `",
                       "#              #",
                       "`              `",
                       "`              `",
                       "#         cc   #",
                       "`         dd   `",
                       "# L -          #",
                       "`              `",
                       "# * C          #",
                       "`              `",
                       "#`#`#`#``#`#`#`#"
                   ],
                   [
                       "#`#`#`#``#`#`#`#",
                       "`              `",
                       "#              #",
                       "`              `",
                       "#              #",
                       "`              `",
                       "#              #",
                       "`              `",
                       "`              `",
                       "#              #",
                       "`         cc   `",
                       "#         dd   #",
                       "`              `",
                       "#              #",
                       "`              `",
                       "#`#`#`#``#`#`#`#"
                   ],
                   [
                       "#`#`#`#``#`#`#`#",
                       "`              `",
                       "#              #",
                       "`  E        E  `",
                       "#              #",
                       "`              `",
                       "#              #",
                       "`              `",
                       "`              `",
                       "#              #",
                       "`              `",
                       "#         cc   #",
                       "`  E      dd   `",
                       "#              #",
                       "`              `",
                       "#`#`#`#``#`#`#`#"
                   ],
                   [
                       "#`#`#`#``#`#`#`#",
                       "`              `",
                       "#              #",
                       "`  {        {  `",
                       "#              #",
                       "`              `",
                       "#              #",
                       "`              `",
                       "`              `",
                       "#              #",
                       "`              `",
                       "#              #",
                       "`  {      cc   `",
                       "#         dd   #",
                       "`              `",
                       "#`#`#`#``#`#`#`#"
                   ]
               ],
    "refpalette":  "biohazard:handcrafted_furnishings"
}
