{
  "xsize": 16,
  "zsize": 16,
  "slices": [
    [
      "#@#@#@#@@#@#@#@#",
      "@##############@",
      "################",
      "@##############@",
      "################",
      "@##############@",
      "################",
      "@##############@",
      "@##############@",
      "################",
      "@#########  ###@",
      "##########  ####",
      "@#########  ###@",
      "##########cc####",
      "@##############@",
      "#@#@#@#@@#@#@#@#"
    ],
    [
      "#`#`#`#``#`#`#`#",
      "`   L :LL: ⓑⓒF `",
      "#L    #  #  ①  #",
      "`              `",
      "#L    #  #    F#",
      "`     :  : C   `",
      "#:# #:#  #:# #:#",
      "`              `",
      "`         cc   `",
      "#:# #:#  :dd:  #",
      "`     :  :  :  `",
      "#L    #  :  :  #",
      "`        :  :  `",
      "#     #        #",
      "` F F : ⓗⓖ ⓜⓛ *`",
      "#`#`#`#``#`#`#`#"
    ],
    [
      "#`#`#`#``#`#`#`#",
      "`   L :LL:     `",
      "#L    #  #     #",
      "`              `",
      "#L    #  #     #",
      "`     :  :     `",
      "#:# #:#  #:# #:#",
      "`              `",
      "`              `",
      "#:# #:#   cc   #",
      "`     :   dd   `",
      "#     #        #",
      "`              `",
      "#     #        #",
      "`     :        `",
      "#`#`#`#``#`#`#`#"
    ],
    [
      "#`#`#`#``#`#`#`#",
      "`     :LL:     `",
      "#     #  #     #",
      "`              `",
      "#     #  #     #",
      "`     :  :     `",
      "#:# #:#  #:# #:#",
      "`              `",
      "`              `",
      "#:# #:#        #",
      "`     :   cc   `",
      "#     #   dd   #",
      "`              `",
      "#     #        #",
      "`     :        `",
      "#`#`#`#``#`#`#`#"
    ],
    [
      "#`#`#`#``#`#`#`#",
      "`     :LL:     `",
      "#     #  #     #",
      "`           E  `",
      "#     #  #     #",
      "`     :  :     `",
      "#:# #:#  #:# #:#",
      "`              `",
      "`              `",
      "#:# #:#        #",
      "`     :        `",
      "#     #   cc   #",
      "`  E      dd   `",
      "#     #        #",
      "`     :        `",
      "#`#`#`#``#`#`#`#"
    ],
    [
      "#`#`#`#``#`#`#`#",
      "`     #  #     `",
      "#     #  #     #",
      "`     #  #  {  `",
      "#     #  #     #",
      "`     #  #     `",
      "######1#########",
      "`     #        `",
      "`     #        `",
      "#######        #",
      "`     #        `",
      "#     #        #",
      "`  {  #   cc   `",
      "#     #   dd   #",
      "`     #        `",
      "#`#`#`#``#`#`#`#"
    ]
  ],
  "refpalette": "biohazard:handcrafted_furnishings"
}
