{
    "xsize":  16,
    "zsize":  16,
    "slices":  [
                   [
                       "#@#@#@#@@#@#@#@#",
                       "@##############@",
                       "################",
                       "@##############@",
                       "################",
                       "@##############@",
                       "################",
                       "@##############@",
                       "@##############@",
                       "################",
                       "@#########  ###@",
                       "##########  ####",
                       "@#########  ###@",
                       "##########cc####",
                       "@##############@",
                       "#@#@#@#@@#@#@#@#"
                   ],
                   [
                       "#`#`#`#``#`#`#`#",
                       "`              `",
                       "#           __ #",
                       "`         w    `",
                       "#  _ Q _    QQ #",
                       "`  _ Q _       `",
                       "#    Q         #",
                       "`  _ Q _D  FEG `",
                       "`  _ Q _  ccC  `",
                       "#    Q   :dd:  #",
                       "`  _ Q _ :  :  `",
                       "#  _ Q _ :  :  #",
                       "`        :  :  `",
                       "#              #",
                       "`              `",
                       "#`#`#`#``#`#`#`#"
                   ],
                   [
                       "#`#`#`#``#`#`#`#",
                       "`              `",
                       "#              #",
                       "`              `",
                       "#           *  #",
                       "`              `",
                       "#    *         #",
                       "`              `",
                       "`              `",
                       "#    *    cc   #",
                       "`         dd   `",
                       "#              #",
                       "`              `",
                       "#              #",
                       "`              `",
                       "#`#`#`#``#`#`#`#"
                   ],
                   [
                       "#`#`#`#``#`#`#`#",
                       "`              `",
                       "#              #",
                       "`              `",
                       "#              #",
                       "`              `",
                       "#              #",
                       "`              `",
                       "`              `",
                       "#              #",
                       "`         cc   `",
                       "#         dd   #",
                       "`              `",
                       "#              #",
                       "`              `",
                       "#`#`#`#``#`#`#`#"
                   ],
                   [
                       "#`#`#`#``#`#`#`#",
                       "`              `",
                       "#              #",
                       "`              `",
                       "#              #",
                       "`              `",
                       "#    E         #",
                       "`              `",
                       "`              `",
                       "#    E         #",
                       "`              `",
                       "#         cc   #",
                       "`         dd   `",
                       "#              #",
                       "`              `",
                       "#`#`#`#``#`#`#`#"
                   ],
                   [
                       "#`#`#`#``#`#`#`#",
                       "`              `",
                       "#              #",
                       "`              `",
                       "#              #",
                       "`              `",
                       "#    {         #",
                       "`              `",
                       "`              `",
                       "#    {         #",
                       "`              `",
                       "#              #",
                       "`         cc   `",
                       "#         dd   #",
                       "`              `",
                       "#`#`#`#``#`#`#`#"
                   ]
               ],
    "refpalette":  "biohazard:handcrafted_furnishings"
}
