{
  "xsize": 16,
  "zsize": 16,
  "slices": [
    [
      " @#@#@#@@#@#@#@ ",
      "@##############@",
      "################",
      "@##############@",
      "################",
      "@##############@",
      "################",
      "@##############@",
      "@##############@",
      "################",
      "@#########  ###@",
      "##########  ####",
      "@#########  ###@",
      "##########cc####",
      "@##############@",
      " @#@#@#@@#@#@#@ "
    ],
    [
      " ζρρρρππππζπππζ ",
      "ζ π  ζ      ⓓ  ζ",
      "π           __ π",
      "π              π",
      "π  _ Q _    QQ π",
      "ζ  _ Q _       ζ",
      "π    Q         π",
      "π  _ Q _       π",
      "π  _ Q _  cc   π",
      "π    Q    dd:  π",
      "ζ  _ Q _    :  ζ",
      "π  _ Q _    :  π",
      "π           :  π",
      "π           :  π",
      "ζ      ⑥⑦      ζ",
      " ζπππζππππρρρρζ "
    ],
    [
      " ζ    θθθθζθθθζ ",
      "ζ θ  ζ         ζ",
      "θ              θ",
      "θ              θ",
      "θ           *  θ",
      "ζ              ζ",
      "θ    *         θ",
      "θ              θ",
      "θ              θ",
      "θ    *    cc   θ",
      "ζ         dd   ζ",
      "θ              θ",
      "θ              θ",
      "θ              θ",
      "ζ              ζ",
      " ζθθθζθθθθ    ζ "
    ],
    [
      " ζ    θθθθζθθθζ ",
      "ζ θθθζ         ζ",
      "θ              θ",
      "θ              θ",
      "θ              θ",
      "ζ              ζ",
      "θ              θ",
      "θ              θ",
      "θ              θ",
      "θ              θ",
      "ζ         cc   ζ",
      "θ         dd   θ",
      "θ              θ",
      "θ              θ",
      "ζ              ζ",
      " ζθθθζθθθθ    ζ "
    ],
    [
      " ζ    θθθθζθθθζ ",
      "ζ θθθζ         ζ",
      "θ              θ",
      "θ              θ",
      "θ              θ",
      "ζ              ζ",
      "θ    E         θ",
      "θ              θ",
      "θ              θ",
      "θ    E         θ",
      "ζ              ζ",
      "θ         cc   θ",
      "θ         dd   θ",
      "θ              θ",
      "ζ         ζθθθ ζ",
      " ζθθθζθθθθ    ζ "
    ],
    [
      " ζ    ππππζπππζ ",
      "ζ πππζ         ζ",
      "π              π",
      "π              π",
      "π              π",
      "ζ              ζ",
      "π    {         π",
      "π              π",
      "π              π",
      "π    {         π",
      "ζ              ζ",
      "π              π",
      "π         cc   π",
      "π         dd   π",
      "ζ         ζπππ ζ",
      " ζπππζππππ    ζ "
    ]
  ],
  "refpalette": "biohazard:furnished_facades"
}
