{
  "xsize": 16,
  "zsize": 16,
  "refpalette": "lcmt:streets",
  "slices": [
    [
      "bbbbASSSSSSAbbbb",
      "bbbbASSSSSSAbbbb",
      "bbUbASSSSSSAbUbb",
      "bbbbASSSSSSAbbbb",
      "AAAAASSSSSSAAAAA",
      "SSSSSSSSSSSSSSSS",
      "SSSSSSSSSSSSSSSS",
      "SSSSSSSSSSSSSSSS",
      "SSSSSSSSSSSSSSSS",
      "SSSSSSSSSSSSSSSS",
      "SSSSSSSSSSSSSSSS",
      "AAAAASSSSSSAAAAA",
      "bbbbASSSSSSAbbbb",
      "bbUbASSSSSSAbUbb",
      "bbbbASSSSSSAbbbb",
      "bbbbASSSSSSAbbbb"
    ],
    [
      "~~~~~~~~~~~~~~~~",
      "~~~~~~~~~~~~~~~~",
      "~~V~~~~~~~~~~V~~",
      "~~~~~~~~~~~~~~~~",
      "~~~~a~~~~~~a~~~~",
      "~~~~~~~~~~~~~~~~",
      "~~~~~~~~~~~~~~~~",
      "~~~~~~~~~~~~~~~~",
      "~~~~~~~~~~~~~~~~",
      "~~~~~~~~~~~~~~~~",
      "~~~~~~~~~~~~~~~~",
      "~~~~a~~~~~~a~~~~",
      "~~~~~~~~~~~~~~~~",
      "~~V~~~~~~~~~~V~~",
      "~~~~~~~~~~~~~~~~",
      "~~~~~~~~~~~~~~~~"
    ],
    [
      "~~~~~~~~~~~~~~~~",
      "~~~~~~~~~~~~~~~~",
      "~~~~~~~~~~~~~~~~",
      "~~~~~~~~~~~~~~~~",
      "~~~~P~~~~~~P~~~~",
      "~~~~~~~~~~~~~~~~",
      "~~~~~~~~~~~~~~~~",
      "~~~~~~~~~~~~~~~~",
      "~~~~~~~~~~~~~~~~",
      "~~~~~~~~~~~~~~~~",
      "~~~~~~~~~~~~~~~~",
      "~~~~P~~~~~~P~~~~",
      "~~~~~~~~~~~~~~~~",
      "~~~~~~~~~~~~~~~~",
      "~~~~~~~~~~~~~~~~",
      "~~~~~~~~~~~~~~~~"
    ],
    [
      "~~~~~~~~~~~~~~~~",
      "~~~~~~~~~~~~~~~~",
      "~~~~~~~~~~~~~~~~",
      "~~~~~~~~~~~~~~~~",
      "~~~~Q~~~~~~Q~~~~",
      "~~~~~~~~~~~~~~~~",
      "~~~~~~~~~~~~~~~~",
      "~~~~~~~~~~~~~~~~",
      "~~~~~~~~~~~~~~~~",
      "~~~~~~~~~~~~~~~~",
      "~~~~~~~~~~~~~~~~",
      "~~~~Q~~~~~~Q~~~~",
      "~~~~~~~~~~~~~~~~",
      "~~~~~~~~~~~~~~~~",
      "~~~~~~~~~~~~~~~~",
      "~~~~~~~~~~~~~~~~"
    ],
    [
      "~~~~~~~~~~~~~~~~",
      "~~~~~~~~~~~~~~~~",
      "~~~~~~~~~~~~~~~~",
      "~~~~~~~~~~~~~~~~",
      "~~~~e~~~~~~e~~~~",
      "~~~~~~~~~~~~~~~~",
      "~~~~~~~~~~~~~~~~",
      "~~~~~~~~~~~~~~~~",
      "~~~~~~~~~~~~~~~~",
      "~~~~~~~~~~~~~~~~",
      "~~~~~~~~~~~~~~~~",
      "~~~~e~~~~~~e~~~~",
      "~~~~~~~~~~~~~~~~",
      "~~~~~~~~~~~~~~~~",
      "~~~~~~~~~~~~~~~~",
      "~~~~~~~~~~~~~~~~"
    ]
  ]
}
