{
  "xsize": 16,
  "zsize": 16,
  "slices": [
    [
      "##   ######   ##",
      "################",
      " ############## ",
      " ############## ",
      " ############## ",
      "################",
      "################",
      "################",
      "################",
      "#######l########",
      "################",
      " ############## ",
      " ############## ",
      " ############## ",
      "################",
      "##   ######   ##"
    ],
    [
      "##   ######   ##",
      "##aaa#LL⑫ⓒ#aaa##",
      " a       ①    a ",
      " a            a ",
      " a            a ",
      "##            ##",
      "#L            L#",
      "#⑪            ⑬#",
      "#⑪            ⑬#",
      "#L     l      L#",
      "##    ###     ##",
      " a            a ",
      " a            a ",
      " a            a ",
      "##aaa#ⓜⓛⓗⓖ#aaa##",
      "##   ######   ##"
    ],
    [
      "##   ######   ##",
      "##aaa#LL  #aaa##",
      " a            a ",
      " a            a ",
      " a            a ",
      "##            ##",
      "#L            L#",
      "#⑪            ⑬#",
      "#⑪            ⑬#",
      "#L     l      L#",
      "##    ###     ##",
      " a            a ",
      " a            a ",
      " a            a ",
      "##aaa#    #aaa##",
      "##   ######   ##"
    ],
    [
      "##   ######   ##",
      "##aaa#LL  #aaa##",
      " a            a ",
      " a            a ",
      " a            a ",
      "##            ##",
      "#L            L#",
      "#L            L#",
      "#L            L#",
      "#L     l      L#",
      "##    ###     ##",
      " a     E      a ",
      " a            a ",
      " a            a ",
      "##aaa#    #aaa##",
      "##   ######   ##"
    ],
    [
      "##   ######   ##",
      "################",
      " ############## ",
      " ############## ",
      " ############## ",
      "################",
      "################",
      "################",
      "################",
      "#######l########",
      "################",
      " ############## ",
      " ############## ",
      " ############## ",
      "################",
      "##   ######   ##"
    ],
    [
      "##   ######   ##",
      "################",
      " ############## ",
      " ############## ",
      " ############## ",
      "################",
      "################",
      "################",
      "################",
      "#######l########",
      "################",
      " ############## ",
      " ############## ",
      " ############## ",
      "################",
      "##   ######   ##"
    ]
  ],
  "refpalette": "biohazard:handcrafted_furnishings"
}
