{
  "xsize": 16,
  "zsize": 16,
  "slices": [
    [
      "##   ######   ##",
      "################",
      " ############## ",
      " ############## ",
      " ############## ",
      "################",
      "################",
      "################",
      "################",
      "#######l########",
      "################",
      " ############## ",
      " ############## ",
      " ############## ",
      "################",
      "##   ######   ##"
    ],
    [
      "##   ######   ##",
      "##aaa#L ⑨ⓓ#aaa##",
      " a  F#  ⑧     a ",
      " a  F#        a ",
      " a   #F       a ",
      "##   #F       ##",
      "#    #        L#",
      "#    #         #",
      "#    #        ⑬#",
      "#    # l      F#",
      "##   ##### #####",
      " a            a ",
      " a            a ",
      " a            a ",
      "##aaa# ⑥⑦ #aaa##",
      "##   ######   ##"
    ],
    [
      "##   ######   ##",
      "##aaa#L   #aaa##",
      " a   #        a ",
      " a   #        a ",
      " a   a        a ",
      "##   a        ##",
      "#    a        ⑬#",
      "#    a         #",
      "#    #         #",
      "#    # l       #",
      "##   ##### #####",
      " a            a ",
      " a            a ",
      " a            a ",
      "##aaa#    #aaa##",
      "##   ######   ##"
    ],
    [
      "##   ######   ##",
      "##aaa#LL⑫⑫#aaa##",
      " a   #        a ",
      " a   #        a ",
      " a   #        a ",
      "##   #        ##",
      "#    #        L#",
      "#    #         #",
      "#   E#         #",
      "#    # l       #",
      "##   ###########",
      " a     E      a ",
      " a            a ",
      " a            a ",
      "##aaa#    #aaa##",
      "##   ######   ##"
    ],
    [
      "##   ######   ##",
      "################",
      " ############## ",
      " ############## ",
      " ############## ",
      "################",
      "################",
      "################",
      "################",
      "#######l########",
      "################",
      " ############## ",
      " ############## ",
      " ############## ",
      "################",
      "##   ######   ##"
    ],
    [
      "##   ######   ##",
      "################",
      " ############## ",
      " ############## ",
      " ############## ",
      "################",
      "################",
      "################",
      "################",
      "#######l########",
      "################",
      " ############## ",
      " ############## ",
      " ############## ",
      "################",
      "##   ######   ##"
    ]
  ],
  "refpalette": "biohazard:handcrafted_furnishings"
}
