{
  "xsize": 16,
  "zsize": 16,
  "slices": [
    [
      "##   ######   ##",
      "################",
      " ############## ",
      " ############## ",
      " ############## ",
      "################",
      "################",
      "################",
      "###########  ###",
      "###########  ###",
      "###########  ###",
      " ##########cc## ",
      " ############## ",
      " ############## ",
      "################",
      "##   ######   ##"
    ],
    [
      "##   ######   ##",
      "##aaa#LL⑫ⓒ#aaa##",
      " a       ①    a ",
      " a            a ",
      " a            a ",
      "##            ##",
      "#L         cc L#",
      "#⑪        :dd:⑬#",
      "#⑪        :  :⑬#",
      "#L        :  :L#",
      "##    ### :  :##",
      " a        :  :a ",
      " a            a ",
      " a            a ",
      "##aaa#ⓜⓛⓗⓖ#aaa##",
      "##   ######   ##"
    ],
    [
      "##   ######   ##",
      "##aaa#LL  #aaa##",
      " a            a ",
      " a            a ",
      " a            a ",
      "##            ##",
      "#L            L#",
      "#⑪         cc ⑬#",
      "#⑪         dd ⑬#",
      "#L            L#",
      "##    ###     ##",
      " a            a ",
      " a            a ",
      " a            a ",
      "##aaa#    #aaa##",
      "##   ######   ##"
    ],
    [
      "##   ######   ##",
      "##aaa#LL  #aaa##",
      " a            a ",
      " a            a ",
      " a            a ",
      "##            ##",
      "#L            L#",
      "#L            L#",
      "#L         cc L#",
      "#L         dd L#",
      "##    ###     ##",
      " a     E      a ",
      " a            a ",
      " a            a ",
      "##aaa#    #aaa##",
      "##   ######   ##"
    ],
    [
      "##   ######   ##",
      "################",
      " ############## ",
      " ############## ",
      " ############## ",
      "################",
      "###########  ###",
      "###########  ###",
      "###########  ###",
      "####### ###cc###",
      "###########dd###",
      " ##########  ## ",
      " ############## ",
      " ############## ",
      "################",
      "##   ######   ##"
    ],
    [
      "##   ######   ##",
      "################",
      " ############## ",
      " ############## ",
      " ############## ",
      "################",
      "###########  ###",
      "###########  ###",
      "###########  ###",
      "####### ###  ###",
      "###########cc###",
      " ##########dd## ",
      " ############## ",
      " ############## ",
      "################",
      "##   ######   ##"
    ]
  ],
  "refpalette": "biohazard:handcrafted_furnishings"
}
