{
  "xsize": 16,
  "zsize": 16,
  "slices": [
    [
      "##   ######   ##",
      "################",
      " ############## ",
      " ############## ",
      " ############## ",
      "#######1########",
      "################",
      "################",
      "###########  ###",
      "###########  ###",
      "#####1#####  ###",
      " ##########cc## ",
      " ############## ",
      " ############## ",
      "################",
      "##   ######   ##"
    ],
    [
      "##   ######   ##",
      "##aaa#Fⓐⓛ #aaa##",
      " a            a ",
      " a            a ",
      " a            a ",
      "##  ######    ##",
      "#   :     :ccⓓⓕ#",
      "#   :     :dd:ⓔ#",
      "#   :     :  : #",
      "#   :     :  : #",
      "##  ######:  :##",
      " a        :  :a ",
      " a            a ",
      " a            a ",
      "##aaa#  ⓗⓖ#aaa##",
      "##   ######   ##"
    ],
    [
      "##   ######   ##",
      "##aaa#    #aaa##",
      " a            a ",
      " a            a ",
      " a            a ",
      "##  ######    ##",
      "#   :     :    #",
      "#   :      cc  #",
      "#   :      dd  #",
      "#   :     :    #",
      "##  #######   ##",
      " a            a ",
      " a            a ",
      " a            a ",
      "##aaa#    #aaa##",
      "##   ######   ##"
    ],
    [
      "##   ######   ##",
      "##aaa#    #aaa##",
      " a            a ",
      " a            a ",
      " a            a ",
      "##  ######    ##",
      "#   :  E  :    #",
      "#   :          #",
      "#   :      cc  #",
      "#   :     :dd  #",
      "##  #######   ##",
      " a            a ",
      " a            a ",
      " a            a ",
      "##aaa#    #aaa##",
      "##   ######   ##"
    ],
    [
      "##   ######   ##",
      "################",
      " ############## ",
      " ############## ",
      " ############## ",
      "################",
      "###########  ###",
      "###########  ###",
      "###########  ###",
      "####### ###cc###",
      "###########dd###",
      " ##########  ## ",
      " ############## ",
      " ############## ",
      "################",
      "##   ######   ##"
    ],
    [
      "##   ######   ##",
      "################",
      " ############## ",
      " ############## ",
      " ############## ",
      "################",
      "###########  ###",
      "###########  ###",
      "###########  ###",
      "####### ###  ###",
      "###########cc###",
      " ##########dd## ",
      " ############## ",
      " ############## ",
      "################",
      "##   ######   ##"
    ]
  ],
  "refpalette": "biohazard:handcrafted_furnishings"
}
