{
    "xsize":  16,
    "zsize":  16,
    "slices":  [
                   [
                       "##   ######   ##",
                       "################",
                       " ############## ",
                       " ############## ",
                       " ############## ",
                       "################",
                       "################",
                       "################",
                       "################",
                       "#######l########",
                       "################",
                       " ############## ",
                       " ############## ",
                       " ############## ",
                       "################",
                       "##   ######   ##"
                   ],
                   [
                       "##   ######   ##",
                       "##aaa#    #aaa##",
                       " a         D  a ",
                       " a        w   a ",
                       " a        E   a ",
                       "##            ##",
                       "#              #",
                       "#      I       #",
                       "#              #",
                       "#      l       #",
                       "##    ###     ##",
                       " a        Bz Ca ",
                       " a         A  a ",
                       " a            a ",
                       "##aaa#    #aaa##",
                       "##   ######   ##"
                   ],
                   [
                       "##   ######   ##",
                       "##aaa#    #aaa##",
                       " a            a ",
                       " a            a ",
                       " a            a ",
                       "##            ##",
                       "#              #",
                       "#              #",
                       "#              #",
                       "#      l       #",
                       "##    ###     ##",
                       " a            a ",
                       " a            a ",
                       " a            a ",
                       "##aaa#    #aaa##",
                       "##   ######   ##"
                   ],
                   [
                       "##   ######   ##",
                       "##aaa#    #aaa##",
                       " a            a ",
                       " a            a ",
                       " a            a ",
                       "##            ##",
                       "#              #",
                       "#              #",
                       "#              #",
                       "#      l       #",
                       "##    ###     ##",
                       " a     E      a ",
                       " a            a ",
                       " a            a ",
                       "##aaa#    #aaa##",
                       "##   ######   ##"
                   ],
                   [
                       "##   ######   ##",
                       "################",
                       " ############## ",
                       " ############## ",
                       " ############## ",
                       "################",
                       "################",
                       "################",
                       "################",
                       "#######l########",
                       "################",
                       " ############## ",
                       " ############## ",
                       " ############## ",
                       "################",
                       "##   ######   ##"
                   ],
                   [
                       "##   ######   ##",
                       "################",
                       " ############## ",
                       " ############## ",
                       " ############## ",
                       "################",
                       "################",
                       "################",
                       "################",
                       "#######l########",
                       "################",
                       " ############## ",
                       " ############## ",
                       " ############## ",
                       "################",
                       "##   ######   ##"
                   ]
               ],
    "refpalette":  "biohazard:handcrafted_furnishings"
}
