{
  "xsize": 16,
  "zsize": 16,
  "slices": [
    [
      " #   ######   # ",
      "################",
      " ############## ",
      " ############## ",
      " ############## ",
      "############1###",
      "################",
      "################",
      "###########  ###",
      "###########  ###",
      "####1######  ###",
      " ##########cc## ",
      " ############## ",
      " ############## ",
      "################",
      " #   ######   # "
    ],
    [
      " ααγγαγγγγαγγαα ",
      "α#aaa#ⓒⓑ⑨ⓓ#aaa#α",
      "γa    ① ⑧     aγ",
      "γa            aγ",
      "γa            aγ",
      "α### #####     α",
      "γL      FF#cc  γ",
      "γ⑪        #dd  γ",
      "γ⑪        #    γ",
      "γL        #   Cγ",
      "α### ######   #α",
      "γa            aγ",
      "γa             γ",
      "γa            aγ",
      "α#aaa#    #aaa#α",
      " ααγγαγγγγαγγαα "
    ],
    [
      " ααηηαηηηηαηηαα ",
      "α#aaa#    #aaa#α",
      "ηa            aη",
      "ηa            aη",
      "ηa            aη",
      "α### #####     α",
      "ηL        #    η",
      "η         #cc  η",
      "η         #dd  η",
      "ηL        #    η",
      "α### ######   #α",
      "ηa            aη",
      "ηa             η",
      "ηa            aη",
      "α#aaa#    #aaa#α",
      " ααηηαηηηηαηηαα "
    ],
    [
      " ααηηαηηηηαηηαα ",
      "α#aaa#    #aaa#α",
      "ηa            aη",
      "ηa            aη",
      "ηa     E      aη",
      "α#########     α",
      "η      E  #  %%η",
      "η         #    η",
      "η         #cc  η",
      "η         #dd %η",
      "α##########  ##α",
      "ηa            aη",
      "ηa             η",
      "ηa            aη",
      "α#aaa#    #aaa#α",
      " ααηηαηηηηαηηαα "
    ],
    [
      " ααηηαηηηηαηηαα ",
      "α##############α",
      "η##############η",
      "η##############η",
      "η##############η",
      "α##############α",
      "η##########  ##η",
      "η##########  ##η",
      "η##########  ##η",
      "η###### ###cc##η",
      "α##########dd##α",
      "η##########  ##η",
      "η##############η",
      "η##############η",
      "α##############α",
      " ααηηαηηηηαηηαα "
    ],
    [
      " ααγγαγγγγαγγαα ",
      "α##############α",
      "γ##############γ",
      "γ##############γ",
      "γ##############γ",
      "α##############α",
      "γ##########  ##γ",
      "γ##########  ##γ",
      "γ##########  ##γ",
      "γ###### ###  ##γ",
      "α##########cc##α",
      "γ##########dd##γ",
      "γ##############γ",
      "γ##############γ",
      "α##############α",
      " ααγγαγγγγαγγαα "
    ]
  ],
  "refpalette": "biohazard:furnished_facades"
}
