{
  "xsize": 16,
  "zsize": 16,
  "slices": [
    [
      "##   ######   ##",
      "################",
      " ############## ",
      " ############## ",
      " ############## ",
      "#######1########",
      "################",
      "################",
      "################",
      "#######l########",
      "#####1##########",
      " ############## ",
      " ############## ",
      " ############## ",
      "################",
      "##   ######   ##"
    ],
    [
      "##   ######   ##",
      "##aaa#Fⓐⓛ #aaa##",
      " a            a ",
      " a            a ",
      " a            a ",
      "##  #######   ##",
      "#   :     :  ⓓⓕ#",
      "#   :         ⓔ#",
      "#   :          #",
      "#   :  l  :    #",
      "##  #######   ##",
      " a            a ",
      " a            a ",
      " a            a ",
      "##aaa#  ⓗⓖ#aaa##",
      "##   ######   ##"
    ],
    [
      "##   ######   ##",
      "##aaa#    #aaa##",
      " a            a ",
      " a            a ",
      " a            a ",
      "##  #######   ##",
      "#   :     :    #",
      "#   :          #",
      "#   :          #",
      "#   :  l  :    #",
      "##  #######   ##",
      " a            a ",
      " a            a ",
      " a            a ",
      "##aaa#    #aaa##",
      "##   ######   ##"
    ],
    [
      "##   ######   ##",
      "##aaa#    #aaa##",
      " a            a ",
      " a            a ",
      " a            a ",
      "##  #######   ##",
      "#   :  E  :    #",
      "#   :          #",
      "#   :          #",
      "#   :  l  :    #",
      "##  #######   ##",
      " a            a ",
      " a            a ",
      " a            a ",
      "##aaa#    #aaa##",
      "##   ######   ##"
    ],
    [
      "##   ######   ##",
      "################",
      " ############## ",
      " ############## ",
      " ############## ",
      "################",
      "################",
      "################",
      "################",
      "#######l########",
      "################",
      " ############## ",
      " ############## ",
      " ############## ",
      "################",
      "##   ######   ##"
    ],
    [
      "##   ######   ##",
      "################",
      " ############## ",
      " ############## ",
      " ############## ",
      "################",
      "################",
      "################",
      "################",
      "#######l########",
      "################",
      " ############## ",
      " ############## ",
      " ############## ",
      "################",
      "##   ######   ##"
    ]
  ],
  "refpalette": "biohazard:handcrafted_furnishings"
}
