{
  "xsize": 16,
  "zsize": 16,
  "slices": [
    [
      "##   ######   ##",
      "################",
      " ############## ",
      " ############## ",
      " ############## ",
      "################",
      "################",
      "################",
      "###########  ###",
      "###########  ###",
      "###########  ###",
      " ##########cc## ",
      " ############## ",
      " ############## ",
      "################",
      "##   ######   ##"
    ],
    [
      "##   ######   ##",
      "##aaa#L ⑨ⓓ#aaa##",
      " a  F#  ⑧     a ",
      " a  F#        a ",
      " a   #F       a ",
      "##   #F       ##",
      "#    #     cc L#",
      "#    #    :dd: #",
      "#    #    :  :⑬#",
      "#    #    :  :F#",
      "##   #####:  :##",
      " a        :  :a ",
      " a            a ",
      " a            a ",
      "##aaa# ⑥⑦ #aaa##",
      "##   ######   ##"
    ],
    [
      "##   ######   ##",
      "##aaa#L   #aaa##",
      " a   #        a ",
      " a   #        a ",
      " a   a        a ",
      "##   a        ##",
      "#    a        ⑬#",
      "#    a     cc  #",
      "#    #     dd  #",
      "#    #         #",
      "##   #####   ###",
      " a            a ",
      " a            a ",
      " a            a ",
      "##aaa#    #aaa##",
      "##   ######   ##"
    ],
    [
      "##   ######   ##",
      "##aaa#LL⑫⑫#aaa##",
      " a   #        a ",
      " a   #        a ",
      " a   #        a ",
      "##   #        ##",
      "#    #        L#",
      "#    #         #",
      "#   E#     cc  #",
      "#    #     dd  #",
      "##   ######  ###",
      " a     E      a ",
      " a            a ",
      " a            a ",
      "##aaa#    #aaa##",
      "##   ######   ##"
    ],
    [
      "##   ######   ##",
      "################",
      " ############## ",
      " ############## ",
      " ############## ",
      "################",
      "###########  ###",
      "###########  ###",
      "###########  ###",
      "####### ###cc###",
      "###########dd###",
      " ##########  ## ",
      " ############## ",
      " ############## ",
      "################",
      "##   ######   ##"
    ],
    [
      "##   ######   ##",
      "################",
      " ############## ",
      " ############## ",
      " ############## ",
      "################",
      "###########  ###",
      "###########  ###",
      "###########  ###",
      "####### ###  ###",
      "###########cc###",
      " ##########dd## ",
      " ############## ",
      " ############## ",
      "################",
      "##   ######   ##"
    ]
  ],
  "refpalette": "biohazard:handcrafted_furnishings"
}
