{
    "xsize":  16,
    "zsize":  16,
    "slices":  [
                   [
                       "##   ######   ##",
                       "################",
                       " ############## ",
                       " ############## ",
                       " ############## ",
                       "################",
                       "################",
                       "################",
                       "################",
                       "#######l########",
                       "################",
                       " ############## ",
                       " ############## ",
                       " ############## ",
                       "################",
                       "##   ######   ##"
                   ],
                   [
                       "##   ######   ##",
                       "##aaa#    #aaa##",
                       " a  F#     D  a ",
                       " a  F#    w   a ",
                       " a   #F   E   a ",
                       "##   #F       ##",
                       "#    #        L#",
                       "#    # I       #",
                       "#    #         #",
                       "#    # l       #",
                       "##   ##### #####",
                       " a        Bz Ca ",
                       " a         A  a ",
                       " a            a ",
                       "##aaa#    #aaa##",
                       "##   ######   ##"
                   ],
                   [
                       "##   ######   ##",
                       "##aaa#    #aaa##",
                       " a   #        a ",
                       " a   #        a ",
                       " a   a        a ",
                       "##   a        ##",
                       "#    a         #",
                       "#    a         #",
                       "#    #         #",
                       "#    # l       #",
                       "##   ##### #####",
                       " a            a ",
                       " a            a ",
                       " a            a ",
                       "##aaa#    #aaa##",
                       "##   ######   ##"
                   ],
                   [
                       "##   ######   ##",
                       "##aaa#    #aaa##",
                       " a   #        a ",
                       " a   #        a ",
                       " a   #        a ",
                       "##   #        ##",
                       "#    #         #",
                       "#    #         #",
                       "#   E#         #",
                       "#    # l       #",
                       "##   ###########",
                       " a     E      a ",
                       " a            a ",
                       " a            a ",
                       "##aaa#    #aaa##",
                       "##   ######   ##"
                   ],
                   [
                       "##   ######   ##",
                       "################",
                       " ############## ",
                       " ############## ",
                       " ############## ",
                       "################",
                       "################",
                       "################",
                       "################",
                       "#######l########",
                       "################",
                       " ############## ",
                       " ############## ",
                       " ############## ",
                       "################",
                       "##   ######   ##"
                   ],
                   [
                       "##   ######   ##",
                       "################",
                       " ############## ",
                       " ############## ",
                       " ############## ",
                       "################",
                       "################",
                       "################",
                       "################",
                       "#######l########",
                       "################",
                       " ############## ",
                       " ############## ",
                       " ############## ",
                       "################",
                       "##   ######   ##"
                   ]
               ],
    "refpalette":  "biohazard:handcrafted_furnishings"
}
