{
  "xsize": 16,
  "zsize": 16,
  "slices": [
    [
      "  ############  ",
      " ############## ",
      "################",
      "################",
      " ###############",
      " ###############",
      " ###############",
      " ###############",
      " ###############",
      " ###########  ##",
      " ###########  ##",
      " ###########  ##",
      "############cc##",
      "################",
      " ############## ",
      "  ############  "
    ],
    [
      "  αααξααααξααα  ",
      " ξ       ⓒⓑ   ξ ",
      "α        ①     α",
      "α  . .         ξ",
      " α             α",
      " ξ . .         ξ",
      " α             α",
      " α          cc α",
      " α         Ldd:ξ",
      " α         L  :α",
      " ξ # LL#  LL  :ξ",
      " α         :  :α",
      "α          :  :ξ",
      "α              α",
      " ξ   ⓗⓖ ⓜⓛ    ξ ",
      "  αααξααααξααα  "
    ],
    [
      "  ηηηξηηηηξηηη  ",
      " η            η ",
      "η              η",
      "η  - -         ξ",
      " η             η",
      " ξ - -         ξ",
      " η             η",
      " η             η",
      " η          cc ξ",
      " η         Ldd η",
      " ξ # LL#  LL   ξ",
      " η             η",
      "η  E           ξ",
      "η              η",
      " η            η ",
      "  ηηηξηηηηξηηη  "
    ],
    [
      "  ηηηξηηηηξηηη  ",
      " η            η ",
      "η              η",
      "η              ξ",
      " η             η",
      " ξ             ξ",
      " η             η",
      " η             η",
      " η             ξ",
      " η          cc η",
      " ξ##########dd#ξ",
      " η##########  #η",
      "η###########  #ξ",
      "η#########     η",
      " η#########   η ",
      "  ηηηξηηηηξηηη  "
    ],
    [
      "  ηηηξηηηηξηηη  ",
      " η            η ",
      "η              η",
      "η              ξ",
      " η         E   η",
      " ξ             ξ",
      " η             η",
      " η             η",
      " η             ξ",
      " η             η",
      " ξ     #    cc ξ",
      " η          dd η",
      "η  . .    .    ξ",
      "η              η",
      " ηⓑⓑF      Fⓑⓑη ",
      "  ηηηξηηηηξηηη  "
    ],
    [
      "  αααξααααξααα  ",
      " ξ            ξ ",
      "α              α",
      "α              ξ",
      " α         {   α",
      " ξ             ξ",
      " α             α",
      " α             α",
      " α             ξ",
      " α             α",
      " ξ     #       ξ",
      " α          cc α",
      "α  - -    - dd ξ",
      "α              α",
      " ξ            ξ ",
      "  αααξααααξααα  "
    ]
  ],
  "refpalette": "rotwire:furnished_facades"
}
