{
  "xsize": 16,
  "zsize": 16,
  "slices": [
    [
      "  ############  ",
      " ############## ",
      "################",
      "################",
      " ###############",
      " ###############",
      " ###############",
      " ###############",
      " ###############",
      " ###########  ##",
      " ###########  ##",
      " ###########  ##",
      "############cc##",
      "################",
      " ############## ",
      "  ############  "
    ],
    [
      "  αααξααααξααα  ",
      " ξL#⑨  ⑨ⓓ ⓒⓑ# ξ ",
      "α⑧ #F  ⑧  ① #  α",
      "α  #F      L#  ξ",
      " α #$      L#  α",
      " ξ #           ξ",
      " α             α",
      " α #        cc α",
      " α #       #dd ξ",
      " α #       #   α",
      " ξ #########   ξ",
      " α     ⑫⑫      α",
      "α              ξ",
      "α              α",
      " ξ   F    F   ξ ",
      "  αααξααααξααα  "
    ],
    [
      "  ηηηξηηηηξηηη  ",
      " η #        # η ",
      "η  #        #  η",
      "η  #       L#  ξ",
      " η #*      L#  η",
      " ξ #           ξ",
      " η             η",
      " η #           η",
      " η #       #cc ξ",
      " η #       #dd η",
      " ξ #########   ξ",
      " η     ⑫⑫      η",
      "η              ξ",
      "η              η",
      " η            η ",
      "  ηηηξηηηηξηηη  "
    ],
    [
      "  ηηηξηηηηξηηη  ",
      " η #        # η ",
      "η  #        #  η",
      "η  #        #  ξ",
      " η #        #  η",
      " ξ #           ξ",
      " η #           η",
      " η #           η",
      " η #           ξ",
      " η #        cc η",
      " ξ #########dd ξ",
      " η             η",
      "η              ξ",
      "η              η",
      " η            η ",
      "  ηηηξηηηηξηηη  "
    ],
    [
      "  ηηηξηηηηξηηη  ",
      " ηL#        # η ",
      "η  #        #  η",
      "η  #        #  ξ",
      " η #        #  η",
      " ξ #        #  ξ",
      " η #        #  η",
      " η #           η",
      " η #           ξ",
      " η #           η",
      " ξ #########cc ξ",
      " η      E   dd η",
      "η              ξ",
      "η              η",
      " η            η ",
      "  ηηηξηηηηξηηη  "
    ],
    [
      "  αααξααααξααα  ",
      " ξL#        # ξ ",
      "α  #        #  α",
      "α  #        #  ξ",
      " α #        #  α",
      " ξ #        #  ξ",
      " α #        #  α",
      " α #           α",
      " α #           ξ",
      " α #           α",
      " ξ #########   ξ",
      " α      {   cc α",
      "α           dd ξ",
      "α              α",
      " ξ            ξ ",
      "  αααξααααξααα  "
    ]
  ],
  "refpalette": "rotwire:furnished_facades"
}
