{
  "xsize": 16,
  "zsize": 16,
  "slices": [
    [
      "  ############  ",
      " ############## ",
      "################",
      "################",
      " ###############",
      " ###############",
      " ###############",
      " ###############",
      " ###############",
      " ###########  ##",
      " ###########  ##",
      " ###########  ##",
      "############cc##",
      "################",
      " ############## ",
      "  ############  "
    ],
    [
      "  αααξααααξααα  ",
      " ξ⑥  :  ⑨ⓓ:   ξ ",
      "α    :  ⑧ :    α",
      "α  # :    : #  ξ",
      " α   :    :    α",
      " ξ: ::    :    ξ",
      " α             α",
      " α          cc α",
      " α         #dd ξ",
      " α         #   α",
      " ξ####  ###    ξ",
      " α FFF    #    α",
      "αF             ξ",
      "α              α",
      " ξ⑦       #   ξ ",
      "  αααξααααξααα  "
    ],
    [
      "  ηηηξηηηηξηηη  ",
      " η   :    :   η ",
      "η    :    :    η",
      "η  # :    : #  ξ",
      " η   :    :    η",
      " ξ: ::    :    ξ",
      " η             η",
      " η             η",
      " η          cc ξ",
      " η         #dd η",
      " ξ####  ###    ξ",
      " η        #    η",
      "η              ξ",
      "η              η",
      " η        #   η ",
      "  ηηηξηηηηξηηη  "
    ],
    [
      "  ηηηξηηηηξηηη  ",
      " η####    ####η ",
      "η## ##    ## ##η",
      "η#####    #####ξ",
      " η####    #####η",
      " ξ####    #    ξ",
      " η             η",
      " η             η",
      " η             ξ",
      " η         #cc η",
      " ξ######### dd ξ",
      " η        #    η",
      "η         #    ξ",
      "η              η",
      " η        #   η ",
      "  ηηηξηηηηξηηη  "
    ],
    [
      "  ηηηξηηηηξηηη  ",
      " η   :    :   η ",
      "η    :    :    η",
      "η 1  :    :  1 ξ",
      " η C :    : C  η",
      " ξ::::    :::::ξ",
      " η             η",
      " η             η",
      " η             ξ",
      " η         #   η",
      " ξ######### cc ξ",
      " η        # dd η",
      "η  E      #    ξ",
      "η         #    η",
      " η        #   η ",
      "  ηηηξηηηηξηηη  "
    ],
    [
      "  αααξααααξααα  ",
      " ξ   :    :   ξ ",
      "α    :    :    α",
      "α    :    :    ξ",
      " α   :    :    α",
      " ξ::::    :::::ξ",
      " α             α",
      " α             α",
      " α             ξ",
      " α         #   α",
      " ξ#########    ξ",
      " α        # cc α",
      "α  {      # dd ξ",
      "α         #    α",
      " ξ        #   ξ ",
      "  αααξααααξααα  "
    ]
  ],
  "refpalette": "rotwire:furnished_facades"
}
