{
  "xsize": 16,
  "zsize": 16,
  "slices": [
    [
      "  SSSSSSSSSSSS  ",
      " ############## ",
      "S##############S",
      "S##############S",
      "S##############S",
      "S############## ",
      "S#####1######## ",
      "S############## ",
      "S############## ",
      "S############## ",
      "S#########  ### ",
      "S#########  ###S",
      "S#########  ###S",
      "S#########cc###S",
      " ############## ",
      "  SSSSSSSSSSSS  "
    ],
    [
      "  οοοεοοοοεοοο  ",
      " εLLLL#⑲      ε ",
      "οL    #②       ο",
      "οC    L③       ο",
      "ο     #①       ο",
      "ε     #       ε ",
      "ο######       ο ",
      "ο    S#       ο ",
      "ο    S#   cc  ο ",
      "ο    S#  :dd: ο ",
      "ε     #  :  : ε ",
      "ο        :  :  ο",
      "ο    F#  :  :  ο",
      "ο    F#  :  :  ο",
      " εF⑥⑦ #       ε ",
      "  οοοεοοοοεοοο  "
    ],
    [
      "  θθθεθθθθεθθθ  ",
      " θLLLL#       θ ",
      "θL    #        θ",
      "θ     L        θ",
      "θ     #        θ",
      "ε     #       ε ",
      "θ#:::##       θ ",
      "θ     #       θ ",
      "θ    *#       θ ",
      "θ    *#   cc  θ ",
      "ε     #   dd  ε ",
      "θ              θ",
      "θ     #        θ",
      "θ     #        θ",
      " θ    #       θ ",
      "  θθθεθθθθεθθθ  "
    ],
    [
      "  θθθεθθθθεθθθ  ",
      " θLLLL#       θ ",
      "θL    #        θ",
      "θ     #        θ",
      "θ     #        θ",
      "ε     #       ε ",
      "θ######E      θ ",
      "θ     #       θ ",
      "θ     #       θ ",
      "θ     #       θ ",
      "ε     #   cc  ε ",
      "θ     #   dd   θ",
      "θ     #        θ",
      "θ     #        θ",
      " θE⑳⑲ #       θ ",
      "  θθθεθθθθεθθθ  "
    ],
    [
      "  θθθεθθθθεθθθ  ",
      " θ############θ ",
      "θ##############θ",
      "θ##############θ",
      "θ##############θ",
      "ε#############ε ",
      "θ#############θ ",
      "θ#############θ ",
      "θ#########  ##θ ",
      "θ#########  ##θ ",
      "ε#########  ##ε ",
      "θ#########cc###θ",
      "θ#########dd###θ",
      "θ#########  ###θ",
      " θ############θ ",
      "  θθθεθθθθεθθθ  "
    ],
    [
      "  οοοεοοοοεοοο  ",
      " ε############ε ",
      "ο##############ο",
      "ο##############ο",
      "ο##############ο",
      "ε#############ε ",
      "ο#############ο ",
      "ο#############ο ",
      "ο#########  ##ο ",
      "ο#########  ##ο ",
      "ε#########  ##ε ",
      "ο#########  ###ο",
      "ο#########cc###ο",
      "ο#########dd###ο",
      " ε############ε ",
      "  οοοεοοοοεοοο  "
    ]
  ],
  "refpalette": "rotwire:furnished_facades"
}
