{
  "xsize": 16,
  "zsize": 16,
  "slices": [
    [
      "  SSSSSSSSSSSS  ",
      " ############## ",
      "S##############S",
      "S##############S",
      "S##############S",
      "S############## ",
      "S############## ",
      "S############## ",
      "S############## ",
      "S############## ",
      "S#########  ### ",
      "S#########  ###S",
      "S#########  ###S",
      "S#########cc###S",
      " ############## ",
      "  SSSSSSSSSSSS  "
    ],
    [
      "  οοοεοοοοεοοο  ",
      " ε⑫ⓐⓛ⑫#  F⑮F  ε ",
      "ο     Q        ο",
      "οF    Q        ο",
      "ο     Q        ο",
      "ε     Q       ε ",
      "οF    #       ο ",
      "ο             ο ",
      "ο         cc  ο ",
      "οF    #  :dd: ο ",
      "εⓕⓓ   Q  :  : ε ",
      "οⓔ    Q  :  :  ο",
      "ο     Q  :  :  ο",
      "ο     Q  :  :  ο",
      " ε    #       ε ",
      "  οοοεοοοοεοοο  "
    ],
    [
      "  θθθεθθθθεθθθ  ",
      " θ    #       θ ",
      "θ     Q        θ",
      "θ     Q        θ",
      "θ     Q        θ",
      "ε     Q       ε ",
      "θ     #       θ ",
      "θ             θ ",
      "θ             θ ",
      "θ     #   cc  θ ",
      "ε     Q   dd  ε ",
      "θ     Q        θ",
      "θ     Q        θ",
      "θ     Q        θ",
      " θ    #       θ ",
      "  θθθεθθθθεθθθ  "
    ],
    [
      "  θθθεθθθθεθθθ  ",
      " θ    #       θ ",
      "θ     Q        θ",
      "θ    EQ        θ",
      "θ     Q        θ",
      "ε     Q       ε ",
      "θ     #       θ ",
      "θ     #       θ ",
      "θ     #       θ ",
      "θ     #       θ ",
      "ε     Q   cc  ε ",
      "θ     Q   dd   θ",
      "θ     Q        θ",
      "θ     Q        θ",
      " θ    #       θ ",
      "  θθθεθθθθεθθθ  "
    ],
    [
      "  θθθεθθθθεθθθ  ",
      " θ############θ ",
      "θ##############θ",
      "θ##############θ",
      "θ##############θ",
      "ε#############ε ",
      "θ#############θ ",
      "θ#############θ ",
      "θ#########  ##θ ",
      "θ#########  ##θ ",
      "ε#########  ##ε ",
      "θ#########cc###θ",
      "θ#########dd###θ",
      "θ#########  ###θ",
      " θ############θ ",
      "  θθθεθθθθεθθθ  "
    ],
    [
      "  οοοεοοοοεοοο  ",
      " ε############ε ",
      "ο##############ο",
      "ο##############ο",
      "ο##############ο",
      "ε#############ε ",
      "ο#############ο ",
      "ο#############ο ",
      "ο#########  ##ο ",
      "ο#########  ##ο ",
      "ε#########  ##ε ",
      "ο#########  ###ο",
      "ο#########cc###ο",
      "ο#########dd###ο",
      " ε############ε ",
      "  οοοεοοοοεοοο  "
    ]
  ],
  "refpalette": "rotwire:furnished_facades"
}
