{
  "xsize": 16,
  "zsize": 16,
  "slices": [
    [
      " #   ######   # ",
      "################",
      " ############## ",
      " ############## ",
      " ############## ",
      "################",
      "################",
      "################",
      "###########  ###",
      "###########  ###",
      "###########  ###",
      " ##########cc## ",
      " ############## ",
      " ############## ",
      "################",
      " #   ######   # "
    ],
    [
      " ααγγαγγγγαγγαα ",
      "α#aaa#L ⑨ⓓ#aaa#α",
      "γa      ⑧     aγ",
      "γa  F#        aγ",
      "γa  F#F       aγ",
      "α#   #F        α",
      "γ    #     cc Lγ",
      "γ    #    :dd  γ",
      "γ    #    :   ⑬γ",
      "γ    #    :   Fγ",
      "α#   ######   #α",
      "γa            aγ",
      "γa             γ",
      "γa            aγ",
      "α#aaa# ⑥⑦ #aaa#α",
      " ααγγαγγγγαγγαα "
    ],
    [
      " ααηηαηηηηαηηαα ",
      "α#aaa#L   #aaa#α",
      "ηa            aη",
      "ηa   #        aη",
      "ηa   a        aη",
      "α#   a         α",
      "η    a        ⑬η",
      "η    a     cc  η",
      "η    #     dd  η",
      "η    #         η",
      "α#   ######  ##α",
      "ηa            aη",
      "ηa             η",
      "ηa            aη",
      "α#aaa#    #aaa#α",
      " ααηηαηηηηαηηαα "
    ],
    [
      " ααηηαηηηηαηηαα ",
      "α#aaa#LL⑫⑫#aaa#α",
      "ηa   #        aη",
      "ηa   #        aη",
      "ηa   #        aη",
      "α#   #         α",
      "η    #        Lη",
      "η    #         η",
      "η   E#     cc  η",
      "η    #     dd  η",
      "α#   ######  ##α",
      "ηa     E      aη",
      "ηa             η",
      "ηa            aη",
      "α#aaa#    #aaa#α",
      " ααηηαηηηηαηηαα "
    ],
    [
      " ααηηαηηηηαηηαα ",
      "α##############α",
      "η##############η",
      "η##############η",
      "η##############η",
      "α##############α",
      "η##########  ##η",
      "η##########  ##η",
      "η##########  ##η",
      "η###### ###cc##η",
      "α##########dd##α",
      "η##########  ##η",
      "η##############η",
      "η##############η",
      "α##############α",
      " ααηηαηηηηαηηαα "
    ],
    [
      " ααγγαγγγγαγγαα ",
      "α##############α",
      "γ##############γ",
      "γ##############γ",
      "γ##############γ",
      "α##############α",
      "γ##########  ##γ",
      "γ##########  ##γ",
      "γ##########  ##γ",
      "γ###### ###  ##γ",
      "α##########cc##α",
      "γ##########dd##γ",
      "γ##############γ",
      "γ##############γ",
      "α##############α",
      " ααγγαγγγγαγγαα "
    ]
  ],
  "refpalette": "rotwire:furnished_facades"
}
