{
  "xsize": 16,
  "zsize": 16,
  "slices": [
    [
      " #   ######   # ",
      "################",
      " ############## ",
      " ############## ",
      " ############## ",
      "#######1########",
      "################",
      "################",
      "###########  ###",
      "###########  ###",
      "#####1#####  ###",
      " ##########cc## ",
      " ############## ",
      " ############## ",
      "################",
      " #   ######   # "
    ],
    [
      " ααγγαγγγγαγγαα ",
      "α#aaa#Fⓐⓛ #aaa#α",
      "γa            aγ",
      "γa            aγ",
      "γa            aγ",
      "α#  ######     α",
      "γ④  :     #cc  γ",
      "γ④  :  ⓙ  #dd  γ",
      "γ④  :     #    γ",
      "γ④  :     #    γ",
      "α#  #######   #α",
      "γa            aγ",
      "γa             γ",
      "γa            aγ",
      "α#aaa# ⓑⓗⓖ#aaa#α",
      " ααγγαγγγγαγγαα "
    ],
    [
      " ααηηαηηηηαηηαα ",
      "α#aaa#    #aaa#α",
      "ηa            aη",
      "ηa            aη",
      "ηa            aη",
      "α#  ######     α",
      "η   :     #    η",
      "η   :     #cc  η",
      "η   :     #dd  η",
      "η   :     #    η",
      "α#  #######   #α",
      "ηa            aη",
      "ηa             η",
      "ηa            aη",
      "α#aaa#    #aaa#α",
      " ααηηαηηηηαηηαα "
    ],
    [
      " ααηηαηηηηαηηαα ",
      "α#aaa#    #aaa#α",
      "ηa            aη",
      "ηa            aη",
      "ηa            aη",
      "α#  ######     α",
      "η   :  E  #    η",
      "η   :     #    η",
      "η   :     #cc  η",
      "η   :     #dd  η",
      "α#  #######   #α",
      "ηa            aη",
      "ηa             η",
      "ηa            aη",
      "α#aaa#    #aaa#α",
      " ααηηαηηηηαηηαα "
    ],
    [
      " ααηηαηηηηαηηαα ",
      "α##############α",
      "η##############η",
      "η##############η",
      "η##############η",
      "α##############α",
      "η##########  ##η",
      "η##########  ##η",
      "η##########  ##η",
      "η###### ###cc##η",
      "α##########dd##α",
      "η##########  ##η",
      "η##############η",
      "η##############η",
      "α##############α",
      " ααηηαηηηηαηηαα "
    ],
    [
      " ααγγαγγγγαγγαα ",
      "α##############α",
      "γ##############γ",
      "γ##############γ",
      "γ##############γ",
      "α##############α",
      "γ##########  ##γ",
      "γ##########  ##γ",
      "γ##########  ##γ",
      "γ###### ###  ##γ",
      "α##########cc##α",
      "γ##########dd##γ",
      "γ##############γ",
      "γ##############γ",
      "α##############α",
      " ααγγαγγγγαγγαα "
    ]
  ],
  "refpalette": "rotwire:furnished_facades"
}
