{
  "xsize": 16,
  "zsize": 16,
  "slices": [
    [
      "################",
      "################",
      "################",
      "################",
      "################",
      "#####  #########",
      "#####  #########",
      "#####  #########",
      "#####cc#########",
      "################",
      "################",
      "################",
      "################",
      "################",
      "################",
      "################"
    ],
    [
      "``````####``````",
      "`Lⓐⓛ ⑮⑫⑫⑮      `",
      "`⑭             `",
      "`    cc   ④⑱⑤  `",
      "`   :dd:       `",
      "`   :  :       `",
      "#   :  :       #",
      "#   :  :       #",
      "#   :  :       #",
      "#              #",
      "``# #`###``# #``",
      "`     *FF      `",
      "`              `",
      "`              `",
      "`*    ⓑⓑⓜ⑥⑦   *`",
      "``````####``````"
    ],
    [
      "``````####``````",
      "`              `",
      "`              `",
      "`              `",
      "`    cc        `",
      "`    dd        `",
      "#              #",
      "#              #",
      "#              #",
      "#              #",
      "``# #`###``# #``",
      "`              `",
      "`              `",
      "`              `",
      "`              `",
      "``````####``````"
    ],
    [
      "################",
      "#              #",
      "#              #",
      "#              #",
      "#              #",
      "#    cc        #",
      "#    dd        #",
      "#              #",
      "#              #",
      "#              #",
      "#`###`###``###`#",
      "#              #",
      "#              #",
      "#              #",
      "#              #",
      "################"
    ],
    [
      "``````####``````",
      "`              `",
      "`              `",
      "`  E        E  `",
      "`              `",
      "`              `",
      "#    cc        #",
      "#    dd        #",
      "#              #",
      "#              #",
      "``````###```````",
      "`              `",
      "`              `",
      "`              `",
      "`              `",
      "``````####``````"
    ],
    [
      "``````####``````",
      "`              `",
      "`              `",
      "`  {        {  `",
      "`              `",
      "`              `",
      "#              #",
      "#    cc        #",
      "#    dd        #",
      "#              #",
      "``````###```````",
      "`              `",
      "`              `",
      "`              `",
      "`              `",
      "``````####``````"
    ]
  ],
  "refpalette": "biohazard:handcrafted_furnishings"
}
