{
  "xsize": 16,
  "zsize": 16,
  "slices": [
    [
      "################",
      "################",
      "################",
      "################",
      "################",
      "#####  #########",
      "#####  #########",
      "#####  #########",
      "#####cc#########",
      "################",
      "################",
      "################",
      "################",
      "################",
      "################",
      "################"
    ],
    [
      "``````####``````",
      "`              `",
      "` $$    ②  $$$ `",
      "` $D$cc ③  $D$ `",
      "` $$:dd:①  $$$ `",
      "`   :  :       `",
      "#L  :  :       #",
      "#L  :  :       #",
      "#LLL:  :       #",
      "####     #     #",
      "`ⓕFFC#####  .  `",
      "`ⓔ             `",
      "`           .  `",
      "`              `",
      "`      ⑥⑦      `",
      "``````####``````"
    ],
    [
      "``````####``````",
      "`              `",
      "`              `",
      "`  K        K  `",
      "`    cc        `",
      "`    dd        `",
      "#L             #",
      "#L             #",
      "#LLLL          #",
      "####     #     #",
      "`    #####  -  `",
      "`              `",
      "`           -  `",
      "`              `",
      "`              `",
      "``````####``````"
    ],
    [
      "################",
      "#              #",
      "#              #",
      "#              #",
      "#              #",
      "#    cc        #",
      "#L   dd        #",
      "#L             #",
      "#LLLL          #",
      "####     #     #",
      "#    #####     #",
      "#              #",
      "#              #",
      "#              #",
      "#              #",
      "################"
    ],
    [
      "``````####``````",
      "`              `",
      "`              `",
      "`  E        E  `",
      "`              `",
      "`              `",
      "#L   cc        #",
      "#L   dd        #",
      "#LLLL          #",
      "######   #     #",
      "`L⑮⑮L#####     `",
      "`              `",
      "`           E  `",
      "`              `",
      "`              `",
      "``````####``````"
    ],
    [
      "``````####``````",
      "`              `",
      "`              `",
      "`  {        {  `",
      "`              `",
      "`              `",
      "#              #",
      "#    cc        #",
      "#    dd        #",
      "######   #     #",
      "`LLLL#####     `",
      "`              `",
      "`           {  `",
      "`              `",
      "`              `",
      "``````####``````"
    ]
  ],
  "refpalette": "biohazard:handcrafted_furnishings"
}
