{
    "xsize":  16,
    "zsize":  16,
    "slices":  [
                   [
                       "################",
                       "################",
                       "################",
                       "################",
                       "################",
                       "################",
                       "################",
                       "################",
                       "################",
                       "#######l########",
                       "################",
                       "################",
                       "################",
                       "################",
                       "################",
                       "################"
                   ],
                   [
                       "``````####``````",
                       "`    uv        `",
                       "` $$$   s  $$$ `",
                       "` $D$   t  $D$ `",
                       "` $$$   r  $$$ `",
                       "`              `",
                       "#              #",
                       "#              #",
                       "#              #",
                       "###### l #     #",
                       "` FFC#####  .  `",
                       "`              `",
                       "`           .  `",
                       "`     y  Bz    `",
                       "`     j  A     `",
                       "``````####``````"
                   ],
                   [
                       "``````####``````",
                       "`              `",
                       "`              `",
                       "`  K        K  `",
                       "`              `",
                       "`              `",
                       "#              #",
                       "#              #",
                       "#              #",
                       "###### l #     #",
                       "`    #####  -  `",
                       "`              `",
                       "`           -  `",
                       "`              `",
                       "`              `",
                       "``````####``````"
                   ],
                   [
                       "################",
                       "#              #",
                       "#              #",
                       "#              #",
                       "#              #",
                       "#              #",
                       "#              #",
                       "#              #",
                       "#              #",
                       "###### l #     #",
                       "#    #####     #",
                       "#              #",
                       "#              #",
                       "#              #",
                       "#              #",
                       "################"
                   ],
                   [
                       "``````####``````",
                       "`              `",
                       "`              `",
                       "`  E        E  `",
                       "`              `",
                       "`              `",
                       "#              #",
                       "#              #",
                       "#              #",
                       "###### l #     #",
                       "`    #####     `",
                       "`              `",
                       "`           E  `",
                       "`              `",
                       "`              `",
                       "``````####``````"
                   ],
                   [
                       "``````####``````",
                       "`              `",
                       "`              `",
                       "`  {        {  `",
                       "`              `",
                       "`              `",
                       "#              #",
                       "#              #",
                       "#              #",
                       "###### l #     #",
                       "`    #####     `",
                       "`              `",
                       "`           {  `",
                       "`              `",
                       "`              `",
                       "``````####``````"
                   ]
               ],
    "refpalette":  "biohazard:handcrafted_furnishings"
}
