{
  "xsize": 16,
  "zsize": 16,
  "slices": [
    [
      "################",
      "################",
      "################",
      "################",
      "################",
      "################",
      "################",
      "################",
      "################",
      "#######l########",
      "################",
      "################",
      "################",
      "################",
      "################",
      "################"
    ],
    [
      "``````####``````",
      "`        ⓒⓑ    `",
      "` $$$    ①   L `",
      "` $$$      L1L `",
      "` $$$      L   `",
      "`            L `",
      "#              #",
      "# L            #",
      "# L            #",
      "#      l       #",
      "`     ###  ⓙⓙⓙ `",
      "` ..       ⓘⓘⓘ `",
      "`          ⓘⓘⓘ `",
      "` $$       ⓘⓘⓘ `",
      "`    ⓗⓖ ⓜⓛⓚⓚⓚ  `",
      "``````####``````"
    ],
    [
      "``````####``````",
      "`              `",
      "` :::        L `",
      "` :C:      L L `",
      "` :::      L   `",
      "`            L `",
      "#              #",
      "# L            #",
      "# L            #",
      "#      l       #",
      "`     ###      `",
      "` --       - - `",
      "`              `",
      "` *        - - `",
      "`              `",
      "``````####``````"
    ],
    [
      "################",
      "#              #",
      "# :::          #",
      "# : :          #",
      "# :::          #",
      "#              #",
      "#              #",
      "# L            #",
      "# L            #",
      "#      l       #",
      "#     ###      #",
      "#              #",
      "#              #",
      "#              #",
      "#              #",
      "################"
    ],
    [
      "``````####``````",
      "`              `",
      "` :::          `",
      "` : :          `",
      "` :::          `",
      "`              `",
      "#              #",
      "# L            #",
      "# L            #",
      "#      l       #",
      "`     ###      `",
      "`              `",
      "`              `",
      "`              `",
      "`              `",
      "``````####``````"
    ],
    [
      "``````####``````",
      "`              `",
      "` :::          `",
      "` : :          `",
      "` :::          `",
      "`              `",
      "#              #",
      "# L            #",
      "# L            #",
      "#      l       #",
      "`     ###      `",
      "`              `",
      "`              `",
      "`              `",
      "`              `",
      "``````####``````"
    ]
  ],
  "refpalette": "biohazard:handcrafted_furnishings"
}
