{
  "xsize": 16,
  "zsize": 16,
  "slices": [
    [
      "################",
      "################",
      "################",
      "################",
      "################",
      "################",
      "################",
      "################",
      "################",
      "#######l########",
      "################",
      "################",
      "################",
      "################",
      "################",
      "################"
    ],
    [
      "``````####``````",
      "`              `",
      "` $$$   ②  $$$ `",
      "` $D$   ③  $D$ `",
      "` $$$   ①  $$$ `",
      "`              `",
      "#L             #",
      "#L             #",
      "#LLLL          #",
      "###### l #     #",
      "`ⓕFFC#####  .  `",
      "`ⓔ             `",
      "`           .  `",
      "`              `",
      "`      ⑥⑦      `",
      "``````####``````"
    ],
    [
      "``````####``````",
      "`              `",
      "`              `",
      "`  K        K  `",
      "`              `",
      "`              `",
      "#L             #",
      "#L             #",
      "#LLLL          #",
      "###### l #     #",
      "`    #####  -  `",
      "`              `",
      "`           -  `",
      "`              `",
      "`              `",
      "``````####``````"
    ],
    [
      "################",
      "#              #",
      "#              #",
      "#              #",
      "#              #",
      "#              #",
      "#L             #",
      "#L             #",
      "#LLLL          #",
      "###### l #     #",
      "#    #####     #",
      "#              #",
      "#              #",
      "#              #",
      "#              #",
      "################"
    ],
    [
      "``````####``````",
      "`              `",
      "`              `",
      "`  E        E  `",
      "`              `",
      "`              `",
      "#L             #",
      "#L             #",
      "#LLLL          #",
      "###### l #     #",
      "`L⑮⑮L#####     `",
      "`              `",
      "`           E  `",
      "`              `",
      "`              `",
      "``````####``````"
    ],
    [
      "``````####``````",
      "`              `",
      "`              `",
      "`  {        {  `",
      "`              `",
      "`              `",
      "#              #",
      "#              #",
      "#              #",
      "###### l #     #",
      "`LLLL#####     `",
      "`              `",
      "`           {  `",
      "`              `",
      "`              `",
      "``````####``````"
    ]
  ],
  "refpalette": "biohazard:handcrafted_furnishings"
}
