{
    "xsize":  16,
    "zsize":  16,
    "slices":  [
                   [
                       "################",
                       "################",
                       "################",
                       "################",
                       "################",
                       "################",
                       "################",
                       "################",
                       "################",
                       "#######l########",
                       "################",
                       "################",
                       "################",
                       "################",
                       "################",
                       "################"
                   ],
                   [
                       "``````####``````",
                       "`    uv        `",
                       "`       s      `",
                       "`       t      `",
                       "`       r      `",
                       "`              `",
                       "#              #",
                       "#              #",
                       "#              #",
                       "#      l       #",
                       "``# #`###``# #``",
                       "`     *FF      `",
                       "`              `",
                       "`     y  Bz    `",
                       "`*    j  A    *`",
                       "``````####``````"
                   ],
                   [
                       "``````####``````",
                       "`              `",
                       "`              `",
                       "`              `",
                       "`              `",
                       "`              `",
                       "#              #",
                       "#              #",
                       "#              #",
                       "#      l       #",
                       "``# #`###``# #``",
                       "`              `",
                       "`              `",
                       "`              `",
                       "`              `",
                       "``````####``````"
                   ],
                   [
                       "################",
                       "#              #",
                       "#              #",
                       "#              #",
                       "#              #",
                       "#              #",
                       "#              #",
                       "#              #",
                       "#              #",
                       "#      l       #",
                       "#`###`###``###`#",
                       "#              #",
                       "#              #",
                       "#              #",
                       "#              #",
                       "################"
                   ],
                   [
                       "``````####``````",
                       "`              `",
                       "`              `",
                       "`  E        E  `",
                       "`              `",
                       "`              `",
                       "#              #",
                       "#              #",
                       "#              #",
                       "#      l       #",
                       "``````###```````",
                       "`              `",
                       "`              `",
                       "`              `",
                       "`              `",
                       "``````####``````"
                   ],
                   [
                       "``````####``````",
                       "`              `",
                       "`              `",
                       "`  {        {  `",
                       "`              `",
                       "`              `",
                       "#              #",
                       "#              #",
                       "#              #",
                       "#      l       #",
                       "``````###```````",
                       "`              `",
                       "`              `",
                       "`              `",
                       "`              `",
                       "``````####``````"
                   ]
               ],
    "refpalette":  "biohazard:handcrafted_furnishings"
}
