{
  "xsize": 16,
  "zsize": 16,
  "slices": [
    [
      "  ############  ",
      " ############## ",
      "################",
      "################",
      "################",
      "#####  #########",
      "#####  #########",
      "#####  #########",
      "#####cc#########",
      "################",
      "################",
      "################",
      "################",
      "################",
      " ############## ",
      "  ############  "
    ],
    [
      "  νγγννγγγνγγν  ",
      " ν⑫      L    ν ",
      "γ $        $ $ γ",
      "γ $  cc    $ $ γ",
      "γ   :dd:       γ",
      "ν   :  :       ν",
      "γ## :  :###:::#γ",
      "γ   :  : #     γ",
      "γ   :  : #F    γ",
      "γ        #F    γ",
      "ν       ##     ν",
      "γ     ②FF      γ",
      "γ $   ③      $ γ",
      "γ $   ①      $ γ",
      " ν ⑥⑦         ν ",
      "  νγγννγγγνγγν  "
    ],
    [
      "  νγγννγγγνγγν  ",
      " η       L    η ",
      "η          * * η",
      "γ *            γ",
      "γ    cc        γ",
      "ν    dd        ν",
      "η## #   ###:::#η",
      "γ        #     γ",
      "γ        #     γ",
      "γ        #     γ",
      "ν       ##     ν",
      "γ              γ",
      "γ *            γ",
      "γ            * γ",
      " η            η ",
      "  νγγννγγγνγγν  "
    ],
    [
      "  νγγννγγγνγγν  ",
      " η      ⑫L    η ",
      "η              η",
      "γ              γ",
      "γ              γ",
      "ν    cc        ν",
      "η####dd####:::#η",
      "γ        #     γ",
      "γ        #     γ",
      "γ        #     γ",
      "ν       ##     ν",
      "γ              γ",
      "γ              γ",
      "γ              γ",
      " η            η ",
      "  νγγννγγγνγγν  "
    ],
    [
      "  νγγννγγγνγγν  ",
      " η    L⑫⑫L    η ",
      "η              η",
      "γ           E  γ",
      "γ              γ",
      "ν              ν",
      "η####cc########η",
      "γ    dd  #     γ",
      "γ        #     γ",
      "γ    #   #     γ",
      "ν    #####     ν",
      "γ              γ",
      "γ           E  γ",
      "γ              γ",
      " η            η ",
      "  νγγννγγγνγγν  "
    ],
    [
      "  νγγννγγγνγγν  ",
      " ν            ν ",
      "γ              γ",
      "γ           {  γ",
      "γ              γ",
      "ν              ν",
      "γ####  ########γ",
      "γ    cc  #     γ",
      "γ    dd  #     γ",
      "γ    #   #     γ",
      "ν    #####     ν",
      "γ              γ",
      "γ           {  γ",
      "γ              γ",
      " ν            ν ",
      "  νγγννγγγνγγν  "
    ]
  ],
  "refpalette": "biohazard:furnished_facades"
}
