{
  "xsize": 16,
  "zsize": 16,
  "slices": [
    [
      "  ############  ",
      " ############## ",
      "################",
      "################",
      "################",
      "#####  #########",
      "#####  #########",
      "#####  #########",
      "#####cc#########",
      "################",
      "################",
      "################",
      "################",
      "################",
      " ############## ",
      "  ############  "
    ],
    [
      "  νγγννγγγνγγν  ",
      " ν       ⓒⓑ   ν ",
      "γ $$     ①   L γ",
      "γ $$$cc    L1L γ",
      "γ $$:dd:   L   γ",
      "ν   :  :     L ν",
      "γ   :  :       γ",
      "γ L :  :       γ",
      "γ L :  :       γ",
      "γ              γ",
      "ν       #  ⓙⓙⓙ ν",
      "γ ..       ⓘⓘⓘ γ",
      "γ          ⓘⓘⓘ γ",
      "γ $$       ⓘⓘⓘ γ",
      " ν   ⓗⓖ ⓜⓛⓚⓚⓚ ν ",
      "  νγγννγγγνγγν  "
    ],
    [
      "  νγγννγγγνγγν  ",
      " η            η ",
      "η ::         L η",
      "γ :C:      L L γ",
      "γ :::cc    L   γ",
      "ν    dd      L ν",
      "η              η",
      "γ L            γ",
      "γ L            γ",
      "γ              γ",
      "ν       #      ν",
      "γ --       - - γ",
      "γ              γ",
      "γ *        - - γ",
      " η            η ",
      "  νγγννγγγνγγν  "
    ],
    [
      "  νγγννγγγνγγν  ",
      " η            η ",
      "η ::           η",
      "γ : :          γ",
      "γ :::          γ",
      "ν    cc        ν",
      "η    dd        η",
      "γ L            γ",
      "γ L            γ",
      "γ              γ",
      "ν       #      ν",
      "γ              γ",
      "γ              γ",
      "γ              γ",
      " η            η ",
      "  νγγννγγγνγγν  "
    ],
    [
      "  νγγννγγγνγγν  ",
      " η            η ",
      "η :::          η",
      "γ : :          γ",
      "γ :::          γ",
      "ν              ν",
      "η    cc        η",
      "γ L  dd        γ",
      "γ L            γ",
      "γ              γ",
      "ν     ###      ν",
      "γ              γ",
      "γ              γ",
      "γ              γ",
      " η            η ",
      "  νγγννγγγνγγν  "
    ],
    [
      "  νγγννγγγνγγν  ",
      " ν            ν ",
      "γ :::          γ",
      "γ : :          γ",
      "γ :::          γ",
      "ν              ν",
      "γ              γ",
      "γ L  cc        γ",
      "γ L  dd        γ",
      "γ              γ",
      "ν     ###      ν",
      "γ              γ",
      "γ              γ",
      "γ              γ",
      " ν            ν ",
      "  νγγννγγγνγγν  "
    ]
  ],
  "refpalette": "biohazard:furnished_facades"
}
