{
  "xsize": 16,
  "zsize": 16,
  "slices": [
    [
      "################",
      "################",
      "################",
      "################",
      "################",
      "################",
      "################",
      "################",
      "################",
      "#######l########",
      "################",
      "################",
      "################",
      "################",
      "################",
      "################"
    ],
    [
      "``````####``````",
      "`              `",
      "` $$$   ②  $$$ `",
      "` $D$   ③  $D$ `",
      "` $$$   ①  $$$ `",
      "`              `",
      "#              #",
      "#              #",
      "#              #",
      "###### l #     #",
      "`ⓕFFC#####  .  `",
      "`ⓔ             `",
      "`           .  `",
      "`              `",
      "`      ⑥⑦      `",
      "``````####``````"
    ],
    [
      "``````####``````",
      "`              `",
      "`              `",
      "`  K        K  `",
      "`              `",
      "`              `",
      "#              #",
      "#              #",
      "#              #",
      "###### l #     #",
      "`    #####  -  `",
      "`              `",
      "`           -  `",
      "`              `",
      "`              `",
      "``````####``````"
    ],
    [
      "################",
      "#              #",
      "#              #",
      "#              #",
      "#              #",
      "#              #",
      "#              #",
      "#              #",
      "#              #",
      "###### l #     #",
      "#    #####     #",
      "#              #",
      "#              #",
      "#              #",
      "#              #",
      "################"
    ],
    [
      "``````####``````",
      "`              `",
      "`              `",
      "`  E        E  `",
      "`              `",
      "`              `",
      "#              #",
      "#              #",
      "#              #",
      "###### l #     #",
      "`    #####     `",
      "`              `",
      "`           E  `",
      "`              `",
      "`              `",
      "``````####``````"
    ],
    [
      "``````####``````",
      "`              `",
      "`              `",
      "`  {        {  `",
      "`              `",
      "`              `",
      "#              #",
      "#              #",
      "#              #",
      "###### l #     #",
      "`    #####     `",
      "`              `",
      "`           {  `",
      "`              `",
      "`              `",
      "``````####``````"
    ]
  ],
  "refpalette": "biohazard:handcrafted_furnishings"
}
