{
  "xsize": 16,
  "zsize": 16,
  "slices": [
    [
      "################",
      "################",
      "################",
      "################",
      "################",
      "#####  #########",
      "#####  #########",
      "#####  #########",
      "#####cc#########",
      "################",
      "################",
      "################",
      "################",
      "################",
      "################",
      "################"
    ],
    [
      "``````####``````",
      "`        ⓒⓑ    `",
      "` $$     ①   L `",
      "` $$$cc    L1L `",
      "` $$:dd:   L   `",
      "`   :  :     L `",
      "#   :  :       #",
      "# L :  :       #",
      "# L :  :       #",
      "#              #",
      "`     ###  ⓙⓙⓙ `",
      "` ..       ⓘⓘⓘ `",
      "`          ⓘⓘⓘ `",
      "` $$       ⓘⓘⓘ `",
      "`    ⓗⓖ ⓜⓛⓚⓚⓚ  `",
      "``````####``````"
    ],
    [
      "``````####``````",
      "`              `",
      "` ::         L `",
      "` :C:      L L `",
      "` :::cc    L   `",
      "`    dd      L `",
      "#              #",
      "# L            #",
      "# L            #",
      "#              #",
      "`     ###      `",
      "` --       - - `",
      "`              `",
      "` *        - - `",
      "`              `",
      "``````####``````"
    ],
    [
      "################",
      "#              #",
      "# ::           #",
      "# : :          #",
      "# :::          #",
      "#    cc        #",
      "#    dd        #",
      "# L            #",
      "# L            #",
      "#              #",
      "#     ###      #",
      "#              #",
      "#              #",
      "#              #",
      "#              #",
      "################"
    ],
    [
      "``````####``````",
      "`              `",
      "` :::          `",
      "` : :          `",
      "` :::          `",
      "`              `",
      "#    cc        #",
      "# L  dd        #",
      "# L            #",
      "#              #",
      "`     ###      `",
      "`              `",
      "`              `",
      "`              `",
      "`              `",
      "``````####``````"
    ],
    [
      "``````####``````",
      "`              `",
      "` :::          `",
      "` : :          `",
      "` :::          `",
      "`              `",
      "#              #",
      "# L  cc        #",
      "# L  dd        #",
      "#              #",
      "`     ###      `",
      "`              `",
      "`              `",
      "`              `",
      "`              `",
      "``````####``````"
    ]
  ],
  "refpalette": "biohazard:handcrafted_furnishings"
}
