{
  "xsize": 16,
  "zsize": 16,
  "slices": [
    [
      "  ############  ",
      " ############## ",
      "################",
      "################",
      "################",
      "#####  #########",
      "#####  #########",
      "#####  #########",
      "#####cc#########",
      "################",
      "################",
      "################",
      "################",
      "################",
      " ############## ",
      "  ############  "
    ],
    [
      "  νγγννγγγνγγν  ",
      " νⓐⓛ    ⑮⑮⑫⑫  ν ",
      "γ⑭             γ",
      "γ    cc   ④⑱⑤  γ",
      "γ   :dd:       γ",
      "ν   :  :       ν",
      "γ   :  :       γ",
      "γ   :  :       γ",
      "γ   :  :       γ",
      "γ              γ",
      "ν`#     #``# #`ν",
      "γ     *FF      γ",
      "γ              γ",
      "γ              γ",
      " ν    ⓑⓑⓜ⑥⑦   ν ",
      "  νγγννγγγνγγν  "
    ],
    [
      "  νγγννγγγνγγν  ",
      " η            η ",
      "η              η",
      "γ              γ",
      "γ    cc        γ",
      "ν    dd        ν",
      "η              η",
      "γ              γ",
      "γ              γ",
      "γ              γ",
      "ν`#     #``# #`ν",
      "γ              γ",
      "γ              γ",
      "γ              γ",
      " η            η ",
      "  νγγννγγγνγγν  "
    ],
    [
      "  νγγννγγγνγγν  ",
      " η            η ",
      "η              η",
      "γ              γ",
      "γ              γ",
      "ν    cc        ν",
      "η    dd        η",
      "γ              γ",
      "γ              γ",
      "γ              γ",
      "ν`##    #``###`ν",
      "γ              γ",
      "γ              γ",
      "γ              γ",
      " η            η ",
      "  νγγννγγγνγγν  "
    ],
    [
      "  νγγννγγγνγγν  ",
      " η            η ",
      "η              η",
      "γ  E        E  γ",
      "γ              γ",
      "ν              ν",
      "η    cc        η",
      "γ    dd        γ",
      "γ              γ",
      "γ              γ",
      "ν`````###``````ν",
      "γ              γ",
      "γ              γ",
      "γ              γ",
      " η            η ",
      "  νγγννγγγνγγν  "
    ],
    [
      "  νγγννγγγνγγν  ",
      " ν            ν ",
      "γ              γ",
      "γ  {        {  γ",
      "γ              γ",
      "ν              ν",
      "γ              γ",
      "γ    cc        γ",
      "γ    dd        γ",
      "γ              γ",
      "ν`````###``````ν",
      "γ              γ",
      "γ              γ",
      "γ              γ",
      " ν            ν ",
      "  νγγννγγγνγγν  "
    ]
  ],
  "refpalette": "biohazard:furnished_facades"
}
