{
  "xsize": 16,
  "zsize": 16,
  "slices": [
    [
      "################",
      "################",
      "################",
      "################",
      "################",
      "#####  #########",
      "#####  #########",
      "#####  #########",
      "#####cc#########",
      "################",
      "################",
      "################",
      "################",
      "################",
      "################",
      "################"
    ],
    [
      "``````####``````",
      "`     L  L     `",
      "` $        $ $ `",
      "` $  cc    $ $ `",
      "`   :dd:       `",
      "`   :  :       `",
      "### :  :###:::##",
      "#   :  : #     #",
      "#   :  : #F    #",
      "#        #F    #",
      "`    #####     `",
      "`     ②FF      `",
      "` $   ③      $ `",
      "` $   ①      $ `",
      "`  ⑥⑦          `",
      "``````####``````"
    ],
    [
      "``````####``````",
      "`     L  L     `",
      "`          * * `",
      "` *            `",
      "`    cc        `",
      "`    dd        `",
      "### #   ###:::##",
      "#        #     #",
      "#        #     #",
      "#        #     #",
      "`    #####     `",
      "`              `",
      "` *            `",
      "`            * `",
      "`              `",
      "``````####``````"
    ],
    [
      "################",
      "#     L⑫⑫L     #",
      "#              #",
      "#              #",
      "#              #",
      "#    cc        #",
      "#####dd####:::##",
      "#        #     #",
      "#        #     #",
      "#        #     #",
      "#    #####     #",
      "#              #",
      "#              #",
      "#              #",
      "#              #",
      "################"
    ],
    [
      "``````####``````",
      "`     L⑫⑫L     `",
      "`              `",
      "`           E  `",
      "`              `",
      "`              `",
      "#####cc#########",
      "#    dd  #     #",
      "#        #     #",
      "#    #   #     #",
      "`    #####     `",
      "`              `",
      "`           E  `",
      "`              `",
      "`              `",
      "``````####``````"
    ],
    [
      "``````####``````",
      "`              `",
      "`              `",
      "`           {  `",
      "`              `",
      "`              `",
      "#####  #########",
      "#    cc  #     #",
      "#    dd  #     #",
      "#    #   #     #",
      "`    #####     `",
      "`              `",
      "`           {  `",
      "`              `",
      "`              `",
      "``````####``````"
    ]
  ],
  "refpalette": "biohazard:handcrafted_furnishings"
}
