{
    "xsize":  16,
    "zsize":  16,
    "slices":  [
                   [
                       "################",
                       "################",
                       "################",
                       "################",
                       "################",
                       "################",
                       "################",
                       "################",
                       "################",
                       "#######l########",
                       "################",
                       "################",
                       "################",
                       "################",
                       "################",
                       "################"
                   ],
                   [
                       "``````####``````",
                       "`    uv        `",
                       "` $$$   s    L `",
                       "` $$$   t  L1L `",
                       "` $$$   r  L   `",
                       "`            L `",
                       "#              #",
                       "#              #",
                       "#              #",
                       "#      l       #",
                       "`     ###      `",
                       "` ..       . . `",
                       "`              `",
                       "` $$  y  Bz. . `",
                       "`     j  A     `",
                       "``````####``````"
                   ],
                   [
                       "``````####``````",
                       "`              `",
                       "` :::        L `",
                       "` :C:      L L `",
                       "` :::      L   `",
                       "`            L `",
                       "#              #",
                       "#              #",
                       "#              #",
                       "#      l       #",
                       "`     ###      `",
                       "` --       - - `",
                       "`              `",
                       "` *        - - `",
                       "`              `",
                       "``````####``````"
                   ],
                   [
                       "################",
                       "#              #",
                       "# :::          #",
                       "# : :          #",
                       "# :::          #",
                       "#              #",
                       "#              #",
                       "#              #",
                       "#              #",
                       "#      l       #",
                       "#     ###      #",
                       "#              #",
                       "#              #",
                       "#              #",
                       "#              #",
                       "################"
                   ],
                   [
                       "``````####``````",
                       "`              `",
                       "` :::          `",
                       "` : :          `",
                       "` :::          `",
                       "`              `",
                       "#              #",
                       "#              #",
                       "#              #",
                       "#      l       #",
                       "`     ###      `",
                       "`              `",
                       "`              `",
                       "`              `",
                       "`              `",
                       "``````####``````"
                   ],
                   [
                       "``````####``````",
                       "`              `",
                       "` :::          `",
                       "` : :          `",
                       "` :::          `",
                       "`              `",
                       "#              #",
                       "#              #",
                       "#              #",
                       "#      l       #",
                       "`     ###      `",
                       "`              `",
                       "`              `",
                       "`              `",
                       "`              `",
                       "``````####``````"
                   ]
               ],
    "refpalette":  "biohazard:handcrafted_furnishings"
}
