{
  "xsize": 16,
  "zsize": 16,
  "slices": [
    [
      "################",
      "################",
      "################",
      "################",
      "################",
      "################",
      "################",
      "################",
      "################",
      "#######l########",
      "################",
      "################",
      "################",
      "################",
      "################",
      "################"
    ],
    [
      "``````####``````",
      "`     L  L     `",
      "` $        $ $ `",
      "` $        $ $ `",
      "`              `",
      "`              `",
      "### ### ###:::##",
      "#    #   #     #",
      "#    #   #F    #",
      "#    # l #F    #",
      "`    #####     `",
      "`     ②FF      `",
      "` $   ③      $ `",
      "` $   ①      $ `",
      "`  ⑥⑦          `",
      "``````####``````"
    ],
    [
      "``````####``````",
      "`     L  L     `",
      "`          * * `",
      "` *            `",
      "`              `",
      "`              `",
      "### ### ###:::##",
      "#    #   #     #",
      "#    #   #     #",
      "#    # l #     #",
      "`    #####     `",
      "`              `",
      "` *            `",
      "`            * `",
      "`              `",
      "``````####``````"
    ],
    [
      "################",
      "#     L⑫⑫L     #",
      "#              #",
      "#              #",
      "#              #",
      "#              #",
      "###########:::##",
      "#    #   #     #",
      "#    #   #     #",
      "#    # l #     #",
      "#    #####     #",
      "#              #",
      "#              #",
      "#              #",
      "#              #",
      "################"
    ],
    [
      "``````####``````",
      "`     L⑫⑫L     `",
      "`              `",
      "`           E  `",
      "`              `",
      "`              `",
      "################",
      "#    #   #     #",
      "#    #   #     #",
      "#    # l #     #",
      "`    #####     `",
      "`              `",
      "`           E  `",
      "`              `",
      "`              `",
      "``````####``````"
    ],
    [
      "``````####``````",
      "`              `",
      "`              `",
      "`           {  `",
      "`              `",
      "`              `",
      "################",
      "#    #   #     #",
      "#    #   #     #",
      "#    # l #     #",
      "`    #####     `",
      "`              `",
      "`           {  `",
      "`              `",
      "`              `",
      "``````####``````"
    ]
  ],
  "refpalette": "biohazard:handcrafted_furnishings"
}
