{
  "xsize": 16,
  "zsize": 16,
  "slices": [
    [
      " @#@#@#@@#@#@#@ ",
      "@##############@",
      "################",
      "@##############@",
      "################",
      "@##############@",
      "################",
      "@##############@",
      "@##############@",
      "################",
      "@#########  ###@",
      "##########  ####",
      "@#########  ###@",
      "##########cc####",
      "@##############@",
      " @#@#@#@@#@#@#@ "
    ],
    [
      " ζρρρρππππζπππζ ",
      "ζ⑮π③②ζ#        ζ",
      "π     `      $ π",
      "π F F `        π",
      "π $$$ `      $ π",
      "ζ     #        ζ",
      "π     #        π",
      "π              π",
      "π        ①cc   π",
      "π     #  :dd:  π",
      "ζ     #  :  :  ζ",
      "π $$$ `  :  :  π",
      "π F F `  :  :  π",
      "π     `  :  :  π",
      "ζ  ⑥⑦ #        ζ",
      " ζπππζππππρρρρζ "
    ],
    [
      " ζ    θθθθζθθθζ ",
      "ζ θ  ζ#        ζ",
      "θ     `      + θ",
      "θ     `        θ",
      "θ *   `      + θ",
      "ζ     #        ζ",
      "θ     #        θ",
      "θ              θ",
      "θ              θ",
      "θ     #   cc   θ",
      "ζ     #   dd   ζ",
      "θ   * `        θ",
      "θ     `        θ",
      "θ     `        θ",
      "ζ     #        ζ",
      " ζθθθζθθθθ    ζ "
    ],
    [
      " ζ    θθθθζθθθζ ",
      "ζ θθθζ#        ζ",
      "θ     `        θ",
      "θ     `        θ",
      "θ     `        θ",
      "ζ     #        ζ",
      "θ     #        θ",
      "θ              θ",
      "θ              θ",
      "θ     #        θ",
      "ζ     #   cc   ζ",
      "θ     `   dd   θ",
      "θ     `        θ",
      "θ     `        θ",
      "ζ     #        ζ",
      " ζθθθζθθθθ    ζ "
    ],
    [
      " ζ    θθθθζθθθζ ",
      "ζ θθθζ#        ζ",
      "θ     `        θ",
      "θ  E  `        θ",
      "θ     `        θ",
      "ζ     #        ζ",
      "θ     #        θ",
      "θ     #        θ",
      "θ     #        θ",
      "θ     #        θ",
      "ζ     #        ζ",
      "θ     `   cc   θ",
      "θ  E  `   dd   θ",
      "θ     `        θ",
      "ζ     #   ζθθθ ζ",
      " ζθθθζθθθθ    ζ "
    ],
    [
      " ζ    ππππζπππζ ",
      "ζ πππζ#        ζ",
      "π     `        π",
      "π  {  `        π",
      "π     `        π",
      "ζ     #        ζ",
      "π     #        π",
      "π     #        π",
      "π     #        π",
      "π     #        π",
      "ζ     #        ζ",
      "π     `        π",
      "π  {  `   cc   π",
      "π     `   dd   π",
      "ζ     #   ζπππ ζ",
      " ζπππζππππ    ζ "
    ]
  ],
  "refpalette": "rotwire:furnished_facades"
}
